2019-09-25 13:17:18,085 INFO: Microblog startup [in D:\项目\project\app\__init__.py:35]
2019-09-25 13:23:01,231 INFO: Microblog startup [in D:\项目\project\app\__init__.py:35]
2019-09-25 13:25:19,252 INFO: Microblog startup [in D:\项目\project\app\__init__.py:35]
2019-09-25 13:25:21,742 ERROR: Exception on /api/check_account [POST] [in c:\users\认为、\appdata\local\programs\python\python37\lib\site-packages\flask\app.py:1761]
Traceback (most recent call last):
  File "c:\users\认为、\appdata\local\programs\python\python37\lib\site-packages\flask\app.py", line 2292, in wsgi_app
    response = self.full_dispatch_request()
  File "c:\users\认为、\appdata\local\programs\python\python37\lib\site-packages\flask\app.py", line 1815, in full_dispatch_request
    rv = self.handle_user_exception(e)
  File "c:\users\认为、\appdata\local\programs\python\python37\lib\site-packages\flask\app.py", line 1718, in handle_user_exception
    reraise(exc_type, exc_value, tb)
  File "c:\users\认为、\appdata\local\programs\python\python37\lib\site-packages\flask\_compat.py", line 35, in reraise
    raise value
  File "c:\users\认为、\appdata\local\programs\python\python37\lib\site-packages\flask\app.py", line 1813, in full_dispatch_request
    rv = self.dispatch_request()
  File "c:\users\认为、\appdata\local\programs\python\python37\lib\site-packages\flask\app.py", line 1799, in dispatch_request
    return self.view_functions[rule.endpoint](**req.view_args)
  File "D:\项目\project\app\routes.py", line 20, in check_account
    username = data['username']
TypeError: byte indices must be integers or slices, not str
2019-09-25 13:26:29,069 INFO: Microblog startup [in D:\项目\project\app\__init__.py:35]
2019-09-25 13:26:34,470 ERROR: Exception on /api/check_account [POST] [in c:\users\认为、\appdata\local\programs\python\python37\lib\site-packages\flask\app.py:1761]
Traceback (most recent call last):
  File "c:\users\认为、\appdata\local\programs\python\python37\lib\site-packages\flask\app.py", line 2292, in wsgi_app
    response = self.full_dispatch_request()
  File "c:\users\认为、\appdata\local\programs\python\python37\lib\site-packages\flask\app.py", line 1815, in full_dispatch_request
    rv = self.handle_user_exception(e)
  File "c:\users\认为、\appdata\local\programs\python\python37\lib\site-packages\flask\app.py", line 1718, in handle_user_exception
    reraise(exc_type, exc_value, tb)
  File "c:\users\认为、\appdata\local\programs\python\python37\lib\site-packages\flask\_compat.py", line 35, in reraise
    raise value
  File "c:\users\认为、\appdata\local\programs\python\python37\lib\site-packages\flask\app.py", line 1813, in full_dispatch_request
    rv = self.dispatch_request()
  File "c:\users\认为、\appdata\local\programs\python\python37\lib\site-packages\flask\app.py", line 1799, in dispatch_request
    return self.view_functions[rule.endpoint](**req.view_args)
  File "D:\项目\project\app\routes.py", line 20, in check_account
    username = data['username']
TypeError: byte indices must be integers or slices, not str
2019-09-25 13:26:57,387 INFO: Microblog startup [in D:\项目\project\app\__init__.py:35]
2019-09-25 13:26:59,381 ERROR: Exception on /api/check_account [POST] [in c:\users\认为、\appdata\local\programs\python\python37\lib\site-packages\flask\app.py:1761]
Traceback (most recent call last):
  File "c:\users\认为、\appdata\local\programs\python\python37\lib\site-packages\flask\app.py", line 2292, in wsgi_app
    response = self.full_dispatch_request()
  File "c:\users\认为、\appdata\local\programs\python\python37\lib\site-packages\flask\app.py", line 1815, in full_dispatch_request
    rv = self.handle_user_exception(e)
  File "c:\users\认为、\appdata\local\programs\python\python37\lib\site-packages\flask\app.py", line 1718, in handle_user_exception
    reraise(exc_type, exc_value, tb)
  File "c:\users\认为、\appdata\local\programs\python\python37\lib\site-packages\flask\_compat.py", line 35, in reraise
    raise value
  File "c:\users\认为、\appdata\local\programs\python\python37\lib\site-packages\flask\app.py", line 1813, in full_dispatch_request
    rv = self.dispatch_request()
  File "c:\users\认为、\appdata\local\programs\python\python37\lib\site-packages\flask\app.py", line 1799, in dispatch_request
    return self.view_functions[rule.endpoint](**req.view_args)
  File "D:\项目\project\app\routes.py", line 21, in check_account
    username = data['username']
TypeError: byte indices must be integers or slices, not str
2019-09-25 13:27:30,855 ERROR: Exception on /api/check_account [POST] [in c:\users\认为、\appdata\local\programs\python\python37\lib\site-packages\flask\app.py:1761]
Traceback (most recent call last):
  File "c:\users\认为、\appdata\local\programs\python\python37\lib\site-packages\flask\app.py", line 2292, in wsgi_app
    response = self.full_dispatch_request()
  File "c:\users\认为、\appdata\local\programs\python\python37\lib\site-packages\flask\app.py", line 1815, in full_dispatch_request
    rv = self.handle_user_exception(e)
  File "c:\users\认为、\appdata\local\programs\python\python37\lib\site-packages\flask\app.py", line 1718, in handle_user_exception
    reraise(exc_type, exc_value, tb)
  File "c:\users\认为、\appdata\local\programs\python\python37\lib\site-packages\flask\_compat.py", line 35, in reraise
    raise value
  File "c:\users\认为、\appdata\local\programs\python\python37\lib\site-packages\flask\app.py", line 1813, in full_dispatch_request
    rv = self.dispatch_request()
  File "c:\users\认为、\appdata\local\programs\python\python37\lib\site-packages\flask\app.py", line 1799, in dispatch_request
    return self.view_functions[rule.endpoint](**req.view_args)
  File "D:\项目\project\app\routes.py", line 21, in check_account
    username = data['username']
TypeError: byte indices must be integers or slices, not str
2019-09-25 13:27:43,277 INFO: Microblog startup [in D:\项目\project\app\__init__.py:35]
2019-09-25 13:27:46,569 ERROR: Exception on /api/check_account [POST] [in c:\users\认为、\appdata\local\programs\python\python37\lib\site-packages\flask\app.py:1761]
Traceback (most recent call last):
  File "c:\users\认为、\appdata\local\programs\python\python37\lib\site-packages\flask\app.py", line 2292, in wsgi_app
    response = self.full_dispatch_request()
  File "c:\users\认为、\appdata\local\programs\python\python37\lib\site-packages\flask\app.py", line 1815, in full_dispatch_request
    rv = self.handle_user_exception(e)
  File "c:\users\认为、\appdata\local\programs\python\python37\lib\site-packages\flask\app.py", line 1718, in handle_user_exception
    reraise(exc_type, exc_value, tb)
  File "c:\users\认为、\appdata\local\programs\python\python37\lib\site-packages\flask\_compat.py", line 35, in reraise
    raise value
  File "c:\users\认为、\appdata\local\programs\python\python37\lib\site-packages\flask\app.py", line 1813, in full_dispatch_request
    rv = self.dispatch_request()
  File "c:\users\认为、\appdata\local\programs\python\python37\lib\site-packages\flask\app.py", line 1799, in dispatch_request
    return self.view_functions[rule.endpoint](**req.view_args)
  File "D:\项目\project\app\routes.py", line 21, in check_account
    username = data['username']
TypeError: byte indices must be integers or slices, not str
2019-09-25 13:29:02,023 ERROR: Exception on /api/check_account [POST] [in c:\users\认为、\appdata\local\programs\python\python37\lib\site-packages\flask\app.py:1761]
Traceback (most recent call last):
  File "c:\users\认为、\appdata\local\programs\python\python37\lib\site-packages\flask\app.py", line 2292, in wsgi_app
    response = self.full_dispatch_request()
  File "c:\users\认为、\appdata\local\programs\python\python37\lib\site-packages\flask\app.py", line 1815, in full_dispatch_request
    rv = self.handle_user_exception(e)
  File "c:\users\认为、\appdata\local\programs\python\python37\lib\site-packages\flask\app.py", line 1718, in handle_user_exception
    reraise(exc_type, exc_value, tb)
  File "c:\users\认为、\appdata\local\programs\python\python37\lib\site-packages\flask\_compat.py", line 35, in reraise
    raise value
  File "c:\users\认为、\appdata\local\programs\python\python37\lib\site-packages\flask\app.py", line 1813, in full_dispatch_request
    rv = self.dispatch_request()
  File "c:\users\认为、\appdata\local\programs\python\python37\lib\site-packages\flask\app.py", line 1799, in dispatch_request
    return self.view_functions[rule.endpoint](**req.view_args)
  File "D:\项目\project\app\routes.py", line 21, in check_account
    username = data['username']
TypeError: byte indices must be integers or slices, not str
2019-09-25 13:30:31,091 INFO: Microblog startup [in D:\项目\project\app\__init__.py:35]
2019-09-25 13:30:34,001 ERROR: Exception on /api/check_account [POST] [in c:\users\认为、\appdata\local\programs\python\python37\lib\site-packages\flask\app.py:1761]
Traceback (most recent call last):
  File "c:\users\认为、\appdata\local\programs\python\python37\lib\site-packages\flask\app.py", line 2292, in wsgi_app
    response = self.full_dispatch_request()
  File "c:\users\认为、\appdata\local\programs\python\python37\lib\site-packages\flask\app.py", line 1815, in full_dispatch_request
    rv = self.handle_user_exception(e)
  File "c:\users\认为、\appdata\local\programs\python\python37\lib\site-packages\flask\app.py", line 1718, in handle_user_exception
    reraise(exc_type, exc_value, tb)
  File "c:\users\认为、\appdata\local\programs\python\python37\lib\site-packages\flask\_compat.py", line 35, in reraise
    raise value
  File "c:\users\认为、\appdata\local\programs\python\python37\lib\site-packages\flask\app.py", line 1813, in full_dispatch_request
    rv = self.dispatch_request()
  File "c:\users\认为、\appdata\local\programs\python\python37\lib\site-packages\flask\app.py", line 1799, in dispatch_request
    return self.view_functions[rule.endpoint](**req.view_args)
  File "D:\项目\project\app\routes.py", line 16, in check_account
    data = dict(request.get_data())
TypeError: cannot convert dictionary update sequence element #0 to a sequence
2019-09-25 13:31:16,526 INFO: Microblog startup [in D:\项目\project\app\__init__.py:35]
2019-09-25 13:31:51,323 ERROR: Exception on /api/check_account [POST] [in c:\users\认为、\appdata\local\programs\python\python37\lib\site-packages\flask\app.py:1761]
Traceback (most recent call last):
  File "c:\users\认为、\appdata\local\programs\python\python37\lib\site-packages\werkzeug\wrappers.py", line 947, in _set_status_code
    self._status = '%d %s' % (code, HTTP_STATUS_CODES[code].upper())
KeyError: <Response 193 bytes [200 OK]>

During handling of the above exception, another exception occurred:

Traceback (most recent call last):
  File "c:\users\认为、\appdata\local\programs\python\python37\lib\site-packages\flask\app.py", line 2292, in wsgi_app
    response = self.full_dispatch_request()
  File "c:\users\认为、\appdata\local\programs\python\python37\lib\site-packages\flask\app.py", line 1816, in full_dispatch_request
    return self.finalize_request(rv)
  File "c:\users\认为、\appdata\local\programs\python\python37\lib\site-packages\flask\app.py", line 1831, in finalize_request
    response = self.make_response(rv)
  File "c:\users\认为、\appdata\local\programs\python\python37\lib\site-packages\flask\app.py", line 1989, in make_response
    rv.status_code = status
  File "c:\users\认为、\appdata\local\programs\python\python37\lib\site-packages\werkzeug\wrappers.py", line 949, in _set_status_code
    self._status = '%d UNKNOWN' % code
TypeError: %d format: a number is required, not Response
2019-09-25 13:32:35,775 INFO: Microblog startup [in D:\项目\project\app\__init__.py:35]
2019-09-25 13:44:07,675 INFO: Microblog startup [in D:\项目\project\app\__init__.py:35]
2019-09-25 13:44:52,790 INFO: Microblog startup [in D:\项目\project\app\__init__.py:35]
2019-09-25 15:47:46,683 INFO: Microblog startup [in D:\项目\project\app\__init__.py:35]
2019-09-25 15:51:31,285 INFO: Microblog startup [in D:\项目\project\app\__init__.py:35]
2019-09-25 15:51:57,684 ERROR: Exception on /api/check_account [POST] [in c:\users\认为、\appdata\local\programs\python\python37\lib\site-packages\flask\app.py:1761]
Traceback (most recent call last):
  File "c:\users\认为、\appdata\local\programs\python\python37\lib\site-packages\flask\app.py", line 2292, in wsgi_app
    response = self.full_dispatch_request()
  File "c:\users\认为、\appdata\local\programs\python\python37\lib\site-packages\flask\app.py", line 1815, in full_dispatch_request
    rv = self.handle_user_exception(e)
  File "c:\users\认为、\appdata\local\programs\python\python37\lib\site-packages\flask\app.py", line 1718, in handle_user_exception
    reraise(exc_type, exc_value, tb)
  File "c:\users\认为、\appdata\local\programs\python\python37\lib\site-packages\flask\_compat.py", line 35, in reraise
    raise value
  File "c:\users\认为、\appdata\local\programs\python\python37\lib\site-packages\flask\app.py", line 1813, in full_dispatch_request
    rv = self.dispatch_request()
  File "c:\users\认为、\appdata\local\programs\python\python37\lib\site-packages\flask\app.py", line 1799, in dispatch_request
    return self.view_functions[rule.endpoint](**req.view_args)
  File "D:\项目\project\app\routes.py", line 30, in check_account
    ,200,jsonify({"Authorization":jsonify({'token':'token '+token.decode('ascii'),'code':0})})
  File "c:\users\认为、\appdata\local\programs\python\python37\lib\site-packages\flask\json\__init__.py", line 321, in jsonify
    dumps(data, indent=indent, separators=separators) + '\n',
  File "c:\users\认为、\appdata\local\programs\python\python37\lib\site-packages\flask\json\__init__.py", line 179, in dumps
    rv = _json.dumps(obj, **kwargs)
  File "c:\users\认为、\appdata\local\programs\python\python37\lib\json\__init__.py", line 238, in dumps
    **kw).encode(obj)
  File "c:\users\认为、\appdata\local\programs\python\python37\lib\json\encoder.py", line 199, in encode
    chunks = self.iterencode(o, _one_shot=True)
  File "c:\users\认为、\appdata\local\programs\python\python37\lib\json\encoder.py", line 257, in iterencode
    return _iterencode(o, 0)
  File "c:\users\认为、\appdata\local\programs\python\python37\lib\site-packages\flask\json\__init__.py", line 81, in default
    return _json.JSONEncoder.default(self, o)
  File "c:\users\认为、\appdata\local\programs\python\python37\lib\json\encoder.py", line 179, in default
    raise TypeError(f'Object of type {o.__class__.__name__} '
TypeError: Object of type Response is not JSON serializable
2019-09-25 15:55:58,689 INFO: Microblog startup [in D:\项目\project\app\__init__.py:35]
2019-09-25 16:00:07,278 INFO: Microblog startup [in D:\项目\project\app\__init__.py:35]
2019-09-25 16:00:11,607 ERROR: Exception on /api/get_all_info [GET] [in c:\users\认为、\appdata\local\programs\python\python37\lib\site-packages\flask\app.py:1761]
Traceback (most recent call last):
  File "c:\users\认为、\appdata\local\programs\python\python37\lib\site-packages\flask\app.py", line 2292, in wsgi_app
    response = self.full_dispatch_request()
  File "c:\users\认为、\appdata\local\programs\python\python37\lib\site-packages\flask\app.py", line 1816, in full_dispatch_request
    return self.finalize_request(rv)
  File "c:\users\认为、\appdata\local\programs\python\python37\lib\site-packages\flask\app.py", line 1831, in finalize_request
    response = self.make_response(rv)
  File "c:\users\认为、\appdata\local\programs\python\python37\lib\site-packages\flask\app.py", line 1968, in make_response
    rv = self.response_class(rv, status=status, headers=headers)
  File "c:\users\认为、\appdata\local\programs\python\python37\lib\site-packages\werkzeug\wrappers.py", line 837, in __init__
    self.headers = Headers(headers)
  File "c:\users\认为、\appdata\local\programs\python\python37\lib\site-packages\werkzeug\datastructures.py", line 949, in __init__
    self.extend(defaults)
  File "c:\users\认为、\appdata\local\programs\python\python37\lib\site-packages\werkzeug\datastructures.py", line 1082, in extend
    for key, value in iterable:
TypeError: 'Response' object is not iterable
2019-09-25 16:00:29,621 ERROR: Exception on /api/get_all_info [GET] [in c:\users\认为、\appdata\local\programs\python\python37\lib\site-packages\flask\app.py:1761]
Traceback (most recent call last):
  File "c:\users\认为、\appdata\local\programs\python\python37\lib\site-packages\flask\app.py", line 2292, in wsgi_app
    response = self.full_dispatch_request()
  File "c:\users\认为、\appdata\local\programs\python\python37\lib\site-packages\flask\app.py", line 1816, in full_dispatch_request
    return self.finalize_request(rv)
  File "c:\users\认为、\appdata\local\programs\python\python37\lib\site-packages\flask\app.py", line 1831, in finalize_request
    response = self.make_response(rv)
  File "c:\users\认为、\appdata\local\programs\python\python37\lib\site-packages\flask\app.py", line 1968, in make_response
    rv = self.response_class(rv, status=status, headers=headers)
  File "c:\users\认为、\appdata\local\programs\python\python37\lib\site-packages\werkzeug\wrappers.py", line 837, in __init__
    self.headers = Headers(headers)
  File "c:\users\认为、\appdata\local\programs\python\python37\lib\site-packages\werkzeug\datastructures.py", line 949, in __init__
    self.extend(defaults)
  File "c:\users\认为、\appdata\local\programs\python\python37\lib\site-packages\werkzeug\datastructures.py", line 1082, in extend
    for key, value in iterable:
TypeError: 'Response' object is not iterable
2019-09-25 16:00:52,462 ERROR: Exception on /api/get_all_info [GET] [in c:\users\认为、\appdata\local\programs\python\python37\lib\site-packages\flask\app.py:1761]
Traceback (most recent call last):
  File "c:\users\认为、\appdata\local\programs\python\python37\lib\site-packages\flask\app.py", line 2292, in wsgi_app
    response = self.full_dispatch_request()
  File "c:\users\认为、\appdata\local\programs\python\python37\lib\site-packages\flask\app.py", line 1816, in full_dispatch_request
    return self.finalize_request(rv)
  File "c:\users\认为、\appdata\local\programs\python\python37\lib\site-packages\flask\app.py", line 1831, in finalize_request
    response = self.make_response(rv)
  File "c:\users\认为、\appdata\local\programs\python\python37\lib\site-packages\flask\app.py", line 1968, in make_response
    rv = self.response_class(rv, status=status, headers=headers)
  File "c:\users\认为、\appdata\local\programs\python\python37\lib\site-packages\werkzeug\wrappers.py", line 837, in __init__
    self.headers = Headers(headers)
  File "c:\users\认为、\appdata\local\programs\python\python37\lib\site-packages\werkzeug\datastructures.py", line 949, in __init__
    self.extend(defaults)
  File "c:\users\认为、\appdata\local\programs\python\python37\lib\site-packages\werkzeug\datastructures.py", line 1082, in extend
    for key, value in iterable:
TypeError: 'Response' object is not iterable
2019-09-25 16:01:11,131 ERROR: Exception on /api/get_all_info [GET] [in c:\users\认为、\appdata\local\programs\python\python37\lib\site-packages\flask\app.py:1761]
Traceback (most recent call last):
  File "c:\users\认为、\appdata\local\programs\python\python37\lib\site-packages\flask\app.py", line 2292, in wsgi_app
    response = self.full_dispatch_request()
  File "c:\users\认为、\appdata\local\programs\python\python37\lib\site-packages\flask\app.py", line 1816, in full_dispatch_request
    return self.finalize_request(rv)
  File "c:\users\认为、\appdata\local\programs\python\python37\lib\site-packages\flask\app.py", line 1831, in finalize_request
    response = self.make_response(rv)
  File "c:\users\认为、\appdata\local\programs\python\python37\lib\site-packages\flask\app.py", line 1968, in make_response
    rv = self.response_class(rv, status=status, headers=headers)
  File "c:\users\认为、\appdata\local\programs\python\python37\lib\site-packages\werkzeug\wrappers.py", line 837, in __init__
    self.headers = Headers(headers)
  File "c:\users\认为、\appdata\local\programs\python\python37\lib\site-packages\werkzeug\datastructures.py", line 949, in __init__
    self.extend(defaults)
  File "c:\users\认为、\appdata\local\programs\python\python37\lib\site-packages\werkzeug\datastructures.py", line 1082, in extend
    for key, value in iterable:
TypeError: 'Response' object is not iterable
2019-09-25 16:01:22,471 ERROR: Exception on /api/get_all_info [GET] [in c:\users\认为、\appdata\local\programs\python\python37\lib\site-packages\flask\app.py:1761]
Traceback (most recent call last):
  File "c:\users\认为、\appdata\local\programs\python\python37\lib\site-packages\flask\app.py", line 2292, in wsgi_app
    response = self.full_dispatch_request()
  File "c:\users\认为、\appdata\local\programs\python\python37\lib\site-packages\flask\app.py", line 1816, in full_dispatch_request
    return self.finalize_request(rv)
  File "c:\users\认为、\appdata\local\programs\python\python37\lib\site-packages\flask\app.py", line 1831, in finalize_request
    response = self.make_response(rv)
  File "c:\users\认为、\appdata\local\programs\python\python37\lib\site-packages\flask\app.py", line 1968, in make_response
    rv = self.response_class(rv, status=status, headers=headers)
  File "c:\users\认为、\appdata\local\programs\python\python37\lib\site-packages\werkzeug\wrappers.py", line 837, in __init__
    self.headers = Headers(headers)
  File "c:\users\认为、\appdata\local\programs\python\python37\lib\site-packages\werkzeug\datastructures.py", line 949, in __init__
    self.extend(defaults)
  File "c:\users\认为、\appdata\local\programs\python\python37\lib\site-packages\werkzeug\datastructures.py", line 1082, in extend
    for key, value in iterable:
TypeError: 'Response' object is not iterable
2019-09-25 16:02:57,203 INFO: Microblog startup [in D:\项目\project\app\__init__.py:35]
2019-09-25 16:06:04,983 INFO: Microblog startup [in D:\项目\project\app\__init__.py:35]
2019-09-25 16:45:13,998 INFO: Microblog startup [in D:\项目\project\app\__init__.py:35]
2019-09-25 16:45:36,063 INFO: Microblog startup [in D:\项目\project\app\__init__.py:35]
2019-09-25 16:47:47,105 ERROR: Exception on /api/get_all_info [GET] [in c:\users\认为、\appdata\local\programs\python\python37\lib\site-packages\flask\app.py:1761]
Traceback (most recent call last):
  File "c:\users\认为、\appdata\local\programs\python\python37\lib\site-packages\flask\app.py", line 2292, in wsgi_app
    response = self.full_dispatch_request()
  File "c:\users\认为、\appdata\local\programs\python\python37\lib\site-packages\flask\app.py", line 1815, in full_dispatch_request
    rv = self.handle_user_exception(e)
  File "c:\users\认为、\appdata\local\programs\python\python37\lib\site-packages\flask\app.py", line 1718, in handle_user_exception
    reraise(exc_type, exc_value, tb)
  File "c:\users\认为、\appdata\local\programs\python\python37\lib\site-packages\flask\_compat.py", line 35, in reraise
    raise value
  File "c:\users\认为、\appdata\local\programs\python\python37\lib\site-packages\flask\app.py", line 1813, in full_dispatch_request
    rv = self.dispatch_request()
  File "c:\users\认为、\appdata\local\programs\python\python37\lib\site-packages\flask\app.py", line 1799, in dispatch_request
    return self.view_functions[rule.endpoint](**req.view_args)
  File "c:\users\认为、\appdata\local\programs\python\python37\lib\site-packages\flask_httpauth.py", line 105, in decorated
    return f(*args, **kwargs)
  File "D:\项目\project\app\routes.py", line 89, in get_all_info
    return "",200,{'Authorization':'token '+token.decode('ascii'),'code':code}
NameError: name 'token' is not defined
2019-09-25 16:49:27,766 INFO: Microblog startup [in D:\项目\project\app\__init__.py:35]
2019-09-25 16:52:26,181 INFO: Microblog startup [in D:\项目\project\app\__init__.py:35]
2019-09-25 16:54:20,141 INFO: Microblog startup [in D:\项目\project\app\__init__.py:35]
2019-09-25 16:57:34,294 INFO: Microblog startup [in D:\项目\project\app\__init__.py:35]
2019-09-25 17:52:24,269 INFO: Microblog startup [in D:\项目\project\app\__init__.py:35]
2019-09-25 17:52:31,945 ERROR: Exception on /api/check_account [POST] [in c:\users\认为、\appdata\local\programs\python\python37\lib\site-packages\flask\app.py:1761]
Traceback (most recent call last):
  File "c:\users\认为、\appdata\local\programs\python\python37\lib\site-packages\flask\app.py", line 2292, in wsgi_app
    response = self.full_dispatch_request()
  File "c:\users\认为、\appdata\local\programs\python\python37\lib\site-packages\flask\app.py", line 1815, in full_dispatch_request
    rv = self.handle_user_exception(e)
  File "c:\users\认为、\appdata\local\programs\python\python37\lib\site-packages\flask\app.py", line 1718, in handle_user_exception
    reraise(exc_type, exc_value, tb)
  File "c:\users\认为、\appdata\local\programs\python\python37\lib\site-packages\flask\_compat.py", line 35, in reraise
    raise value
  File "c:\users\认为、\appdata\local\programs\python\python37\lib\site-packages\flask\app.py", line 1813, in full_dispatch_request
    rv = self.dispatch_request()
  File "c:\users\认为、\appdata\local\programs\python\python37\lib\site-packages\flask\app.py", line 1799, in dispatch_request
    return self.view_functions[rule.endpoint](**req.view_args)
  File "D:\项目\project\app\routes.py", line 30, in check_account
    print(user.ip)
AttributeError: 'User' object has no attribute 'ip'
2019-09-25 17:54:33,618 INFO: Microblog startup [in D:\项目\project\app\__init__.py:35]
2019-09-25 17:55:25,962 INFO: Microblog startup [in D:\项目\project\app\__init__.py:35]
2019-09-25 17:56:35,923 INFO: Microblog startup [in D:\项目\project\app\__init__.py:35]
2019-09-25 17:56:45,759 ERROR: Exception on /api/check_account [POST] [in c:\users\认为、\appdata\local\programs\python\python37\lib\site-packages\flask\app.py:1761]
Traceback (most recent call last):
  File "c:\users\认为、\appdata\local\programs\python\python37\lib\site-packages\flask\app.py", line 2292, in wsgi_app
    response = self.full_dispatch_request()
  File "c:\users\认为、\appdata\local\programs\python\python37\lib\site-packages\flask\app.py", line 1815, in full_dispatch_request
    rv = self.handle_user_exception(e)
  File "c:\users\认为、\appdata\local\programs\python\python37\lib\site-packages\flask\app.py", line 1718, in handle_user_exception
    reraise(exc_type, exc_value, tb)
  File "c:\users\认为、\appdata\local\programs\python\python37\lib\site-packages\flask\_compat.py", line 35, in reraise
    raise value
  File "c:\users\认为、\appdata\local\programs\python\python37\lib\site-packages\flask\app.py", line 1813, in full_dispatch_request
    rv = self.dispatch_request()
  File "c:\users\认为、\appdata\local\programs\python\python37\lib\site-packages\flask\app.py", line 1799, in dispatch_request
    return self.view_functions[rule.endpoint](**req.view_args)
  File "D:\项目\project\app\routes.py", line 27, in check_account
    user.add_ip(ip)
  File "D:\项目\project\app\models.py", line 63, in add_ip
    if ip_addr!=None and len(self.ip_addr)/15<=right:
TypeError: object of type 'NoneType' has no len()
2019-09-25 17:57:58,670 INFO: Microblog startup [in D:\项目\project\app\__init__.py:35]
2019-09-25 17:58:03,385 ERROR: Exception on /api/check_account [POST] [in c:\users\认为、\appdata\local\programs\python\python37\lib\site-packages\flask\app.py:1761]
Traceback (most recent call last):
  File "c:\users\认为、\appdata\local\programs\python\python37\lib\site-packages\flask\app.py", line 2292, in wsgi_app
    response = self.full_dispatch_request()
  File "c:\users\认为、\appdata\local\programs\python\python37\lib\site-packages\flask\app.py", line 1815, in full_dispatch_request
    rv = self.handle_user_exception(e)
  File "c:\users\认为、\appdata\local\programs\python\python37\lib\site-packages\flask\app.py", line 1718, in handle_user_exception
    reraise(exc_type, exc_value, tb)
  File "c:\users\认为、\appdata\local\programs\python\python37\lib\site-packages\flask\_compat.py", line 35, in reraise
    raise value
  File "c:\users\认为、\appdata\local\programs\python\python37\lib\site-packages\flask\app.py", line 1813, in full_dispatch_request
    rv = self.dispatch_request()
  File "c:\users\认为、\appdata\local\programs\python\python37\lib\site-packages\flask\app.py", line 1799, in dispatch_request
    return self.view_functions[rule.endpoint](**req.view_args)
  File "D:\项目\project\app\routes.py", line 27, in check_account
    user.add_ip(ip)
  File "D:\项目\project\app\models.py", line 65, in add_ip
    if ip_addr!=None and len(self.ip_addr)/15<=right:
NameError: name 'right' is not defined
2019-09-25 17:59:35,770 ERROR: Exception on /api/check_account [POST] [in c:\users\认为、\appdata\local\programs\python\python37\lib\site-packages\flask\app.py:1761]
Traceback (most recent call last):
  File "c:\users\认为、\appdata\local\programs\python\python37\lib\site-packages\flask\app.py", line 2292, in wsgi_app
    response = self.full_dispatch_request()
  File "c:\users\认为、\appdata\local\programs\python\python37\lib\site-packages\flask\app.py", line 1815, in full_dispatch_request
    rv = self.handle_user_exception(e)
  File "c:\users\认为、\appdata\local\programs\python\python37\lib\site-packages\flask\app.py", line 1718, in handle_user_exception
    reraise(exc_type, exc_value, tb)
  File "c:\users\认为、\appdata\local\programs\python\python37\lib\site-packages\flask\_compat.py", line 35, in reraise
    raise value
  File "c:\users\认为、\appdata\local\programs\python\python37\lib\site-packages\flask\app.py", line 1813, in full_dispatch_request
    rv = self.dispatch_request()
  File "c:\users\认为、\appdata\local\programs\python\python37\lib\site-packages\flask\app.py", line 1799, in dispatch_request
    return self.view_functions[rule.endpoint](**req.view_args)
  File "D:\项目\project\app\routes.py", line 27, in check_account
    user.add_ip(ip)
  File "D:\项目\project\app\models.py", line 65, in add_ip
    self.ip_addr = ip_addr
NameError: name 'right' is not defined
2019-09-25 18:02:29,163 INFO: Microblog startup [in D:\项目\project\app\__init__.py:35]
2019-09-25 20:50:31,661 ERROR: Exception on /api/check_account [POST] [in c:\users\认为、\appdata\local\programs\python\python37\lib\site-packages\flask\app.py:1761]
Traceback (most recent call last):
  File "c:\users\认为、\appdata\local\programs\python\python37\lib\site-packages\flask\app.py", line 2292, in wsgi_app
    response = self.full_dispatch_request()
  File "c:\users\认为、\appdata\local\programs\python\python37\lib\site-packages\flask\app.py", line 1815, in full_dispatch_request
    rv = self.handle_user_exception(e)
  File "c:\users\认为、\appdata\local\programs\python\python37\lib\site-packages\flask\app.py", line 1718, in handle_user_exception
    reraise(exc_type, exc_value, tb)
  File "c:\users\认为、\appdata\local\programs\python\python37\lib\site-packages\flask\_compat.py", line 35, in reraise
    raise value
  File "c:\users\认为、\appdata\local\programs\python\python37\lib\site-packages\flask\app.py", line 1813, in full_dispatch_request
    rv = self.dispatch_request()
  File "c:\users\认为、\appdata\local\programs\python\python37\lib\site-packages\flask\app.py", line 1799, in dispatch_request
    return self.view_functions[rule.endpoint](**req.view_args)
  File "D:\项目\project\app\routes.py", line 27, in check_account
    user.add_ip(ip)
  File "D:\项目\project\app\models.py", line 66, in add_ip
    if ip_addr!=None and len(self.ip_addr)/15<=self.right:
TypeError: '<=' not supported between instances of 'float' and 'NoneType'
2019-09-25 21:13:34,434 INFO: Microblog startup [in D:\项目\project\app\__init__.py:35]
2019-09-25 22:37:03,482 INFO: Microblog startup [in D:\项目\project\app\__init__.py:35]
2019-09-26 16:21:59,582 INFO: Microblog startup [in D:\项目\project\app\__init__.py:35]
2019-09-27 21:13:25,975 INFO: Microblog startup [in D:\项目\project\app\__init__.py:35]
2019-09-27 21:16:21,718 INFO: Microblog startup [in D:\项目\project\app\__init__.py:35]
2019-09-27 21:16:41,794 INFO: Microblog startup [in D:\项目\project\app\__init__.py:35]
2019-09-27 21:17:01,643 INFO: Microblog startup [in D:\项目\project\app\__init__.py:35]
2019-09-27 21:17:28,532 INFO: Microblog startup [in D:\项目\project\app\__init__.py:35]
2019-09-28 20:58:49,893 INFO: Microblog startup [in D:\项目\project\app\__init__.py:35]
2019-09-28 21:01:50,562 INFO: Microblog startup [in D:\项目\project\app\__init__.py:35]
2019-09-28 21:02:23,083 INFO: Microblog startup [in D:\项目\project\app\__init__.py:35]
2019-09-28 21:02:40,435 INFO: Microblog startup [in D:\项目\project\app\__init__.py:35]
2019-09-28 21:03:05,575 INFO: Microblog startup [in D:\项目\project\app\__init__.py:35]
2019-09-28 21:07:31,507 INFO: Microblog startup [in D:\项目\project\app\__init__.py:35]
2019-09-28 21:09:30,720 ERROR: Exception on /api/check_account [POST] [in c:\users\认为、\appdata\local\programs\python\python37\lib\site-packages\flask\app.py:1761]
Traceback (most recent call last):
  File "c:\users\认为、\appdata\local\programs\python\python37\lib\site-packages\flask\app.py", line 2292, in wsgi_app
    response = self.full_dispatch_request()
  File "c:\users\认为、\appdata\local\programs\python\python37\lib\site-packages\flask\app.py", line 1815, in full_dispatch_request
    rv = self.handle_user_exception(e)
  File "c:\users\认为、\appdata\local\programs\python\python37\lib\site-packages\flask\app.py", line 1718, in handle_user_exception
    reraise(exc_type, exc_value, tb)
  File "c:\users\认为、\appdata\local\programs\python\python37\lib\site-packages\flask\_compat.py", line 35, in reraise
    raise value
  File "c:\users\认为、\appdata\local\programs\python\python37\lib\site-packages\flask\app.py", line 1813, in full_dispatch_request
    rv = self.dispatch_request()
  File "c:\users\认为、\appdata\local\programs\python\python37\lib\site-packages\flask\app.py", line 1799, in dispatch_request
    return self.view_functions[rule.endpoint](**req.view_args)
  File "D:\项目\project\app\routes.py", line 23, in check_account
    ok = verify_password(telnum, password)
  File "D:\项目\project\app\models.py", line 167, in verify_password
    if not user or not user.check_password(password):
  File "D:\项目\project\app\models.py", line 55, in check_password
    return check_password_hash(self.password_hash, password)
  File "c:\users\认为、\appdata\local\programs\python\python37\lib\site-packages\werkzeug\security.py", line 248, in check_password_hash
    return safe_str_cmp(_hash_internal(method, salt, password)[0], hashval)
  File "c:\users\认为、\appdata\local\programs\python\python37\lib\site-packages\werkzeug\security.py", line 192, in _hash_internal
    hashfunc=hash_func)
  File "c:\users\认为、\appdata\local\programs\python\python37\lib\site-packages\werkzeug\security.py", line 64, in pbkdf2_hex
    rv = pbkdf2_bin(data, salt, iterations, keylen, hashfunc)
  File "c:\users\认为、\appdata\local\programs\python\python37\lib\site-packages\werkzeug\security.py", line 93, in pbkdf2_bin
    data = to_bytes(data)
  File "c:\users\认为、\appdata\local\programs\python\python37\lib\site-packages\werkzeug\_compat.py", line 190, in to_bytes
    raise TypeError('Expected bytes')
TypeError: Expected bytes
2019-09-28 21:19:34,086 INFO: Microblog startup [in D:\项目\project\app\__init__.py:35]
2019-09-28 21:19:53,887 INFO: Microblog startup [in D:\项目\project\app\__init__.py:35]
2019-09-28 21:21:29,369 ERROR: Exception on /api/check_account [POST] [in c:\users\认为、\appdata\local\programs\python\python37\lib\site-packages\flask\app.py:1761]
Traceback (most recent call last):
  File "c:\users\认为、\appdata\local\programs\python\python37\lib\site-packages\flask\app.py", line 2292, in wsgi_app
    response = self.full_dispatch_request()
  File "c:\users\认为、\appdata\local\programs\python\python37\lib\site-packages\flask\app.py", line 1815, in full_dispatch_request
    rv = self.handle_user_exception(e)
  File "c:\users\认为、\appdata\local\programs\python\python37\lib\site-packages\flask\app.py", line 1718, in handle_user_exception
    reraise(exc_type, exc_value, tb)
  File "c:\users\认为、\appdata\local\programs\python\python37\lib\site-packages\flask\_compat.py", line 35, in reraise
    raise value
  File "c:\users\认为、\appdata\local\programs\python\python37\lib\site-packages\flask\app.py", line 1813, in full_dispatch_request
    rv = self.dispatch_request()
  File "c:\users\认为、\appdata\local\programs\python\python37\lib\site-packages\flask\app.py", line 1799, in dispatch_request
    return self.view_functions[rule.endpoint](**req.view_args)
  File "D:\项目\project\app\routes.py", line 23, in check_account
    ok = verify_password(telnum, password)
  File "D:\项目\project\app\models.py", line 172, in verify_password
    user = User.query.filter_by(telnum = username_or_token).first()
  File "c:\users\认为、\appdata\local\programs\python\python37\lib\site-packages\sqlalchemy\orm\query.py", line 3232, in first
    ret = list(self[0:1])
  File "c:\users\认为、\appdata\local\programs\python\python37\lib\site-packages\sqlalchemy\orm\query.py", line 3018, in __getitem__
    return list(res)
  File "c:\users\认为、\appdata\local\programs\python\python37\lib\site-packages\sqlalchemy\orm\loading.py", line 105, in instances
    util.raise_from_cause(err)
  File "c:\users\认为、\appdata\local\programs\python\python37\lib\site-packages\sqlalchemy\util\compat.py", line 398, in raise_from_cause
    reraise(type(exception), exception, tb=exc_tb, cause=cause)
  File "c:\users\认为、\appdata\local\programs\python\python37\lib\site-packages\sqlalchemy\util\compat.py", line 153, in reraise
    raise value
  File "c:\users\认为、\appdata\local\programs\python\python37\lib\site-packages\sqlalchemy\orm\loading.py", line 85, in instances
    rows = [proc(row) for row in fetch]
  File "c:\users\认为、\appdata\local\programs\python\python37\lib\site-packages\sqlalchemy\orm\loading.py", line 85, in <listcomp>
    rows = [proc(row) for row in fetch]
  File "c:\users\认为、\appdata\local\programs\python\python37\lib\site-packages\sqlalchemy\orm\loading.py", line 572, in _instance
    populators,
  File "c:\users\认为、\appdata\local\programs\python\python37\lib\site-packages\sqlalchemy\orm\loading.py", line 693, in _populate_full
    dict_[key] = getter(row)
  File "c:\users\认为、\appdata\local\programs\python\python37\lib\site-packages\sqlalchemy\sql\sqltypes.py", line 1681, in process
    value = impl_processor(value)
  File "c:\users\认为、\appdata\local\programs\python\python37\lib\site-packages\sqlalchemy\sql\sqltypes.py", line 944, in process
    value = bytes(value)
TypeError: string argument without an encoding
2019-09-28 21:23:50,283 INFO: Microblog startup [in D:\项目\project\app\__init__.py:35]
