2019-10-12 16:28:30,143 ERROR: Exception on /api/search [POST] [in c:\users\认为、\appdata\local\programs\python\python37\lib\site-packages\flask\app.py:1761]
Traceback (most recent call last):
  File "c:\users\认为、\appdata\local\programs\python\python37\lib\site-packages\flask\app.py", line 2292, in wsgi_app
    response = self.full_dispatch_request()
  File "c:\users\认为、\appdata\local\programs\python\python37\lib\site-packages\flask\app.py", line 1816, in full_dispatch_request
    return self.finalize_request(rv)
  File "c:\users\认为、\appdata\local\programs\python\python37\lib\site-packages\flask\app.py", line 1833, in finalize_request
    response = self.process_response(response)
  File "c:\users\认为、\appdata\local\programs\python\python37\lib\site-packages\flask\app.py", line 2114, in process_response
    self.session_interface.save_session(self, ctx.session, response)
  File "c:\users\认为、\appdata\local\programs\python\python37\lib\site-packages\flask\sessions.py", line 375, in save_session
    val = self.get_signing_serializer(app).dumps(dict(session))
  File "c:\users\认为、\appdata\local\programs\python\python37\lib\site-packages\itsdangerous\serializer.py", line 166, in dumps
    payload = want_bytes(self.dump_payload(obj))
  File "c:\users\认为、\appdata\local\programs\python\python37\lib\site-packages\itsdangerous\url_safe.py", line 42, in dump_payload
    json = super(URLSafeSerializerMixin, self).dump_payload(obj)
  File "c:\users\认为、\appdata\local\programs\python\python37\lib\site-packages\itsdangerous\serializer.py", line 133, in dump_payload
    return want_bytes(self.serializer.dumps(obj, **self.serializer_kwargs))
  File "c:\users\认为、\appdata\local\programs\python\python37\lib\site-packages\flask\json\tag.py", line 296, in dumps
    return dumps(self.tag(value), separators=(',', ':'))
  File "c:\users\认为、\appdata\local\programs\python\python37\lib\site-packages\flask\json\__init__.py", line 179, in dumps
    rv = _json.dumps(obj, **kwargs)
  File "c:\users\认为、\appdata\local\programs\python\python37\lib\json\__init__.py", line 238, in dumps
    **kw).encode(obj)
  File "c:\users\认为、\appdata\local\programs\python\python37\lib\json\encoder.py", line 199, in encode
    chunks = self.iterencode(o, _one_shot=True)
  File "c:\users\认为、\appdata\local\programs\python\python37\lib\json\encoder.py", line 257, in iterencode
    return _iterencode(o, 0)
  File "c:\users\认为、\appdata\local\programs\python\python37\lib\site-packages\flask\json\__init__.py", line 81, in default
    return _json.JSONEncoder.default(self, o)
  File "c:\users\认为、\appdata\local\programs\python\python37\lib\json\encoder.py", line 179, in default
    raise TypeError(f'Object of type {o.__class__.__name__} '
TypeError: Object of type store_info is not JSON serializable
2019-10-12 16:29:25,467 INFO: Microblog startup [in D:\项目\project\app\__init__.py:39]
2019-10-12 16:29:27,787 ERROR: Exception on /api/search [POST] [in c:\users\认为、\appdata\local\programs\python\python37\lib\site-packages\flask\app.py:1761]
Traceback (most recent call last):
  File "c:\users\认为、\appdata\local\programs\python\python37\lib\site-packages\flask\app.py", line 2292, in wsgi_app
    response = self.full_dispatch_request()
  File "c:\users\认为、\appdata\local\programs\python\python37\lib\site-packages\flask\app.py", line 1816, in full_dispatch_request
    return self.finalize_request(rv)
  File "c:\users\认为、\appdata\local\programs\python\python37\lib\site-packages\flask\app.py", line 1833, in finalize_request
    response = self.process_response(response)
  File "c:\users\认为、\appdata\local\programs\python\python37\lib\site-packages\flask\app.py", line 2114, in process_response
    self.session_interface.save_session(self, ctx.session, response)
  File "c:\users\认为、\appdata\local\programs\python\python37\lib\site-packages\flask\sessions.py", line 375, in save_session
    val = self.get_signing_serializer(app).dumps(dict(session))
  File "c:\users\认为、\appdata\local\programs\python\python37\lib\site-packages\itsdangerous\serializer.py", line 166, in dumps
    payload = want_bytes(self.dump_payload(obj))
  File "c:\users\认为、\appdata\local\programs\python\python37\lib\site-packages\itsdangerous\url_safe.py", line 42, in dump_payload
    json = super(URLSafeSerializerMixin, self).dump_payload(obj)
  File "c:\users\认为、\appdata\local\programs\python\python37\lib\site-packages\itsdangerous\serializer.py", line 133, in dump_payload
    return want_bytes(self.serializer.dumps(obj, **self.serializer_kwargs))
  File "c:\users\认为、\appdata\local\programs\python\python37\lib\site-packages\flask\json\tag.py", line 296, in dumps
    return dumps(self.tag(value), separators=(',', ':'))
  File "c:\users\认为、\appdata\local\programs\python\python37\lib\site-packages\flask\json\__init__.py", line 179, in dumps
    rv = _json.dumps(obj, **kwargs)
  File "c:\users\认为、\appdata\local\programs\python\python37\lib\json\__init__.py", line 238, in dumps
    **kw).encode(obj)
  File "c:\users\认为、\appdata\local\programs\python\python37\lib\json\encoder.py", line 199, in encode
    chunks = self.iterencode(o, _one_shot=True)
  File "c:\users\认为、\appdata\local\programs\python\python37\lib\json\encoder.py", line 257, in iterencode
    return _iterencode(o, 0)
  File "c:\users\认为、\appdata\local\programs\python\python37\lib\site-packages\flask\json\__init__.py", line 81, in default
    return _json.JSONEncoder.default(self, o)
  File "c:\users\认为、\appdata\local\programs\python\python37\lib\json\encoder.py", line 179, in default
    raise TypeError(f'Object of type {o.__class__.__name__} '
TypeError: Object of type store_info is not JSON serializable
2019-10-12 16:29:53,889 INFO: Microblog startup [in D:\项目\project\app\__init__.py:39]
2019-10-12 16:29:56,942 ERROR: Exception on /api/search [POST] [in c:\users\认为、\appdata\local\programs\python\python37\lib\site-packages\flask\app.py:1761]
Traceback (most recent call last):
  File "c:\users\认为、\appdata\local\programs\python\python37\lib\site-packages\flask\app.py", line 2292, in wsgi_app
    response = self.full_dispatch_request()
  File "c:\users\认为、\appdata\local\programs\python\python37\lib\site-packages\flask\app.py", line 1816, in full_dispatch_request
    return self.finalize_request(rv)
  File "c:\users\认为、\appdata\local\programs\python\python37\lib\site-packages\flask\app.py", line 1833, in finalize_request
    response = self.process_response(response)
  File "c:\users\认为、\appdata\local\programs\python\python37\lib\site-packages\flask\app.py", line 2114, in process_response
    self.session_interface.save_session(self, ctx.session, response)
  File "c:\users\认为、\appdata\local\programs\python\python37\lib\site-packages\flask\sessions.py", line 375, in save_session
    val = self.get_signing_serializer(app).dumps(dict(session))
  File "c:\users\认为、\appdata\local\programs\python\python37\lib\site-packages\itsdangerous\serializer.py", line 166, in dumps
    payload = want_bytes(self.dump_payload(obj))
  File "c:\users\认为、\appdata\local\programs\python\python37\lib\site-packages\itsdangerous\url_safe.py", line 42, in dump_payload
    json = super(URLSafeSerializerMixin, self).dump_payload(obj)
  File "c:\users\认为、\appdata\local\programs\python\python37\lib\site-packages\itsdangerous\serializer.py", line 133, in dump_payload
    return want_bytes(self.serializer.dumps(obj, **self.serializer_kwargs))
  File "c:\users\认为、\appdata\local\programs\python\python37\lib\site-packages\flask\json\tag.py", line 296, in dumps
    return dumps(self.tag(value), separators=(',', ':'))
  File "c:\users\认为、\appdata\local\programs\python\python37\lib\site-packages\flask\json\__init__.py", line 179, in dumps
    rv = _json.dumps(obj, **kwargs)
  File "c:\users\认为、\appdata\local\programs\python\python37\lib\json\__init__.py", line 238, in dumps
    **kw).encode(obj)
  File "c:\users\认为、\appdata\local\programs\python\python37\lib\json\encoder.py", line 199, in encode
    chunks = self.iterencode(o, _one_shot=True)
  File "c:\users\认为、\appdata\local\programs\python\python37\lib\json\encoder.py", line 257, in iterencode
    return _iterencode(o, 0)
  File "c:\users\认为、\appdata\local\programs\python\python37\lib\site-packages\flask\json\__init__.py", line 81, in default
    return _json.JSONEncoder.default(self, o)
  File "c:\users\认为、\appdata\local\programs\python\python37\lib\json\encoder.py", line 179, in default
    raise TypeError(f'Object of type {o.__class__.__name__} '
TypeError: Object of type store_info is not JSON serializable
2019-10-12 16:30:21,434 INFO: Microblog startup [in D:\项目\project\app\__init__.py:39]
2019-10-12 16:30:23,650 ERROR: Exception on /api/search [POST] [in c:\users\认为、\appdata\local\programs\python\python37\lib\site-packages\flask\app.py:1761]
Traceback (most recent call last):
  File "c:\users\认为、\appdata\local\programs\python\python37\lib\site-packages\flask\app.py", line 2292, in wsgi_app
    response = self.full_dispatch_request()
  File "c:\users\认为、\appdata\local\programs\python\python37\lib\site-packages\flask\app.py", line 1816, in full_dispatch_request
    return self.finalize_request(rv)
  File "c:\users\认为、\appdata\local\programs\python\python37\lib\site-packages\flask\app.py", line 1833, in finalize_request
    response = self.process_response(response)
  File "c:\users\认为、\appdata\local\programs\python\python37\lib\site-packages\flask\app.py", line 2114, in process_response
    self.session_interface.save_session(self, ctx.session, response)
  File "c:\users\认为、\appdata\local\programs\python\python37\lib\site-packages\flask\sessions.py", line 375, in save_session
    val = self.get_signing_serializer(app).dumps(dict(session))
  File "c:\users\认为、\appdata\local\programs\python\python37\lib\site-packages\itsdangerous\serializer.py", line 166, in dumps
    payload = want_bytes(self.dump_payload(obj))
  File "c:\users\认为、\appdata\local\programs\python\python37\lib\site-packages\itsdangerous\url_safe.py", line 42, in dump_payload
    json = super(URLSafeSerializerMixin, self).dump_payload(obj)
  File "c:\users\认为、\appdata\local\programs\python\python37\lib\site-packages\itsdangerous\serializer.py", line 133, in dump_payload
    return want_bytes(self.serializer.dumps(obj, **self.serializer_kwargs))
  File "c:\users\认为、\appdata\local\programs\python\python37\lib\site-packages\flask\json\tag.py", line 296, in dumps
    return dumps(self.tag(value), separators=(',', ':'))
  File "c:\users\认为、\appdata\local\programs\python\python37\lib\site-packages\flask\json\__init__.py", line 179, in dumps
    rv = _json.dumps(obj, **kwargs)
  File "c:\users\认为、\appdata\local\programs\python\python37\lib\json\__init__.py", line 238, in dumps
    **kw).encode(obj)
  File "c:\users\认为、\appdata\local\programs\python\python37\lib\json\encoder.py", line 199, in encode
    chunks = self.iterencode(o, _one_shot=True)
  File "c:\users\认为、\appdata\local\programs\python\python37\lib\json\encoder.py", line 257, in iterencode
    return _iterencode(o, 0)
  File "c:\users\认为、\appdata\local\programs\python\python37\lib\site-packages\flask\json\__init__.py", line 81, in default
    return _json.JSONEncoder.default(self, o)
  File "c:\users\认为、\appdata\local\programs\python\python37\lib\json\encoder.py", line 179, in default
    raise TypeError(f'Object of type {o.__class__.__name__} '
TypeError: Object of type store_info is not JSON serializable
2019-10-12 16:32:13,248 INFO: Microblog startup [in D:\项目\project\app\__init__.py:39]
2019-10-12 16:32:15,477 ERROR: Exception on /api/search [POST] [in c:\users\认为、\appdata\local\programs\python\python37\lib\site-packages\flask\app.py:1761]
Traceback (most recent call last):
  File "c:\users\认为、\appdata\local\programs\python\python37\lib\site-packages\flask\app.py", line 2292, in wsgi_app
    response = self.full_dispatch_request()
  File "c:\users\认为、\appdata\local\programs\python\python37\lib\site-packages\flask\app.py", line 1816, in full_dispatch_request
    return self.finalize_request(rv)
  File "c:\users\认为、\appdata\local\programs\python\python37\lib\site-packages\flask\app.py", line 1833, in finalize_request
    response = self.process_response(response)
  File "c:\users\认为、\appdata\local\programs\python\python37\lib\site-packages\flask\app.py", line 2114, in process_response
    self.session_interface.save_session(self, ctx.session, response)
  File "c:\users\认为、\appdata\local\programs\python\python37\lib\site-packages\flask\sessions.py", line 375, in save_session
    val = self.get_signing_serializer(app).dumps(dict(session))
  File "c:\users\认为、\appdata\local\programs\python\python37\lib\site-packages\itsdangerous\serializer.py", line 166, in dumps
    payload = want_bytes(self.dump_payload(obj))
  File "c:\users\认为、\appdata\local\programs\python\python37\lib\site-packages\itsdangerous\url_safe.py", line 42, in dump_payload
    json = super(URLSafeSerializerMixin, self).dump_payload(obj)
  File "c:\users\认为、\appdata\local\programs\python\python37\lib\site-packages\itsdangerous\serializer.py", line 133, in dump_payload
    return want_bytes(self.serializer.dumps(obj, **self.serializer_kwargs))
  File "c:\users\认为、\appdata\local\programs\python\python37\lib\site-packages\flask\json\tag.py", line 296, in dumps
    return dumps(self.tag(value), separators=(',', ':'))
  File "c:\users\认为、\appdata\local\programs\python\python37\lib\site-packages\flask\json\__init__.py", line 179, in dumps
    rv = _json.dumps(obj, **kwargs)
  File "c:\users\认为、\appdata\local\programs\python\python37\lib\json\__init__.py", line 238, in dumps
    **kw).encode(obj)
  File "c:\users\认为、\appdata\local\programs\python\python37\lib\json\encoder.py", line 199, in encode
    chunks = self.iterencode(o, _one_shot=True)
  File "c:\users\认为、\appdata\local\programs\python\python37\lib\json\encoder.py", line 257, in iterencode
    return _iterencode(o, 0)
  File "c:\users\认为、\appdata\local\programs\python\python37\lib\site-packages\flask\json\__init__.py", line 81, in default
    return _json.JSONEncoder.default(self, o)
  File "c:\users\认为、\appdata\local\programs\python\python37\lib\json\encoder.py", line 179, in default
    raise TypeError(f'Object of type {o.__class__.__name__} '
TypeError: Object of type store_info is not JSON serializable
2019-10-12 16:32:48,671 INFO: Microblog startup [in D:\项目\project\app\__init__.py:39]
2019-10-12 16:32:53,227 ERROR: Exception on /api/search [POST] [in c:\users\认为、\appdata\local\programs\python\python37\lib\site-packages\flask\app.py:1761]
Traceback (most recent call last):
  File "c:\users\认为、\appdata\local\programs\python\python37\lib\site-packages\flask\app.py", line 2292, in wsgi_app
    response = self.full_dispatch_request()
  File "c:\users\认为、\appdata\local\programs\python\python37\lib\site-packages\flask\app.py", line 1816, in full_dispatch_request
    return self.finalize_request(rv)
  File "c:\users\认为、\appdata\local\programs\python\python37\lib\site-packages\flask\app.py", line 1833, in finalize_request
    response = self.process_response(response)
  File "c:\users\认为、\appdata\local\programs\python\python37\lib\site-packages\flask\app.py", line 2114, in process_response
    self.session_interface.save_session(self, ctx.session, response)
  File "c:\users\认为、\appdata\local\programs\python\python37\lib\site-packages\flask\sessions.py", line 375, in save_session
    val = self.get_signing_serializer(app).dumps(dict(session))
  File "c:\users\认为、\appdata\local\programs\python\python37\lib\site-packages\itsdangerous\serializer.py", line 166, in dumps
    payload = want_bytes(self.dump_payload(obj))
  File "c:\users\认为、\appdata\local\programs\python\python37\lib\site-packages\itsdangerous\url_safe.py", line 42, in dump_payload
    json = super(URLSafeSerializerMixin, self).dump_payload(obj)
  File "c:\users\认为、\appdata\local\programs\python\python37\lib\site-packages\itsdangerous\serializer.py", line 133, in dump_payload
    return want_bytes(self.serializer.dumps(obj, **self.serializer_kwargs))
  File "c:\users\认为、\appdata\local\programs\python\python37\lib\site-packages\flask\json\tag.py", line 296, in dumps
    return dumps(self.tag(value), separators=(',', ':'))
  File "c:\users\认为、\appdata\local\programs\python\python37\lib\site-packages\flask\json\__init__.py", line 179, in dumps
    rv = _json.dumps(obj, **kwargs)
  File "c:\users\认为、\appdata\local\programs\python\python37\lib\json\__init__.py", line 238, in dumps
    **kw).encode(obj)
  File "c:\users\认为、\appdata\local\programs\python\python37\lib\json\encoder.py", line 199, in encode
    chunks = self.iterencode(o, _one_shot=True)
  File "c:\users\认为、\appdata\local\programs\python\python37\lib\json\encoder.py", line 257, in iterencode
    return _iterencode(o, 0)
  File "c:\users\认为、\appdata\local\programs\python\python37\lib\site-packages\flask\json\__init__.py", line 81, in default
    return _json.JSONEncoder.default(self, o)
  File "c:\users\认为、\appdata\local\programs\python\python37\lib\json\encoder.py", line 179, in default
    raise TypeError(f'Object of type {o.__class__.__name__} '
TypeError: Object of type store_info is not JSON serializable
2019-10-12 16:34:10,905 INFO: Microblog startup [in D:\项目\project\app\__init__.py:39]
2019-10-12 16:34:39,692 INFO: Microblog startup [in D:\项目\project\app\__init__.py:39]
2019-10-12 16:35:13,852 INFO: Microblog startup [in D:\项目\project\app\__init__.py:39]
2019-10-12 16:35:42,118 INFO: Microblog startup [in D:\项目\project\app\__init__.py:39]
2019-10-12 16:36:24,563 INFO: Microblog startup [in D:\项目\project\app\__init__.py:39]
2019-10-12 16:37:27,501 INFO: Microblog startup [in D:\项目\project\app\__init__.py:39]
2019-10-12 17:41:03,617 INFO: Microblog startup [in D:\项目\project\app\__init__.py:39]
2019-10-12 17:41:07,116 INFO: Microblog startup [in D:\项目\project\app\__init__.py:39]
2019-10-12 17:41:12,472 INFO: Microblog startup [in D:\项目\project\app\__init__.py:39]
2019-10-12 17:47:43,378 ERROR: Exception on /api/get_user_info [POST] [in c:\users\认为、\appdata\local\programs\python\python37\lib\site-packages\flask\app.py:1761]
Traceback (most recent call last):
  File "c:\users\认为、\appdata\local\programs\python\python37\lib\site-packages\flask\app.py", line 2292, in wsgi_app
    response = self.full_dispatch_request()
  File "c:\users\认为、\appdata\local\programs\python\python37\lib\site-packages\flask\app.py", line 1815, in full_dispatch_request
    rv = self.handle_user_exception(e)
  File "c:\users\认为、\appdata\local\programs\python\python37\lib\site-packages\flask\app.py", line 1718, in handle_user_exception
    reraise(exc_type, exc_value, tb)
  File "c:\users\认为、\appdata\local\programs\python\python37\lib\site-packages\flask\_compat.py", line 35, in reraise
    raise value
  File "c:\users\认为、\appdata\local\programs\python\python37\lib\site-packages\flask\app.py", line 1813, in full_dispatch_request
    rv = self.dispatch_request()
  File "c:\users\认为、\appdata\local\programs\python\python37\lib\site-packages\flask\app.py", line 1799, in dispatch_request
    return self.view_functions[rule.endpoint](**req.view_args)
  File "c:\users\认为、\appdata\local\programs\python\python37\lib\site-packages\flask_httpauth.py", line 103, in decorated
    return self.auth_error_callback()
  File "c:\users\认为、\appdata\local\programs\python\python37\lib\site-packages\flask_httpauth.py", line 44, in decorated
    res = f(*args, **kwargs)
  File "D:\项目\project\app\models.py", line 243, in unauthorized
    code = get_code(request.headers['Authorization'])
  File "c:\users\认为、\appdata\local\programs\python\python37\lib\site-packages\werkzeug\datastructures.py", line 1354, in __getitem__
    return _unicodify_header_value(self.environ['HTTP_' + key])
KeyError: 'HTTP_AUTHORIZATION'
2019-10-12 17:47:43,382 ERROR: Exception on /api/get_user_info [POST] [in c:\users\认为、\appdata\local\programs\python\python37\lib\site-packages\flask\app.py:1761]
Traceback (most recent call last):
  File "c:\users\认为、\appdata\local\programs\python\python37\lib\site-packages\flask\app.py", line 2292, in wsgi_app
    response = self.full_dispatch_request()
  File "c:\users\认为、\appdata\local\programs\python\python37\lib\site-packages\flask\app.py", line 1815, in full_dispatch_request
    rv = self.handle_user_exception(e)
  File "c:\users\认为、\appdata\local\programs\python\python37\lib\site-packages\flask\app.py", line 1718, in handle_user_exception
    reraise(exc_type, exc_value, tb)
  File "c:\users\认为、\appdata\local\programs\python\python37\lib\site-packages\flask\_compat.py", line 35, in reraise
    raise value
  File "c:\users\认为、\appdata\local\programs\python\python37\lib\site-packages\flask\app.py", line 1813, in full_dispatch_request
    rv = self.dispatch_request()
  File "c:\users\认为、\appdata\local\programs\python\python37\lib\site-packages\flask\app.py", line 1799, in dispatch_request
    return self.view_functions[rule.endpoint](**req.view_args)
  File "c:\users\认为、\appdata\local\programs\python\python37\lib\site-packages\flask_httpauth.py", line 103, in decorated
    return self.auth_error_callback()
  File "c:\users\认为、\appdata\local\programs\python\python37\lib\site-packages\flask_httpauth.py", line 44, in decorated
    res = f(*args, **kwargs)
  File "D:\项目\project\app\models.py", line 243, in unauthorized
    code = get_code(request.headers['Authorization'])
  File "c:\users\认为、\appdata\local\programs\python\python37\lib\site-packages\werkzeug\datastructures.py", line 1354, in __getitem__
    return _unicodify_header_value(self.environ['HTTP_' + key])
KeyError: 'HTTP_AUTHORIZATION'
2019-10-12 17:47:54,193 ERROR: Exception on /api/get_user_info [POST] [in c:\users\认为、\appdata\local\programs\python\python37\lib\site-packages\flask\app.py:1761]
Traceback (most recent call last):
  File "c:\users\认为、\appdata\local\programs\python\python37\lib\site-packages\flask\app.py", line 2292, in wsgi_app
    response = self.full_dispatch_request()
  File "c:\users\认为、\appdata\local\programs\python\python37\lib\site-packages\flask\app.py", line 1815, in full_dispatch_request
    rv = self.handle_user_exception(e)
  File "c:\users\认为、\appdata\local\programs\python\python37\lib\site-packages\flask\app.py", line 1718, in handle_user_exception
    reraise(exc_type, exc_value, tb)
  File "c:\users\认为、\appdata\local\programs\python\python37\lib\site-packages\flask\_compat.py", line 35, in reraise
    raise value
  File "c:\users\认为、\appdata\local\programs\python\python37\lib\site-packages\flask\app.py", line 1813, in full_dispatch_request
    rv = self.dispatch_request()
  File "c:\users\认为、\appdata\local\programs\python\python37\lib\site-packages\flask\app.py", line 1799, in dispatch_request
    return self.view_functions[rule.endpoint](**req.view_args)
  File "c:\users\认为、\appdata\local\programs\python\python37\lib\site-packages\flask_httpauth.py", line 103, in decorated
    return self.auth_error_callback()
  File "c:\users\认为、\appdata\local\programs\python\python37\lib\site-packages\flask_httpauth.py", line 44, in decorated
    res = f(*args, **kwargs)
  File "D:\项目\project\app\models.py", line 243, in unauthorized
    code = get_code(request.headers['Authorization'])
  File "c:\users\认为、\appdata\local\programs\python\python37\lib\site-packages\werkzeug\datastructures.py", line 1354, in __getitem__
    return _unicodify_header_value(self.environ['HTTP_' + key])
KeyError: 'HTTP_AUTHORIZATION'
2019-10-12 17:47:54,220 ERROR: Exception on /api/get_user_info [POST] [in c:\users\认为、\appdata\local\programs\python\python37\lib\site-packages\flask\app.py:1761]
Traceback (most recent call last):
  File "c:\users\认为、\appdata\local\programs\python\python37\lib\site-packages\flask\app.py", line 2292, in wsgi_app
    response = self.full_dispatch_request()
  File "c:\users\认为、\appdata\local\programs\python\python37\lib\site-packages\flask\app.py", line 1815, in full_dispatch_request
    rv = self.handle_user_exception(e)
  File "c:\users\认为、\appdata\local\programs\python\python37\lib\site-packages\flask\app.py", line 1718, in handle_user_exception
    reraise(exc_type, exc_value, tb)
  File "c:\users\认为、\appdata\local\programs\python\python37\lib\site-packages\flask\_compat.py", line 35, in reraise
    raise value
  File "c:\users\认为、\appdata\local\programs\python\python37\lib\site-packages\flask\app.py", line 1813, in full_dispatch_request
    rv = self.dispatch_request()
  File "c:\users\认为、\appdata\local\programs\python\python37\lib\site-packages\flask\app.py", line 1799, in dispatch_request
    return self.view_functions[rule.endpoint](**req.view_args)
  File "c:\users\认为、\appdata\local\programs\python\python37\lib\site-packages\flask_httpauth.py", line 103, in decorated
    return self.auth_error_callback()
  File "c:\users\认为、\appdata\local\programs\python\python37\lib\site-packages\flask_httpauth.py", line 44, in decorated
    res = f(*args, **kwargs)
  File "D:\项目\project\app\models.py", line 243, in unauthorized
    code = get_code(request.headers['Authorization'])
  File "c:\users\认为、\appdata\local\programs\python\python37\lib\site-packages\werkzeug\datastructures.py", line 1354, in __getitem__
    return _unicodify_header_value(self.environ['HTTP_' + key])
KeyError: 'HTTP_AUTHORIZATION'
2019-10-12 17:48:11,668 INFO: Microblog startup [in D:\项目\project\app\__init__.py:39]
2019-10-12 17:48:39,443 INFO: Microblog startup [in D:\项目\project\app\__init__.py:39]
2019-10-12 17:48:46,627 ERROR: Exception on /api/get_user_info [POST] [in c:\users\认为、\appdata\local\programs\python\python37\lib\site-packages\flask\app.py:1761]
Traceback (most recent call last):
  File "c:\users\认为、\appdata\local\programs\python\python37\lib\site-packages\flask\app.py", line 2292, in wsgi_app
    response = self.full_dispatch_request()
  File "c:\users\认为、\appdata\local\programs\python\python37\lib\site-packages\flask\app.py", line 1815, in full_dispatch_request
    rv = self.handle_user_exception(e)
  File "c:\users\认为、\appdata\local\programs\python\python37\lib\site-packages\flask\app.py", line 1718, in handle_user_exception
    reraise(exc_type, exc_value, tb)
  File "c:\users\认为、\appdata\local\programs\python\python37\lib\site-packages\flask\_compat.py", line 35, in reraise
    raise value
  File "c:\users\认为、\appdata\local\programs\python\python37\lib\site-packages\flask\app.py", line 1813, in full_dispatch_request
    rv = self.dispatch_request()
  File "c:\users\认为、\appdata\local\programs\python\python37\lib\site-packages\flask\app.py", line 1799, in dispatch_request
    return self.view_functions[rule.endpoint](**req.view_args)
  File "c:\users\认为、\appdata\local\programs\python\python37\lib\site-packages\flask_httpauth.py", line 103, in decorated
    return self.auth_error_callback()
  File "c:\users\认为、\appdata\local\programs\python\python37\lib\site-packages\flask_httpauth.py", line 44, in decorated
    res = f(*args, **kwargs)
  File "D:\项目\project\app\models.py", line 243, in unauthorized
    code = get_code(request.headers['Authorization'])
  File "c:\users\认为、\appdata\local\programs\python\python37\lib\site-packages\werkzeug\datastructures.py", line 1354, in __getitem__
    return _unicodify_header_value(self.environ['HTTP_' + key])
KeyError: 'HTTP_AUTHORIZATION'
2019-10-12 17:48:46,629 ERROR: Exception on /api/get_user_info [POST] [in c:\users\认为、\appdata\local\programs\python\python37\lib\site-packages\flask\app.py:1761]
Traceback (most recent call last):
  File "c:\users\认为、\appdata\local\programs\python\python37\lib\site-packages\flask\app.py", line 2292, in wsgi_app
    response = self.full_dispatch_request()
  File "c:\users\认为、\appdata\local\programs\python\python37\lib\site-packages\flask\app.py", line 1815, in full_dispatch_request
    rv = self.handle_user_exception(e)
  File "c:\users\认为、\appdata\local\programs\python\python37\lib\site-packages\flask\app.py", line 1718, in handle_user_exception
    reraise(exc_type, exc_value, tb)
  File "c:\users\认为、\appdata\local\programs\python\python37\lib\site-packages\flask\_compat.py", line 35, in reraise
    raise value
  File "c:\users\认为、\appdata\local\programs\python\python37\lib\site-packages\flask\app.py", line 1813, in full_dispatch_request
    rv = self.dispatch_request()
  File "c:\users\认为、\appdata\local\programs\python\python37\lib\site-packages\flask\app.py", line 1799, in dispatch_request
    return self.view_functions[rule.endpoint](**req.view_args)
  File "c:\users\认为、\appdata\local\programs\python\python37\lib\site-packages\flask_httpauth.py", line 103, in decorated
    return self.auth_error_callback()
  File "c:\users\认为、\appdata\local\programs\python\python37\lib\site-packages\flask_httpauth.py", line 44, in decorated
    res = f(*args, **kwargs)
  File "D:\项目\project\app\models.py", line 243, in unauthorized
    code = get_code(request.headers['Authorization'])
  File "c:\users\认为、\appdata\local\programs\python\python37\lib\site-packages\werkzeug\datastructures.py", line 1354, in __getitem__
    return _unicodify_header_value(self.environ['HTTP_' + key])
KeyError: 'HTTP_AUTHORIZATION'
2019-10-12 17:49:25,604 INFO: Microblog startup [in D:\项目\project\app\__init__.py:39]
2019-10-12 17:53:52,723 INFO: Microblog startup [in D:\项目\project\app\__init__.py:39]
2019-10-12 17:54:14,096 ERROR: Exception on /api/get_user_info [POST] [in c:\users\认为、\appdata\local\programs\python\python37\lib\site-packages\flask\app.py:1761]
Traceback (most recent call last):
  File "c:\users\认为、\appdata\local\programs\python\python37\lib\site-packages\flask\app.py", line 2292, in wsgi_app
    response = self.full_dispatch_request()
  File "c:\users\认为、\appdata\local\programs\python\python37\lib\site-packages\flask\app.py", line 1815, in full_dispatch_request
    rv = self.handle_user_exception(e)
  File "c:\users\认为、\appdata\local\programs\python\python37\lib\site-packages\flask\app.py", line 1718, in handle_user_exception
    reraise(exc_type, exc_value, tb)
  File "c:\users\认为、\appdata\local\programs\python\python37\lib\site-packages\flask\_compat.py", line 35, in reraise
    raise value
  File "c:\users\认为、\appdata\local\programs\python\python37\lib\site-packages\flask\app.py", line 1813, in full_dispatch_request
    rv = self.dispatch_request()
  File "c:\users\认为、\appdata\local\programs\python\python37\lib\site-packages\flask\app.py", line 1799, in dispatch_request
    return self.view_functions[rule.endpoint](**req.view_args)
  File "c:\users\认为、\appdata\local\programs\python\python37\lib\site-packages\flask_httpauth.py", line 103, in decorated
    return self.auth_error_callback()
  File "c:\users\认为、\appdata\local\programs\python\python37\lib\site-packages\flask_httpauth.py", line 44, in decorated
    res = f(*args, **kwargs)
  File "D:\项目\project\app\models.py", line 242, in unauthorized
    code = get_code(request.headers['Authorization'])
  File "c:\users\认为、\appdata\local\programs\python\python37\lib\site-packages\werkzeug\datastructures.py", line 1354, in __getitem__
    return _unicodify_header_value(self.environ['HTTP_' + key])
KeyError: 'HTTP_AUTHORIZATION'
2019-10-12 18:00:27,964 INFO: Microblog startup [in D:\项目\project\app\__init__.py:39]
2019-10-12 18:10:55,648 INFO: Microblog startup [in D:\项目\project\app\__init__.py:39]
2019-10-12 18:11:24,835 ERROR: Exception on /api/get_user_info [POST] [in c:\users\认为、\appdata\local\programs\python\python37\lib\site-packages\flask\app.py:1761]
Traceback (most recent call last):
  File "c:\users\认为、\appdata\local\programs\python\python37\lib\site-packages\flask\app.py", line 2292, in wsgi_app
    response = self.full_dispatch_request()
  File "c:\users\认为、\appdata\local\programs\python\python37\lib\site-packages\flask\app.py", line 1815, in full_dispatch_request
    rv = self.handle_user_exception(e)
  File "c:\users\认为、\appdata\local\programs\python\python37\lib\site-packages\flask\app.py", line 1718, in handle_user_exception
    reraise(exc_type, exc_value, tb)
  File "c:\users\认为、\appdata\local\programs\python\python37\lib\site-packages\flask\_compat.py", line 35, in reraise
    raise value
  File "c:\users\认为、\appdata\local\programs\python\python37\lib\site-packages\flask\app.py", line 1813, in full_dispatch_request
    rv = self.dispatch_request()
  File "c:\users\认为、\appdata\local\programs\python\python37\lib\site-packages\flask\app.py", line 1799, in dispatch_request
    return self.view_functions[rule.endpoint](**req.view_args)
  File "c:\users\认为、\appdata\local\programs\python\python37\lib\site-packages\flask_httpauth.py", line 105, in decorated
    return f(*args, **kwargs)
  File "D:\项目\project\app\routes.py", line 102, in get_user_info
    user_info, pages = User.get_all_user(page_num)
  File "D:\项目\project\app\models.py", line 111, in get_all_user
    return [user.to_dict() for user in all_user], page.pages
  File "D:\项目\project\app\models.py", line 111, in <listcomp>
    return [user.to_dict() for user in all_user], page.pages
  File "D:\项目\project\app\models.py", line 104, in to_dict
    "ip":self.ip}
AttributeError: 'User' object has no attribute 'ip'
2019-10-12 18:11:48,292 INFO: Microblog startup [in D:\项目\project\app\__init__.py:39]
2019-10-12 18:17:24,036 ERROR: Exception on /api/del_user [POST] [in c:\users\认为、\appdata\local\programs\python\python37\lib\site-packages\flask\app.py:1761]
Traceback (most recent call last):
  File "c:\users\认为、\appdata\local\programs\python\python37\lib\site-packages\flask\app.py", line 2292, in wsgi_app
    response = self.full_dispatch_request()
  File "c:\users\认为、\appdata\local\programs\python\python37\lib\site-packages\flask\app.py", line 1815, in full_dispatch_request
    rv = self.handle_user_exception(e)
  File "c:\users\认为、\appdata\local\programs\python\python37\lib\site-packages\flask\app.py", line 1718, in handle_user_exception
    reraise(exc_type, exc_value, tb)
  File "c:\users\认为、\appdata\local\programs\python\python37\lib\site-packages\flask\_compat.py", line 35, in reraise
    raise value
  File "c:\users\认为、\appdata\local\programs\python\python37\lib\site-packages\flask\app.py", line 1813, in full_dispatch_request
    rv = self.dispatch_request()
  File "c:\users\认为、\appdata\local\programs\python\python37\lib\site-packages\flask\app.py", line 1799, in dispatch_request
    return self.view_functions[rule.endpoint](**req.view_args)
  File "c:\users\认为、\appdata\local\programs\python\python37\lib\site-packages\flask_httpauth.py", line 105, in decorated
    return f(*args, **kwargs)
  File "D:\项目\project\app\routes.py", line 137, in del_user
    rest_day = 30)
  File "c:\users\认为、\appdata\local\programs\python\python37\lib\site-packages\flask_httpauth.py", line 105, in decorated
    return f(*args, **kwargs)
TypeError: recircle_user() got an unexpected keyword argument 'account'
2019-10-12 18:18:18,090 INFO: Microblog startup [in D:\项目\project\app\__init__.py:39]
2019-10-12 18:18:44,313 ERROR: Exception on /api/del_user [POST] [in c:\users\认为、\appdata\local\programs\python\python37\lib\site-packages\flask\app.py:1761]
Traceback (most recent call last):
  File "c:\users\认为、\appdata\local\programs\python\python37\lib\site-packages\flask\app.py", line 2292, in wsgi_app
    response = self.full_dispatch_request()
  File "c:\users\认为、\appdata\local\programs\python\python37\lib\site-packages\flask\app.py", line 1815, in full_dispatch_request
    rv = self.handle_user_exception(e)
  File "c:\users\认为、\appdata\local\programs\python\python37\lib\site-packages\flask\app.py", line 1718, in handle_user_exception
    reraise(exc_type, exc_value, tb)
  File "c:\users\认为、\appdata\local\programs\python\python37\lib\site-packages\flask\_compat.py", line 35, in reraise
    raise value
  File "c:\users\认为、\appdata\local\programs\python\python37\lib\site-packages\flask\app.py", line 1813, in full_dispatch_request
    rv = self.dispatch_request()
  File "c:\users\认为、\appdata\local\programs\python\python37\lib\site-packages\flask\app.py", line 1799, in dispatch_request
    return self.view_functions[rule.endpoint](**req.view_args)
  File "c:\users\认为、\appdata\local\programs\python\python37\lib\site-packages\flask_httpauth.py", line 105, in decorated
    return f(*args, **kwargs)
  File "D:\项目\project\app\routes.py", line 138, in del_user
    rest_day = 30)
  File "c:\users\认为、\appdata\local\programs\python\python37\lib\site-packages\flask_httpauth.py", line 105, in decorated
    return f(*args, **kwargs)
TypeError: recircle_user() got an unexpected keyword argument 'account'
2019-10-12 18:26:57,397 INFO: Microblog startup [in D:\项目\project\app\__init__.py:39]
2019-10-12 18:27:40,690 ERROR: Exception on /api/del_user [POST] [in c:\users\认为、\appdata\local\programs\python\python37\lib\site-packages\flask\app.py:1761]
Traceback (most recent call last):
  File "c:\users\认为、\appdata\local\programs\python\python37\lib\site-packages\flask\app.py", line 2292, in wsgi_app
    response = self.full_dispatch_request()
  File "c:\users\认为、\appdata\local\programs\python\python37\lib\site-packages\flask\app.py", line 1815, in full_dispatch_request
    rv = self.handle_user_exception(e)
  File "c:\users\认为、\appdata\local\programs\python\python37\lib\site-packages\flask\app.py", line 1718, in handle_user_exception
    reraise(exc_type, exc_value, tb)
  File "c:\users\认为、\appdata\local\programs\python\python37\lib\site-packages\flask\_compat.py", line 35, in reraise
    raise value
  File "c:\users\认为、\appdata\local\programs\python\python37\lib\site-packages\flask\app.py", line 1813, in full_dispatch_request
    rv = self.dispatch_request()
  File "c:\users\认为、\appdata\local\programs\python\python37\lib\site-packages\flask\app.py", line 1799, in dispatch_request
    return self.view_functions[rule.endpoint](**req.view_args)
  File "c:\users\认为、\appdata\local\programs\python\python37\lib\site-packages\flask_httpauth.py", line 105, in decorated
    return f(*args, **kwargs)
  File "D:\项目\project\app\routes.py", line 138, in del_user
    rest_day = 30)
  File "c:\users\认为、\appdata\local\programs\python\python37\lib\site-packages\flask_httpauth.py", line 105, in decorated
    return f(*args, **kwargs)
TypeError: recircle_user() got an unexpected keyword argument 'account'
2019-10-12 18:28:02,222 INFO: Microblog startup [in D:\项目\project\app\__init__.py:39]
