2019-10-12 15:44:49,978 ERROR: Exception on /api/get_store_info [POST] [in c:\users\认为、\appdata\local\programs\python\python37\lib\site-packages\flask\app.py:1761]
Traceback (most recent call last):
  File "c:\users\认为、\appdata\local\programs\python\python37\lib\site-packages\flask\app.py", line 2292, in wsgi_app
    response = self.full_dispatch_request()
  File "c:\users\认为、\appdata\local\programs\python\python37\lib\site-packages\flask\app.py", line 1815, in full_dispatch_request
    rv = self.handle_user_exception(e)
  File "c:\users\认为、\appdata\local\programs\python\python37\lib\site-packages\flask\app.py", line 1718, in handle_user_exception
    reraise(exc_type, exc_value, tb)
  File "c:\users\认为、\appdata\local\programs\python\python37\lib\site-packages\flask\_compat.py", line 35, in reraise
    raise value
  File "c:\users\认为、\appdata\local\programs\python\python37\lib\site-packages\flask\app.py", line 1813, in full_dispatch_request
    rv = self.dispatch_request()
  File "c:\users\认为、\appdata\local\programs\python\python37\lib\site-packages\flask\app.py", line 1799, in dispatch_request
    return self.view_functions[rule.endpoint](**req.view_args)
  File "c:\users\认为、\appdata\local\programs\python\python37\lib\site-packages\flask_httpauth.py", line 103, in decorated
    return self.auth_error_callback()
  File "c:\users\认为、\appdata\local\programs\python\python37\lib\site-packages\flask_httpauth.py", line 44, in decorated
    res = f(*args, **kwargs)
  File "D:\项目\project\app\models.py", line 218, in unauthorized
    if not d_user:
  File "c:\users\认为、\appdata\local\programs\python\python37\lib\site-packages\werkzeug\datastructures.py", line 1354, in __getitem__
    return _unicodify_header_value(self.environ['HTTP_' + key])
KeyError: 'HTTP_AUTHORIZATION'
2019-10-12 15:44:56,837 ERROR: Exception on /api/get_store_info [POST] [in c:\users\认为、\appdata\local\programs\python\python37\lib\site-packages\flask\app.py:1761]
Traceback (most recent call last):
  File "c:\users\认为、\appdata\local\programs\python\python37\lib\site-packages\flask\app.py", line 2292, in wsgi_app
    response = self.full_dispatch_request()
  File "c:\users\认为、\appdata\local\programs\python\python37\lib\site-packages\flask\app.py", line 1815, in full_dispatch_request
    rv = self.handle_user_exception(e)
  File "c:\users\认为、\appdata\local\programs\python\python37\lib\site-packages\flask\app.py", line 1718, in handle_user_exception
    reraise(exc_type, exc_value, tb)
  File "c:\users\认为、\appdata\local\programs\python\python37\lib\site-packages\flask\_compat.py", line 35, in reraise
    raise value
  File "c:\users\认为、\appdata\local\programs\python\python37\lib\site-packages\flask\app.py", line 1813, in full_dispatch_request
    rv = self.dispatch_request()
  File "c:\users\认为、\appdata\local\programs\python\python37\lib\site-packages\flask\app.py", line 1799, in dispatch_request
    return self.view_functions[rule.endpoint](**req.view_args)
  File "c:\users\认为、\appdata\local\programs\python\python37\lib\site-packages\flask_httpauth.py", line 103, in decorated
    return self.auth_error_callback()
  File "c:\users\认为、\appdata\local\programs\python\python37\lib\site-packages\flask_httpauth.py", line 44, in decorated
    res = f(*args, **kwargs)
  File "D:\项目\project\app\models.py", line 218, in unauthorized
    if not d_user:
  File "c:\users\认为、\appdata\local\programs\python\python37\lib\site-packages\werkzeug\datastructures.py", line 1354, in __getitem__
    return _unicodify_header_value(self.environ['HTTP_' + key])
KeyError: 'HTTP_AUTHORIZATION'
2019-10-12 15:46:50,281 ERROR: Exception on /api/get_store_info [POST] [in c:\users\认为、\appdata\local\programs\python\python37\lib\site-packages\flask\app.py:1761]
Traceback (most recent call last):
  File "c:\users\认为、\appdata\local\programs\python\python37\lib\site-packages\flask\app.py", line 2292, in wsgi_app
    response = self.full_dispatch_request()
  File "c:\users\认为、\appdata\local\programs\python\python37\lib\site-packages\flask\app.py", line 1815, in full_dispatch_request
    rv = self.handle_user_exception(e)
  File "c:\users\认为、\appdata\local\programs\python\python37\lib\site-packages\flask\app.py", line 1718, in handle_user_exception
    reraise(exc_type, exc_value, tb)
  File "c:\users\认为、\appdata\local\programs\python\python37\lib\site-packages\flask\_compat.py", line 35, in reraise
    raise value
  File "c:\users\认为、\appdata\local\programs\python\python37\lib\site-packages\flask\app.py", line 1813, in full_dispatch_request
    rv = self.dispatch_request()
  File "c:\users\认为、\appdata\local\programs\python\python37\lib\site-packages\flask\app.py", line 1799, in dispatch_request
    return self.view_functions[rule.endpoint](**req.view_args)
  File "c:\users\认为、\appdata\local\programs\python\python37\lib\site-packages\flask_httpauth.py", line 103, in decorated
    return self.auth_error_callback()
  File "c:\users\认为、\appdata\local\programs\python\python37\lib\site-packages\flask_httpauth.py", line 44, in decorated
    res = f(*args, **kwargs)
  File "D:\项目\project\app\models.py", line 218, in unauthorized
    if not d_user:
  File "c:\users\认为、\appdata\local\programs\python\python37\lib\site-packages\werkzeug\datastructures.py", line 1354, in __getitem__
    return _unicodify_header_value(self.environ['HTTP_' + key])
KeyError: 'HTTP_AUTHORIZATION'
2019-10-12 15:48:14,710 INFO: Microblog startup [in D:\项目\project\app\__init__.py:39]
2019-10-12 15:48:36,593 INFO: Microblog startup [in D:\项目\project\app\__init__.py:39]
2019-10-12 15:48:40,487 ERROR: Exception on /api/check_account [POST] [in c:\users\认为、\appdata\local\programs\python\python37\lib\site-packages\flask\app.py:1761]
Traceback (most recent call last):
  File "c:\users\认为、\appdata\local\programs\python\python37\lib\site-packages\flask\app.py", line 2292, in wsgi_app
    response = self.full_dispatch_request()
  File "c:\users\认为、\appdata\local\programs\python\python37\lib\site-packages\flask\app.py", line 1815, in full_dispatch_request
    rv = self.handle_user_exception(e)
  File "c:\users\认为、\appdata\local\programs\python\python37\lib\site-packages\flask\app.py", line 1718, in handle_user_exception
    reraise(exc_type, exc_value, tb)
  File "c:\users\认为、\appdata\local\programs\python\python37\lib\site-packages\flask\_compat.py", line 35, in reraise
    raise value
  File "c:\users\认为、\appdata\local\programs\python\python37\lib\site-packages\flask\app.py", line 1813, in full_dispatch_request
    rv = self.dispatch_request()
  File "c:\users\认为、\appdata\local\programs\python\python37\lib\site-packages\flask\app.py", line 1799, in dispatch_request
    return self.view_functions[rule.endpoint](**req.view_args)
  File "D:\项目\project\app\routes.py", line 23, in check_account
    account = data['account']
TypeError: list indices must be integers or slices, not str
2019-10-12 15:49:23,337 INFO: Microblog startup [in D:\项目\project\app\__init__.py:39]
2019-10-12 15:51:55,431 ERROR: Exception on /api/search [POST] [in c:\users\认为、\appdata\local\programs\python\python37\lib\site-packages\flask\app.py:1761]
Traceback (most recent call last):
  File "c:\users\认为、\appdata\local\programs\python\python37\lib\site-packages\flask\app.py", line 2292, in wsgi_app
    response = self.full_dispatch_request()
  File "c:\users\认为、\appdata\local\programs\python\python37\lib\site-packages\flask\app.py", line 1815, in full_dispatch_request
    rv = self.handle_user_exception(e)
  File "c:\users\认为、\appdata\local\programs\python\python37\lib\site-packages\flask\app.py", line 1718, in handle_user_exception
    reraise(exc_type, exc_value, tb)
  File "c:\users\认为、\appdata\local\programs\python\python37\lib\site-packages\flask\_compat.py", line 35, in reraise
    raise value
  File "c:\users\认为、\appdata\local\programs\python\python37\lib\site-packages\flask\app.py", line 1813, in full_dispatch_request
    rv = self.dispatch_request()
  File "c:\users\认为、\appdata\local\programs\python\python37\lib\site-packages\flask\app.py", line 1799, in dispatch_request
    return self.view_functions[rule.endpoint](**req.view_args)
  File "c:\users\认为、\appdata\local\programs\python\python37\lib\site-packages\flask_httpauth.py", line 105, in decorated
    return f(*args, **kwargs)
  File "D:\项目\project\app\routes.py", line 189, in search
    path = data['path']
KeyError: 'path'
2019-10-12 15:52:16,420 INFO: Microblog startup [in D:\项目\project\app\__init__.py:39]
2019-10-12 15:52:20,247 ERROR: Exception on /api/search [POST] [in c:\users\认为、\appdata\local\programs\python\python37\lib\site-packages\flask\app.py:1761]
Traceback (most recent call last):
  File "c:\users\认为、\appdata\local\programs\python\python37\lib\site-packages\flask\app.py", line 2292, in wsgi_app
    response = self.full_dispatch_request()
  File "c:\users\认为、\appdata\local\programs\python\python37\lib\site-packages\flask\app.py", line 1815, in full_dispatch_request
    rv = self.handle_user_exception(e)
  File "c:\users\认为、\appdata\local\programs\python\python37\lib\site-packages\flask\app.py", line 1718, in handle_user_exception
    reraise(exc_type, exc_value, tb)
  File "c:\users\认为、\appdata\local\programs\python\python37\lib\site-packages\flask\_compat.py", line 35, in reraise
    raise value
  File "c:\users\认为、\appdata\local\programs\python\python37\lib\site-packages\flask\app.py", line 1813, in full_dispatch_request
    rv = self.dispatch_request()
  File "c:\users\认为、\appdata\local\programs\python\python37\lib\site-packages\flask\app.py", line 1799, in dispatch_request
    return self.view_functions[rule.endpoint](**req.view_args)
  File "c:\users\认为、\appdata\local\programs\python\python37\lib\site-packages\flask_httpauth.py", line 105, in decorated
    return f(*args, **kwargs)
  File "D:\项目\project\app\routes.py", line 190, in search
    page_num = data['page_num']
KeyError: 'page_num'
2019-10-12 15:53:12,088 INFO: Microblog startup [in D:\项目\project\app\__init__.py:39]
2019-10-12 15:53:15,631 ERROR: Exception on /api/search [POST] [in c:\users\认为、\appdata\local\programs\python\python37\lib\site-packages\flask\app.py:1761]
Traceback (most recent call last):
  File "c:\users\认为、\appdata\local\programs\python\python37\lib\site-packages\flask\app.py", line 2292, in wsgi_app
    response = self.full_dispatch_request()
  File "c:\users\认为、\appdata\local\programs\python\python37\lib\site-packages\flask\app.py", line 1815, in full_dispatch_request
    rv = self.handle_user_exception(e)
  File "c:\users\认为、\appdata\local\programs\python\python37\lib\site-packages\flask\app.py", line 1718, in handle_user_exception
    reraise(exc_type, exc_value, tb)
  File "c:\users\认为、\appdata\local\programs\python\python37\lib\site-packages\flask\_compat.py", line 35, in reraise
    raise value
  File "c:\users\认为、\appdata\local\programs\python\python37\lib\site-packages\flask\app.py", line 1813, in full_dispatch_request
    rv = self.dispatch_request()
  File "c:\users\认为、\appdata\local\programs\python\python37\lib\site-packages\flask\app.py", line 1799, in dispatch_request
    return self.view_functions[rule.endpoint](**req.view_args)
  File "c:\users\认为、\appdata\local\programs\python\python37\lib\site-packages\flask_httpauth.py", line 105, in decorated
    return f(*args, **kwargs)
  File "D:\项目\project\app\routes.py", line 197, in search
    if g.user.data_count <= 0:
TypeError: '<=' not supported between instances of 'NoneType' and 'int'
2019-10-12 15:54:32,596 ERROR: Exception on /api/search [POST] [in c:\users\认为、\appdata\local\programs\python\python37\lib\site-packages\flask\app.py:1761]
Traceback (most recent call last):
  File "c:\users\认为、\appdata\local\programs\python\python37\lib\site-packages\flask\app.py", line 2292, in wsgi_app
    response = self.full_dispatch_request()
  File "c:\users\认为、\appdata\local\programs\python\python37\lib\site-packages\flask\app.py", line 1815, in full_dispatch_request
    rv = self.handle_user_exception(e)
  File "c:\users\认为、\appdata\local\programs\python\python37\lib\site-packages\flask\app.py", line 1718, in handle_user_exception
    reraise(exc_type, exc_value, tb)
  File "c:\users\认为、\appdata\local\programs\python\python37\lib\site-packages\flask\_compat.py", line 35, in reraise
    raise value
  File "c:\users\认为、\appdata\local\programs\python\python37\lib\site-packages\flask\app.py", line 1813, in full_dispatch_request
    rv = self.dispatch_request()
  File "c:\users\认为、\appdata\local\programs\python\python37\lib\site-packages\flask\app.py", line 1799, in dispatch_request
    return self.view_functions[rule.endpoint](**req.view_args)
  File "c:\users\认为、\appdata\local\programs\python\python37\lib\site-packages\flask_httpauth.py", line 105, in decorated
    return f(*args, **kwargs)
  File "D:\项目\project\app\routes.py", line 197, in search
    if g.user.data_count <= 0:
TypeError: '<=' not supported between instances of 'NoneType' and 'int'
2019-10-12 15:55:25,168 INFO: Microblog startup [in D:\项目\project\app\__init__.py:39]
2019-10-12 15:55:28,369 ERROR: Exception on /api/search [POST] [in c:\users\认为、\appdata\local\programs\python\python37\lib\site-packages\flask\app.py:1761]
Traceback (most recent call last):
  File "c:\users\认为、\appdata\local\programs\python\python37\lib\site-packages\flask\app.py", line 2292, in wsgi_app
    response = self.full_dispatch_request()
  File "c:\users\认为、\appdata\local\programs\python\python37\lib\site-packages\flask\app.py", line 1815, in full_dispatch_request
    rv = self.handle_user_exception(e)
  File "c:\users\认为、\appdata\local\programs\python\python37\lib\site-packages\flask\app.py", line 1718, in handle_user_exception
    reraise(exc_type, exc_value, tb)
  File "c:\users\认为、\appdata\local\programs\python\python37\lib\site-packages\flask\_compat.py", line 35, in reraise
    raise value
  File "c:\users\认为、\appdata\local\programs\python\python37\lib\site-packages\flask\app.py", line 1813, in full_dispatch_request
    rv = self.dispatch_request()
  File "c:\users\认为、\appdata\local\programs\python\python37\lib\site-packages\flask\app.py", line 1799, in dispatch_request
    return self.view_functions[rule.endpoint](**req.view_args)
  File "c:\users\认为、\appdata\local\programs\python\python37\lib\site-packages\flask_httpauth.py", line 105, in decorated
    return f(*args, **kwargs)
  File "D:\项目\project\app\routes.py", line 197, in search
    if g.user.right > 4 and g.user.data_count <= 0:
TypeError: '<=' not supported between instances of 'NoneType' and 'int'
2019-10-12 15:56:23,455 INFO: Microblog startup [in D:\项目\project\app\__init__.py:39]
2019-10-12 15:56:25,484 ERROR: Exception on /api/search [POST] [in c:\users\认为、\appdata\local\programs\python\python37\lib\site-packages\flask\app.py:1761]
Traceback (most recent call last):
  File "c:\users\认为、\appdata\local\programs\python\python37\lib\site-packages\flask\app.py", line 2292, in wsgi_app
    response = self.full_dispatch_request()
  File "c:\users\认为、\appdata\local\programs\python\python37\lib\site-packages\flask\app.py", line 1815, in full_dispatch_request
    rv = self.handle_user_exception(e)
  File "c:\users\认为、\appdata\local\programs\python\python37\lib\site-packages\flask\app.py", line 1718, in handle_user_exception
    reraise(exc_type, exc_value, tb)
  File "c:\users\认为、\appdata\local\programs\python\python37\lib\site-packages\flask\_compat.py", line 35, in reraise
    raise value
  File "c:\users\认为、\appdata\local\programs\python\python37\lib\site-packages\flask\app.py", line 1813, in full_dispatch_request
    rv = self.dispatch_request()
  File "c:\users\认为、\appdata\local\programs\python\python37\lib\site-packages\flask\app.py", line 1799, in dispatch_request
    return self.view_functions[rule.endpoint](**req.view_args)
  File "c:\users\认为、\appdata\local\programs\python\python37\lib\site-packages\flask_httpauth.py", line 105, in decorated
    return f(*args, **kwargs)
  File "D:\项目\project\app\routes.py", line 199, in search
    session['search_info'] = store_info.search(keyword,telnum,info_from,date_begin,date_end)
  File "D:\项目\project\app\models.py", line 193, in search
    info  =  store_info.query.filter_by(con)
UnboundLocalError: local variable 'con' referenced before assignment
2019-10-12 15:57:03,986 INFO: Microblog startup [in D:\项目\project\app\__init__.py:39]
2019-10-12 15:57:06,443 ERROR: Exception on /api/search [POST] [in c:\users\认为、\appdata\local\programs\python\python37\lib\site-packages\flask\app.py:1761]
Traceback (most recent call last):
  File "c:\users\认为、\appdata\local\programs\python\python37\lib\site-packages\flask\app.py", line 2292, in wsgi_app
    response = self.full_dispatch_request()
  File "c:\users\认为、\appdata\local\programs\python\python37\lib\site-packages\flask\app.py", line 1815, in full_dispatch_request
    rv = self.handle_user_exception(e)
  File "c:\users\认为、\appdata\local\programs\python\python37\lib\site-packages\flask\app.py", line 1718, in handle_user_exception
    reraise(exc_type, exc_value, tb)
  File "c:\users\认为、\appdata\local\programs\python\python37\lib\site-packages\flask\_compat.py", line 35, in reraise
    raise value
  File "c:\users\认为、\appdata\local\programs\python\python37\lib\site-packages\flask\app.py", line 1813, in full_dispatch_request
    rv = self.dispatch_request()
  File "c:\users\认为、\appdata\local\programs\python\python37\lib\site-packages\flask\app.py", line 1799, in dispatch_request
    return self.view_functions[rule.endpoint](**req.view_args)
  File "c:\users\认为、\appdata\local\programs\python\python37\lib\site-packages\flask_httpauth.py", line 105, in decorated
    return f(*args, **kwargs)
  File "D:\项目\project\app\routes.py", line 199, in search
    session['search_info'] = store_info.search(keyword,telnum,info_from,date_begin,date_end)
  File "D:\项目\project\app\models.py", line 194, in search
    info  =  store_info.query.filter_by(con)
TypeError: filter_by() takes 1 positional argument but 2 were given
2019-10-12 15:57:51,566 INFO: Microblog startup [in D:\项目\project\app\__init__.py:39]
2019-10-12 15:57:53,341 ERROR: Exception on /api/search [POST] [in c:\users\认为、\appdata\local\programs\python\python37\lib\site-packages\flask\app.py:1761]
Traceback (most recent call last):
  File "c:\users\认为、\appdata\local\programs\python\python37\lib\site-packages\flask\app.py", line 2292, in wsgi_app
    response = self.full_dispatch_request()
  File "c:\users\认为、\appdata\local\programs\python\python37\lib\site-packages\flask\app.py", line 1815, in full_dispatch_request
    rv = self.handle_user_exception(e)
  File "c:\users\认为、\appdata\local\programs\python\python37\lib\site-packages\flask\app.py", line 1718, in handle_user_exception
    reraise(exc_type, exc_value, tb)
  File "c:\users\认为、\appdata\local\programs\python\python37\lib\site-packages\flask\_compat.py", line 35, in reraise
    raise value
  File "c:\users\认为、\appdata\local\programs\python\python37\lib\site-packages\flask\app.py", line 1813, in full_dispatch_request
    rv = self.dispatch_request()
  File "c:\users\认为、\appdata\local\programs\python\python37\lib\site-packages\flask\app.py", line 1799, in dispatch_request
    return self.view_functions[rule.endpoint](**req.view_args)
  File "c:\users\认为、\appdata\local\programs\python\python37\lib\site-packages\flask_httpauth.py", line 105, in decorated
    return f(*args, **kwargs)
  File "D:\项目\project\app\routes.py", line 201, in search
    return jsonify({"info":info , "pages":pages}), 200, {'Authorization':request.headers['Authorization'],'code':0}
UnboundLocalError: local variable 'info' referenced before assignment
2019-10-12 15:58:53,695 INFO: Microblog startup [in D:\项目\project\app\__init__.py:39]
2019-10-12 15:58:55,912 ERROR: Exception on /api/search [POST] [in c:\users\认为、\appdata\local\programs\python\python37\lib\site-packages\flask\app.py:1761]
Traceback (most recent call last):
  File "c:\users\认为、\appdata\local\programs\python\python37\lib\site-packages\flask\app.py", line 2292, in wsgi_app
    response = self.full_dispatch_request()
  File "c:\users\认为、\appdata\local\programs\python\python37\lib\site-packages\flask\app.py", line 1815, in full_dispatch_request
    rv = self.handle_user_exception(e)
  File "c:\users\认为、\appdata\local\programs\python\python37\lib\site-packages\flask\app.py", line 1718, in handle_user_exception
    reraise(exc_type, exc_value, tb)
  File "c:\users\认为、\appdata\local\programs\python\python37\lib\site-packages\flask\_compat.py", line 35, in reraise
    raise value
  File "c:\users\认为、\appdata\local\programs\python\python37\lib\site-packages\flask\app.py", line 1813, in full_dispatch_request
    rv = self.dispatch_request()
  File "c:\users\认为、\appdata\local\programs\python\python37\lib\site-packages\flask\app.py", line 1799, in dispatch_request
    return self.view_functions[rule.endpoint](**req.view_args)
  File "c:\users\认为、\appdata\local\programs\python\python37\lib\site-packages\flask_httpauth.py", line 105, in decorated
    return f(*args, **kwargs)
  File "D:\项目\project\app\routes.py", line 200, in search
    info,pages = store_info.paging(session['search_info'],int(request.get_json(silent=True)['page_num']))
KeyError: 'page_num'
2019-10-12 16:00:17,764 ERROR: Exception on /api/search [POST] [in c:\users\认为、\appdata\local\programs\python\python37\lib\site-packages\flask\app.py:1761]
Traceback (most recent call last):
  File "c:\users\认为、\appdata\local\programs\python\python37\lib\site-packages\flask\app.py", line 2292, in wsgi_app
    response = self.full_dispatch_request()
  File "c:\users\认为、\appdata\local\programs\python\python37\lib\site-packages\flask\app.py", line 1815, in full_dispatch_request
    rv = self.handle_user_exception(e)
  File "c:\users\认为、\appdata\local\programs\python\python37\lib\site-packages\flask\app.py", line 1718, in handle_user_exception
    reraise(exc_type, exc_value, tb)
  File "c:\users\认为、\appdata\local\programs\python\python37\lib\site-packages\flask\_compat.py", line 35, in reraise
    raise value
  File "c:\users\认为、\appdata\local\programs\python\python37\lib\site-packages\flask\app.py", line 1813, in full_dispatch_request
    rv = self.dispatch_request()
  File "c:\users\认为、\appdata\local\programs\python\python37\lib\site-packages\flask\app.py", line 1799, in dispatch_request
    return self.view_functions[rule.endpoint](**req.view_args)
  File "c:\users\认为、\appdata\local\programs\python\python37\lib\site-packages\flask_httpauth.py", line 105, in decorated
    return f(*args, **kwargs)
  File "D:\项目\project\app\routes.py", line 200, in search
    info,pages = store_info.paging(session['search_info'],int(request.get_json(silent=True)['page_num']))
  File "D:\项目\project\app\models.py", line 175, in paging
    page = data.paginate(page_num,per_page=20,error_out=False)
AttributeError: 'list' object has no attribute 'paginate'
2019-10-12 16:01:08,744 INFO: Microblog startup [in D:\项目\project\app\__init__.py:39]
2019-10-12 16:01:11,005 ERROR: Exception on /api/search [POST] [in c:\users\认为、\appdata\local\programs\python\python37\lib\site-packages\flask\app.py:1761]
Traceback (most recent call last):
  File "c:\users\认为、\appdata\local\programs\python\python37\lib\site-packages\flask\app.py", line 2292, in wsgi_app
    response = self.full_dispatch_request()
  File "c:\users\认为、\appdata\local\programs\python\python37\lib\site-packages\flask\app.py", line 1815, in full_dispatch_request
    rv = self.handle_user_exception(e)
  File "c:\users\认为、\appdata\local\programs\python\python37\lib\site-packages\flask\app.py", line 1718, in handle_user_exception
    reraise(exc_type, exc_value, tb)
  File "c:\users\认为、\appdata\local\programs\python\python37\lib\site-packages\flask\_compat.py", line 35, in reraise
    raise value
  File "c:\users\认为、\appdata\local\programs\python\python37\lib\site-packages\flask\app.py", line 1813, in full_dispatch_request
    rv = self.dispatch_request()
  File "c:\users\认为、\appdata\local\programs\python\python37\lib\site-packages\flask\app.py", line 1799, in dispatch_request
    return self.view_functions[rule.endpoint](**req.view_args)
  File "c:\users\认为、\appdata\local\programs\python\python37\lib\site-packages\flask_httpauth.py", line 105, in decorated
    return f(*args, **kwargs)
  File "D:\项目\project\app\routes.py", line 199, in search
    session['search_info'] = store_info.search(keyword,telnum,info_from,date_begin,date_end)
  File "D:\项目\project\app\models.py", line 194, in search
    info  =  store_info.query.filter_by(None)
TypeError: filter_by() takes 1 positional argument but 2 were given
2019-10-12 16:03:51,780 INFO: Microblog startup [in D:\项目\project\app\__init__.py:39]
2019-10-12 16:03:54,093 ERROR: Exception on /api/search [POST] [in c:\users\认为、\appdata\local\programs\python\python37\lib\site-packages\flask\app.py:1761]
Traceback (most recent call last):
  File "c:\users\认为、\appdata\local\programs\python\python37\lib\site-packages\flask\app.py", line 2292, in wsgi_app
    response = self.full_dispatch_request()
  File "c:\users\认为、\appdata\local\programs\python\python37\lib\site-packages\flask\app.py", line 1816, in full_dispatch_request
    return self.finalize_request(rv)
  File "c:\users\认为、\appdata\local\programs\python\python37\lib\site-packages\flask\app.py", line 1833, in finalize_request
    response = self.process_response(response)
  File "c:\users\认为、\appdata\local\programs\python\python37\lib\site-packages\flask\app.py", line 2114, in process_response
    self.session_interface.save_session(self, ctx.session, response)
  File "c:\users\认为、\appdata\local\programs\python\python37\lib\site-packages\flask\sessions.py", line 375, in save_session
    val = self.get_signing_serializer(app).dumps(dict(session))
  File "c:\users\认为、\appdata\local\programs\python\python37\lib\site-packages\itsdangerous\serializer.py", line 166, in dumps
    payload = want_bytes(self.dump_payload(obj))
  File "c:\users\认为、\appdata\local\programs\python\python37\lib\site-packages\itsdangerous\url_safe.py", line 42, in dump_payload
    json = super(URLSafeSerializerMixin, self).dump_payload(obj)
  File "c:\users\认为、\appdata\local\programs\python\python37\lib\site-packages\itsdangerous\serializer.py", line 133, in dump_payload
    return want_bytes(self.serializer.dumps(obj, **self.serializer_kwargs))
  File "c:\users\认为、\appdata\local\programs\python\python37\lib\site-packages\flask\json\tag.py", line 296, in dumps
    return dumps(self.tag(value), separators=(',', ':'))
  File "c:\users\认为、\appdata\local\programs\python\python37\lib\site-packages\flask\json\__init__.py", line 179, in dumps
    rv = _json.dumps(obj, **kwargs)
  File "c:\users\认为、\appdata\local\programs\python\python37\lib\json\__init__.py", line 238, in dumps
    **kw).encode(obj)
  File "c:\users\认为、\appdata\local\programs\python\python37\lib\json\encoder.py", line 199, in encode
    chunks = self.iterencode(o, _one_shot=True)
  File "c:\users\认为、\appdata\local\programs\python\python37\lib\json\encoder.py", line 257, in iterencode
    return _iterencode(o, 0)
  File "c:\users\认为、\appdata\local\programs\python\python37\lib\site-packages\flask\json\__init__.py", line 81, in default
    return _json.JSONEncoder.default(self, o)
  File "c:\users\认为、\appdata\local\programs\python\python37\lib\json\encoder.py", line 179, in default
    raise TypeError(f'Object of type {o.__class__.__name__} '
TypeError: Object of type BaseQuery is not JSON serializable
2019-10-12 16:05:15,069 INFO: Microblog startup [in D:\项目\project\app\__init__.py:39]
2019-10-12 16:05:18,052 ERROR: Exception on /api/search [POST] [in c:\users\认为、\appdata\local\programs\python\python37\lib\site-packages\flask\app.py:1761]
Traceback (most recent call last):
  File "c:\users\认为、\appdata\local\programs\python\python37\lib\site-packages\flask\app.py", line 2292, in wsgi_app
    response = self.full_dispatch_request()
  File "c:\users\认为、\appdata\local\programs\python\python37\lib\site-packages\flask\app.py", line 1815, in full_dispatch_request
    rv = self.handle_user_exception(e)
  File "c:\users\认为、\appdata\local\programs\python\python37\lib\site-packages\flask\app.py", line 1718, in handle_user_exception
    reraise(exc_type, exc_value, tb)
  File "c:\users\认为、\appdata\local\programs\python\python37\lib\site-packages\flask\_compat.py", line 35, in reraise
    raise value
  File "c:\users\认为、\appdata\local\programs\python\python37\lib\site-packages\flask\app.py", line 1813, in full_dispatch_request
    rv = self.dispatch_request()
  File "c:\users\认为、\appdata\local\programs\python\python37\lib\site-packages\flask\app.py", line 1799, in dispatch_request
    return self.view_functions[rule.endpoint](**req.view_args)
  File "c:\users\认为、\appdata\local\programs\python\python37\lib\site-packages\flask_httpauth.py", line 105, in decorated
    return f(*args, **kwargs)
  File "D:\项目\project\app\routes.py", line 200, in search
    info,pages = store_info.paging(session['search_info'],int(request.get_json(silent=True)['page_num']))
  File "D:\项目\project\app\models.py", line 175, in paging
    page = data.paginate(page_num,per_page=20,error_out=False)
AttributeError: 'list' object has no attribute 'paginate'
2019-10-12 16:07:34,640 INFO: Microblog startup [in D:\项目\project\app\__init__.py:39]
2019-10-12 16:07:37,406 ERROR: Exception on /api/search [POST] [in c:\users\认为、\appdata\local\programs\python\python37\lib\site-packages\flask\app.py:1761]
Traceback (most recent call last):
  File "c:\users\认为、\appdata\local\programs\python\python37\lib\site-packages\flask\app.py", line 2292, in wsgi_app
    response = self.full_dispatch_request()
  File "c:\users\认为、\appdata\local\programs\python\python37\lib\site-packages\flask\app.py", line 1816, in full_dispatch_request
    return self.finalize_request(rv)
  File "c:\users\认为、\appdata\local\programs\python\python37\lib\site-packages\flask\app.py", line 1833, in finalize_request
    response = self.process_response(response)
  File "c:\users\认为、\appdata\local\programs\python\python37\lib\site-packages\flask\app.py", line 2114, in process_response
    self.session_interface.save_session(self, ctx.session, response)
  File "c:\users\认为、\appdata\local\programs\python\python37\lib\site-packages\flask\sessions.py", line 375, in save_session
    val = self.get_signing_serializer(app).dumps(dict(session))
  File "c:\users\认为、\appdata\local\programs\python\python37\lib\site-packages\itsdangerous\serializer.py", line 166, in dumps
    payload = want_bytes(self.dump_payload(obj))
  File "c:\users\认为、\appdata\local\programs\python\python37\lib\site-packages\itsdangerous\url_safe.py", line 42, in dump_payload
    json = super(URLSafeSerializerMixin, self).dump_payload(obj)
  File "c:\users\认为、\appdata\local\programs\python\python37\lib\site-packages\itsdangerous\serializer.py", line 133, in dump_payload
    return want_bytes(self.serializer.dumps(obj, **self.serializer_kwargs))
  File "c:\users\认为、\appdata\local\programs\python\python37\lib\site-packages\flask\json\tag.py", line 296, in dumps
    return dumps(self.tag(value), separators=(',', ':'))
  File "c:\users\认为、\appdata\local\programs\python\python37\lib\site-packages\flask\json\__init__.py", line 179, in dumps
    rv = _json.dumps(obj, **kwargs)
  File "c:\users\认为、\appdata\local\programs\python\python37\lib\json\__init__.py", line 238, in dumps
    **kw).encode(obj)
  File "c:\users\认为、\appdata\local\programs\python\python37\lib\json\encoder.py", line 199, in encode
    chunks = self.iterencode(o, _one_shot=True)
  File "c:\users\认为、\appdata\local\programs\python\python37\lib\json\encoder.py", line 257, in iterencode
    return _iterencode(o, 0)
  File "c:\users\认为、\appdata\local\programs\python\python37\lib\site-packages\flask\json\__init__.py", line 81, in default
    return _json.JSONEncoder.default(self, o)
  File "c:\users\认为、\appdata\local\programs\python\python37\lib\json\encoder.py", line 179, in default
    raise TypeError(f'Object of type {o.__class__.__name__} '
TypeError: Object of type BaseQuery is not JSON serializable
2019-10-12 16:08:22,344 INFO: Microblog startup [in D:\项目\project\app\__init__.py:39]
2019-10-12 16:08:24,561 ERROR: Exception on /api/search [POST] [in c:\users\认为、\appdata\local\programs\python\python37\lib\site-packages\flask\app.py:1761]
Traceback (most recent call last):
  File "c:\users\认为、\appdata\local\programs\python\python37\lib\site-packages\flask\app.py", line 2292, in wsgi_app
    response = self.full_dispatch_request()
  File "c:\users\认为、\appdata\local\programs\python\python37\lib\site-packages\flask\app.py", line 1815, in full_dispatch_request
    rv = self.handle_user_exception(e)
  File "c:\users\认为、\appdata\local\programs\python\python37\lib\site-packages\flask\app.py", line 1718, in handle_user_exception
    reraise(exc_type, exc_value, tb)
  File "c:\users\认为、\appdata\local\programs\python\python37\lib\site-packages\flask\_compat.py", line 35, in reraise
    raise value
  File "c:\users\认为、\appdata\local\programs\python\python37\lib\site-packages\flask\app.py", line 1813, in full_dispatch_request
    rv = self.dispatch_request()
  File "c:\users\认为、\appdata\local\programs\python\python37\lib\site-packages\flask\app.py", line 1799, in dispatch_request
    return self.view_functions[rule.endpoint](**req.view_args)
  File "c:\users\认为、\appdata\local\programs\python\python37\lib\site-packages\flask_httpauth.py", line 105, in decorated
    return f(*args, **kwargs)
  File "D:\项目\project\app\routes.py", line 199, in search
    session['search_info'] = store_info.search(keyword,telnum,info_from,date_begin,date_end)
  File "D:\项目\project\app\models.py", line 195, in search
    info  =  store_info.query.filter(id>=0)
TypeError: '>=' not supported between instances of 'builtin_function_or_method' and 'int'
2019-10-12 16:08:44,555 INFO: Microblog startup [in D:\项目\project\app\__init__.py:39]
2019-10-12 16:08:46,565 ERROR: Exception on /api/search [POST] [in c:\users\认为、\appdata\local\programs\python\python37\lib\site-packages\flask\app.py:1761]
Traceback (most recent call last):
  File "c:\users\认为、\appdata\local\programs\python\python37\lib\site-packages\flask\app.py", line 2292, in wsgi_app
    response = self.full_dispatch_request()
  File "c:\users\认为、\appdata\local\programs\python\python37\lib\site-packages\flask\app.py", line 1816, in full_dispatch_request
    return self.finalize_request(rv)
  File "c:\users\认为、\appdata\local\programs\python\python37\lib\site-packages\flask\app.py", line 1833, in finalize_request
    response = self.process_response(response)
  File "c:\users\认为、\appdata\local\programs\python\python37\lib\site-packages\flask\app.py", line 2114, in process_response
    self.session_interface.save_session(self, ctx.session, response)
  File "c:\users\认为、\appdata\local\programs\python\python37\lib\site-packages\flask\sessions.py", line 375, in save_session
    val = self.get_signing_serializer(app).dumps(dict(session))
  File "c:\users\认为、\appdata\local\programs\python\python37\lib\site-packages\itsdangerous\serializer.py", line 166, in dumps
    payload = want_bytes(self.dump_payload(obj))
  File "c:\users\认为、\appdata\local\programs\python\python37\lib\site-packages\itsdangerous\url_safe.py", line 42, in dump_payload
    json = super(URLSafeSerializerMixin, self).dump_payload(obj)
  File "c:\users\认为、\appdata\local\programs\python\python37\lib\site-packages\itsdangerous\serializer.py", line 133, in dump_payload
    return want_bytes(self.serializer.dumps(obj, **self.serializer_kwargs))
  File "c:\users\认为、\appdata\local\programs\python\python37\lib\site-packages\flask\json\tag.py", line 296, in dumps
    return dumps(self.tag(value), separators=(',', ':'))
  File "c:\users\认为、\appdata\local\programs\python\python37\lib\site-packages\flask\json\__init__.py", line 179, in dumps
    rv = _json.dumps(obj, **kwargs)
  File "c:\users\认为、\appdata\local\programs\python\python37\lib\json\__init__.py", line 238, in dumps
    **kw).encode(obj)
  File "c:\users\认为、\appdata\local\programs\python\python37\lib\json\encoder.py", line 199, in encode
    chunks = self.iterencode(o, _one_shot=True)
  File "c:\users\认为、\appdata\local\programs\python\python37\lib\json\encoder.py", line 257, in iterencode
    return _iterencode(o, 0)
  File "c:\users\认为、\appdata\local\programs\python\python37\lib\site-packages\flask\json\__init__.py", line 81, in default
    return _json.JSONEncoder.default(self, o)
  File "c:\users\认为、\appdata\local\programs\python\python37\lib\json\encoder.py", line 179, in default
    raise TypeError(f'Object of type {o.__class__.__name__} '
TypeError: Object of type BaseQuery is not JSON serializable
2019-10-12 16:11:52,389 INFO: Microblog startup [in D:\项目\project\app\__init__.py:39]
2019-10-12 16:11:55,160 ERROR: Exception on /api/search [POST] [in c:\users\认为、\appdata\local\programs\python\python37\lib\site-packages\flask\app.py:1761]
Traceback (most recent call last):
  File "c:\users\认为、\appdata\local\programs\python\python37\lib\site-packages\flask\app.py", line 1974, in make_response
    rv = self.response_class.force_type(rv, request.environ)
  File "c:\users\认为、\appdata\local\programs\python\python37\lib\site-packages\werkzeug\wrappers.py", line 921, in force_type
    response = BaseResponse(*_run_wsgi_app(response, environ))
  File "c:\users\认为、\appdata\local\programs\python\python37\lib\site-packages\werkzeug\wrappers.py", line 59, in _run_wsgi_app
    return _run_wsgi_app(*args)
  File "c:\users\认为、\appdata\local\programs\python\python37\lib\site-packages\werkzeug\test.py", line 923, in run_wsgi_app
    app_rv = app(environ, start_response)
TypeError: 'dict' object is not callable

During handling of the above exception, another exception occurred:

Traceback (most recent call last):
  File "c:\users\认为、\appdata\local\programs\python\python37\lib\site-packages\flask\app.py", line 2292, in wsgi_app
    response = self.full_dispatch_request()
  File "c:\users\认为、\appdata\local\programs\python\python37\lib\site-packages\flask\app.py", line 1816, in full_dispatch_request
    return self.finalize_request(rv)
  File "c:\users\认为、\appdata\local\programs\python\python37\lib\site-packages\flask\app.py", line 1831, in finalize_request
    response = self.make_response(rv)
  File "c:\users\认为、\appdata\local\programs\python\python37\lib\site-packages\flask\app.py", line 1982, in make_response
    reraise(TypeError, new_error, sys.exc_info()[2])
  File "c:\users\认为、\appdata\local\programs\python\python37\lib\site-packages\flask\_compat.py", line 34, in reraise
    raise value.with_traceback(tb)
  File "c:\users\认为、\appdata\local\programs\python\python37\lib\site-packages\flask\app.py", line 1974, in make_response
    rv = self.response_class.force_type(rv, request.environ)
  File "c:\users\认为、\appdata\local\programs\python\python37\lib\site-packages\werkzeug\wrappers.py", line 921, in force_type
    response = BaseResponse(*_run_wsgi_app(response, environ))
  File "c:\users\认为、\appdata\local\programs\python\python37\lib\site-packages\werkzeug\wrappers.py", line 59, in _run_wsgi_app
    return _run_wsgi_app(*args)
  File "c:\users\认为、\appdata\local\programs\python\python37\lib\site-packages\werkzeug\test.py", line 923, in run_wsgi_app
    app_rv = app(environ, start_response)
TypeError: 'dict' object is not callable
The view function did not return a valid response. The return type must be a string, tuple, Response instance, or WSGI callable, but it was a dict.
