2019-09-28 21:23:52,845 ERROR: Exception on /api/check_account [POST] [in c:\users\认为、\appdata\local\programs\python\python37\lib\site-packages\flask\app.py:1761]
Traceback (most recent call last):
  File "c:\users\认为、\appdata\local\programs\python\python37\lib\site-packages\flask\app.py", line 2292, in wsgi_app
    response = self.full_dispatch_request()
  File "c:\users\认为、\appdata\local\programs\python\python37\lib\site-packages\flask\app.py", line 1815, in full_dispatch_request
    rv = self.handle_user_exception(e)
  File "c:\users\认为、\appdata\local\programs\python\python37\lib\site-packages\flask\app.py", line 1718, in handle_user_exception
    reraise(exc_type, exc_value, tb)
  File "c:\users\认为、\appdata\local\programs\python\python37\lib\site-packages\flask\_compat.py", line 35, in reraise
    raise value
  File "c:\users\认为、\appdata\local\programs\python\python37\lib\site-packages\flask\app.py", line 1813, in full_dispatch_request
    rv = self.dispatch_request()
  File "c:\users\认为、\appdata\local\programs\python\python37\lib\site-packages\flask\app.py", line 1799, in dispatch_request
    return self.view_functions[rule.endpoint](**req.view_args)
  File "D:\项目\project\app\routes.py", line 23, in check_account
    ok = verify_password(telnum, password)
  File "D:\项目\project\app\models.py", line 172, in verify_password
    user = User.query.filter_by(telnum = telnum).first()
  File "c:\users\认为、\appdata\local\programs\python\python37\lib\site-packages\sqlalchemy\orm\query.py", line 3232, in first
    ret = list(self[0:1])
  File "c:\users\认为、\appdata\local\programs\python\python37\lib\site-packages\sqlalchemy\orm\query.py", line 3018, in __getitem__
    return list(res)
  File "c:\users\认为、\appdata\local\programs\python\python37\lib\site-packages\sqlalchemy\orm\loading.py", line 105, in instances
    util.raise_from_cause(err)
  File "c:\users\认为、\appdata\local\programs\python\python37\lib\site-packages\sqlalchemy\util\compat.py", line 398, in raise_from_cause
    reraise(type(exception), exception, tb=exc_tb, cause=cause)
  File "c:\users\认为、\appdata\local\programs\python\python37\lib\site-packages\sqlalchemy\util\compat.py", line 153, in reraise
    raise value
  File "c:\users\认为、\appdata\local\programs\python\python37\lib\site-packages\sqlalchemy\orm\loading.py", line 85, in instances
    rows = [proc(row) for row in fetch]
  File "c:\users\认为、\appdata\local\programs\python\python37\lib\site-packages\sqlalchemy\orm\loading.py", line 85, in <listcomp>
    rows = [proc(row) for row in fetch]
  File "c:\users\认为、\appdata\local\programs\python\python37\lib\site-packages\sqlalchemy\orm\loading.py", line 572, in _instance
    populators,
  File "c:\users\认为、\appdata\local\programs\python\python37\lib\site-packages\sqlalchemy\orm\loading.py", line 693, in _populate_full
    dict_[key] = getter(row)
  File "c:\users\认为、\appdata\local\programs\python\python37\lib\site-packages\sqlalchemy\sql\sqltypes.py", line 1681, in process
    value = impl_processor(value)
  File "c:\users\认为、\appdata\local\programs\python\python37\lib\site-packages\sqlalchemy\sql\sqltypes.py", line 944, in process
    value = bytes(value)
TypeError: string argument without an encoding
2019-09-28 21:24:51,562 ERROR: Exception on /api/check_account [POST] [in c:\users\认为、\appdata\local\programs\python\python37\lib\site-packages\flask\app.py:1761]
Traceback (most recent call last):
  File "c:\users\认为、\appdata\local\programs\python\python37\lib\site-packages\flask\app.py", line 2292, in wsgi_app
    response = self.full_dispatch_request()
  File "c:\users\认为、\appdata\local\programs\python\python37\lib\site-packages\flask\app.py", line 1815, in full_dispatch_request
    rv = self.handle_user_exception(e)
  File "c:\users\认为、\appdata\local\programs\python\python37\lib\site-packages\flask\app.py", line 1718, in handle_user_exception
    reraise(exc_type, exc_value, tb)
  File "c:\users\认为、\appdata\local\programs\python\python37\lib\site-packages\flask\_compat.py", line 35, in reraise
    raise value
  File "c:\users\认为、\appdata\local\programs\python\python37\lib\site-packages\flask\app.py", line 1813, in full_dispatch_request
    rv = self.dispatch_request()
  File "c:\users\认为、\appdata\local\programs\python\python37\lib\site-packages\flask\app.py", line 1799, in dispatch_request
    return self.view_functions[rule.endpoint](**req.view_args)
  File "D:\项目\project\app\routes.py", line 23, in check_account
    ok = verify_password(telnum, password)
  File "D:\项目\project\app\models.py", line 172, in verify_password
    user = User.query.filter_by(telnum = telnum).first()
  File "c:\users\认为、\appdata\local\programs\python\python37\lib\site-packages\sqlalchemy\orm\query.py", line 3232, in first
    ret = list(self[0:1])
  File "c:\users\认为、\appdata\local\programs\python\python37\lib\site-packages\sqlalchemy\orm\query.py", line 3018, in __getitem__
    return list(res)
  File "c:\users\认为、\appdata\local\programs\python\python37\lib\site-packages\sqlalchemy\orm\loading.py", line 105, in instances
    util.raise_from_cause(err)
  File "c:\users\认为、\appdata\local\programs\python\python37\lib\site-packages\sqlalchemy\util\compat.py", line 398, in raise_from_cause
    reraise(type(exception), exception, tb=exc_tb, cause=cause)
  File "c:\users\认为、\appdata\local\programs\python\python37\lib\site-packages\sqlalchemy\util\compat.py", line 153, in reraise
    raise value
  File "c:\users\认为、\appdata\local\programs\python\python37\lib\site-packages\sqlalchemy\orm\loading.py", line 85, in instances
    rows = [proc(row) for row in fetch]
  File "c:\users\认为、\appdata\local\programs\python\python37\lib\site-packages\sqlalchemy\orm\loading.py", line 85, in <listcomp>
    rows = [proc(row) for row in fetch]
  File "c:\users\认为、\appdata\local\programs\python\python37\lib\site-packages\sqlalchemy\orm\loading.py", line 572, in _instance
    populators,
  File "c:\users\认为、\appdata\local\programs\python\python37\lib\site-packages\sqlalchemy\orm\loading.py", line 693, in _populate_full
    dict_[key] = getter(row)
  File "c:\users\认为、\appdata\local\programs\python\python37\lib\site-packages\sqlalchemy\sql\sqltypes.py", line 1681, in process
    value = impl_processor(value)
  File "c:\users\认为、\appdata\local\programs\python\python37\lib\site-packages\sqlalchemy\sql\sqltypes.py", line 944, in process
    value = bytes(value)
TypeError: string argument without an encoding
2019-09-28 21:26:31,153 ERROR: Exception on /api/check_account [POST] [in c:\users\认为、\appdata\local\programs\python\python37\lib\site-packages\flask\app.py:1761]
Traceback (most recent call last):
  File "c:\users\认为、\appdata\local\programs\python\python37\lib\site-packages\flask\app.py", line 2292, in wsgi_app
    response = self.full_dispatch_request()
  File "c:\users\认为、\appdata\local\programs\python\python37\lib\site-packages\flask\app.py", line 1815, in full_dispatch_request
    rv = self.handle_user_exception(e)
  File "c:\users\认为、\appdata\local\programs\python\python37\lib\site-packages\flask\app.py", line 1718, in handle_user_exception
    reraise(exc_type, exc_value, tb)
  File "c:\users\认为、\appdata\local\programs\python\python37\lib\site-packages\flask\_compat.py", line 35, in reraise
    raise value
  File "c:\users\认为、\appdata\local\programs\python\python37\lib\site-packages\flask\app.py", line 1813, in full_dispatch_request
    rv = self.dispatch_request()
  File "c:\users\认为、\appdata\local\programs\python\python37\lib\site-packages\flask\app.py", line 1799, in dispatch_request
    return self.view_functions[rule.endpoint](**req.view_args)
  File "D:\项目\project\app\routes.py", line 23, in check_account
    ok = verify_password(telnum, password)
  File "D:\项目\project\app\models.py", line 172, in verify_password
    user = User.query.filter_by(telnum = telnum).first()
  File "c:\users\认为、\appdata\local\programs\python\python37\lib\site-packages\sqlalchemy\orm\query.py", line 3232, in first
    ret = list(self[0:1])
  File "c:\users\认为、\appdata\local\programs\python\python37\lib\site-packages\sqlalchemy\orm\query.py", line 3018, in __getitem__
    return list(res)
  File "c:\users\认为、\appdata\local\programs\python\python37\lib\site-packages\sqlalchemy\orm\loading.py", line 105, in instances
    util.raise_from_cause(err)
  File "c:\users\认为、\appdata\local\programs\python\python37\lib\site-packages\sqlalchemy\util\compat.py", line 398, in raise_from_cause
    reraise(type(exception), exception, tb=exc_tb, cause=cause)
  File "c:\users\认为、\appdata\local\programs\python\python37\lib\site-packages\sqlalchemy\util\compat.py", line 153, in reraise
    raise value
  File "c:\users\认为、\appdata\local\programs\python\python37\lib\site-packages\sqlalchemy\orm\loading.py", line 85, in instances
    rows = [proc(row) for row in fetch]
  File "c:\users\认为、\appdata\local\programs\python\python37\lib\site-packages\sqlalchemy\orm\loading.py", line 85, in <listcomp>
    rows = [proc(row) for row in fetch]
  File "c:\users\认为、\appdata\local\programs\python\python37\lib\site-packages\sqlalchemy\orm\loading.py", line 572, in _instance
    populators,
  File "c:\users\认为、\appdata\local\programs\python\python37\lib\site-packages\sqlalchemy\orm\loading.py", line 693, in _populate_full
    dict_[key] = getter(row)
  File "c:\users\认为、\appdata\local\programs\python\python37\lib\site-packages\sqlalchemy\sql\sqltypes.py", line 1681, in process
    value = impl_processor(value)
  File "c:\users\认为、\appdata\local\programs\python\python37\lib\site-packages\sqlalchemy\sql\sqltypes.py", line 944, in process
    value = bytes(value)
TypeError: string argument without an encoding
2019-09-28 21:27:05,193 INFO: Microblog startup [in D:\项目\project\app\__init__.py:35]
2019-09-28 21:28:36,747 INFO: Microblog startup [in D:\项目\project\app\__init__.py:35]
2019-09-28 21:30:03,861 INFO: Microblog startup [in D:\项目\project\app\__init__.py:35]
2019-09-28 21:30:57,962 INFO: Microblog startup [in D:\项目\project\app\__init__.py:35]
2019-09-28 21:31:01,418 ERROR: Exception on /api/check_account [POST] [in c:\users\认为、\appdata\local\programs\python\python37\lib\site-packages\flask\app.py:1761]
Traceback (most recent call last):
  File "c:\users\认为、\appdata\local\programs\python\python37\lib\site-packages\flask\app.py", line 2292, in wsgi_app
    response = self.full_dispatch_request()
  File "c:\users\认为、\appdata\local\programs\python\python37\lib\site-packages\flask\app.py", line 1815, in full_dispatch_request
    rv = self.handle_user_exception(e)
  File "c:\users\认为、\appdata\local\programs\python\python37\lib\site-packages\flask\app.py", line 1718, in handle_user_exception
    reraise(exc_type, exc_value, tb)
  File "c:\users\认为、\appdata\local\programs\python\python37\lib\site-packages\flask\_compat.py", line 35, in reraise
    raise value
  File "c:\users\认为、\appdata\local\programs\python\python37\lib\site-packages\flask\app.py", line 1813, in full_dispatch_request
    rv = self.dispatch_request()
  File "c:\users\认为、\appdata\local\programs\python\python37\lib\site-packages\flask\app.py", line 1799, in dispatch_request
    return self.view_functions[rule.endpoint](**req.view_args)
  File "D:\项目\project\app\routes.py", line 23, in check_account
    ok = verify_password(telnum, password)
  File "D:\项目\project\app\models.py", line 173, in verify_password
    user = User.query.filter_by(telnum = telnum).first()
  File "c:\users\认为、\appdata\local\programs\python\python37\lib\site-packages\sqlalchemy\orm\query.py", line 3232, in first
    ret = list(self[0:1])
  File "c:\users\认为、\appdata\local\programs\python\python37\lib\site-packages\sqlalchemy\orm\query.py", line 3018, in __getitem__
    return list(res)
  File "c:\users\认为、\appdata\local\programs\python\python37\lib\site-packages\sqlalchemy\orm\loading.py", line 105, in instances
    util.raise_from_cause(err)
  File "c:\users\认为、\appdata\local\programs\python\python37\lib\site-packages\sqlalchemy\util\compat.py", line 398, in raise_from_cause
    reraise(type(exception), exception, tb=exc_tb, cause=cause)
  File "c:\users\认为、\appdata\local\programs\python\python37\lib\site-packages\sqlalchemy\util\compat.py", line 153, in reraise
    raise value
  File "c:\users\认为、\appdata\local\programs\python\python37\lib\site-packages\sqlalchemy\orm\loading.py", line 85, in instances
    rows = [proc(row) for row in fetch]
  File "c:\users\认为、\appdata\local\programs\python\python37\lib\site-packages\sqlalchemy\orm\loading.py", line 85, in <listcomp>
    rows = [proc(row) for row in fetch]
  File "c:\users\认为、\appdata\local\programs\python\python37\lib\site-packages\sqlalchemy\orm\loading.py", line 572, in _instance
    populators,
  File "c:\users\认为、\appdata\local\programs\python\python37\lib\site-packages\sqlalchemy\orm\loading.py", line 693, in _populate_full
    dict_[key] = getter(row)
  File "c:\users\认为、\appdata\local\programs\python\python37\lib\site-packages\sqlalchemy\sql\sqltypes.py", line 1681, in process
    value = impl_processor(value)
  File "c:\users\认为、\appdata\local\programs\python\python37\lib\site-packages\sqlalchemy\sql\sqltypes.py", line 944, in process
    value = bytes(value)
TypeError: string argument without an encoding
2019-09-28 21:31:58,902 INFO: Microblog startup [in D:\项目\project\app\__init__.py:35]
2019-09-28 21:32:01,437 ERROR: Exception on /api/check_account [POST] [in c:\users\认为、\appdata\local\programs\python\python37\lib\site-packages\flask\app.py:1761]
Traceback (most recent call last):
  File "c:\users\认为、\appdata\local\programs\python\python37\lib\site-packages\flask\app.py", line 2292, in wsgi_app
    response = self.full_dispatch_request()
  File "c:\users\认为、\appdata\local\programs\python\python37\lib\site-packages\flask\app.py", line 1815, in full_dispatch_request
    rv = self.handle_user_exception(e)
  File "c:\users\认为、\appdata\local\programs\python\python37\lib\site-packages\flask\app.py", line 1718, in handle_user_exception
    reraise(exc_type, exc_value, tb)
  File "c:\users\认为、\appdata\local\programs\python\python37\lib\site-packages\flask\_compat.py", line 35, in reraise
    raise value
  File "c:\users\认为、\appdata\local\programs\python\python37\lib\site-packages\flask\app.py", line 1813, in full_dispatch_request
    rv = self.dispatch_request()
  File "c:\users\认为、\appdata\local\programs\python\python37\lib\site-packages\flask\app.py", line 1799, in dispatch_request
    return self.view_functions[rule.endpoint](**req.view_args)
  File "D:\项目\project\app\routes.py", line 23, in check_account
    ok = verify_password(telnum.encode('assic'), password.encode('assic'))
LookupError: unknown encoding: assic
2019-09-28 21:32:54,350 INFO: Microblog startup [in D:\项目\project\app\__init__.py:35]
2019-09-28 21:32:56,895 ERROR: Exception on /api/check_account [POST] [in c:\users\认为、\appdata\local\programs\python\python37\lib\site-packages\flask\app.py:1761]
Traceback (most recent call last):
  File "c:\users\认为、\appdata\local\programs\python\python37\lib\site-packages\flask\app.py", line 2292, in wsgi_app
    response = self.full_dispatch_request()
  File "c:\users\认为、\appdata\local\programs\python\python37\lib\site-packages\flask\app.py", line 1815, in full_dispatch_request
    rv = self.handle_user_exception(e)
  File "c:\users\认为、\appdata\local\programs\python\python37\lib\site-packages\flask\app.py", line 1718, in handle_user_exception
    reraise(exc_type, exc_value, tb)
  File "c:\users\认为、\appdata\local\programs\python\python37\lib\site-packages\flask\_compat.py", line 35, in reraise
    raise value
  File "c:\users\认为、\appdata\local\programs\python\python37\lib\site-packages\flask\app.py", line 1813, in full_dispatch_request
    rv = self.dispatch_request()
  File "c:\users\认为、\appdata\local\programs\python\python37\lib\site-packages\flask\app.py", line 1799, in dispatch_request
    return self.view_functions[rule.endpoint](**req.view_args)
  File "D:\项目\project\app\routes.py", line 23, in check_account
    ok = verify_password(telnum.encode('Unicode'), password.encode('Unicode'))
LookupError: unknown encoding: Unicode
2019-09-28 21:34:47,950 INFO: Microblog startup [in D:\项目\project\app\__init__.py:35]
2019-09-28 21:34:52,192 ERROR: Exception on /api/check_account [POST] [in c:\users\认为、\appdata\local\programs\python\python37\lib\site-packages\flask\app.py:1761]
Traceback (most recent call last):
  File "c:\users\认为、\appdata\local\programs\python\python37\lib\site-packages\flask\app.py", line 2292, in wsgi_app
    response = self.full_dispatch_request()
  File "c:\users\认为、\appdata\local\programs\python\python37\lib\site-packages\flask\app.py", line 1815, in full_dispatch_request
    rv = self.handle_user_exception(e)
  File "c:\users\认为、\appdata\local\programs\python\python37\lib\site-packages\flask\app.py", line 1718, in handle_user_exception
    reraise(exc_type, exc_value, tb)
  File "c:\users\认为、\appdata\local\programs\python\python37\lib\site-packages\flask\_compat.py", line 35, in reraise
    raise value
  File "c:\users\认为、\appdata\local\programs\python\python37\lib\site-packages\flask\app.py", line 1813, in full_dispatch_request
    rv = self.dispatch_request()
  File "c:\users\认为、\appdata\local\programs\python\python37\lib\site-packages\flask\app.py", line 1799, in dispatch_request
    return self.view_functions[rule.endpoint](**req.view_args)
  File "D:\项目\project\app\routes.py", line 23, in check_account
    ok = verify_password(telnum.decode('utf-8'), password.decode('utf-8'))
AttributeError: 'str' object has no attribute 'decode'
2019-09-28 21:36:31,121 INFO: Microblog startup [in D:\项目\project\app\__init__.py:35]
2019-09-28 21:36:32,728 ERROR: Exception on /api/check_account [POST] [in c:\users\认为、\appdata\local\programs\python\python37\lib\site-packages\flask\app.py:1761]
Traceback (most recent call last):
  File "c:\users\认为、\appdata\local\programs\python\python37\lib\site-packages\flask\app.py", line 2292, in wsgi_app
    response = self.full_dispatch_request()
  File "c:\users\认为、\appdata\local\programs\python\python37\lib\site-packages\flask\app.py", line 1815, in full_dispatch_request
    rv = self.handle_user_exception(e)
  File "c:\users\认为、\appdata\local\programs\python\python37\lib\site-packages\flask\app.py", line 1718, in handle_user_exception
    reraise(exc_type, exc_value, tb)
  File "c:\users\认为、\appdata\local\programs\python\python37\lib\site-packages\flask\_compat.py", line 35, in reraise
    raise value
  File "c:\users\认为、\appdata\local\programs\python\python37\lib\site-packages\flask\app.py", line 1813, in full_dispatch_request
    rv = self.dispatch_request()
  File "c:\users\认为、\appdata\local\programs\python\python37\lib\site-packages\flask\app.py", line 1799, in dispatch_request
    return self.view_functions[rule.endpoint](**req.view_args)
  File "D:\项目\project\app\routes.py", line 23, in check_account
    ok = verify_password(telnum.decode('ascii'), password.decode('ascii'))
AttributeError: 'str' object has no attribute 'decode'
2019-09-28 21:36:50,653 INFO: Microblog startup [in D:\项目\project\app\__init__.py:35]
2019-09-28 21:40:04,403 INFO: Microblog startup [in D:\项目\project\app\__init__.py:35]
2019-09-28 21:40:07,109 ERROR: Exception on /api/check_account [POST] [in c:\users\认为、\appdata\local\programs\python\python37\lib\site-packages\flask\app.py:1761]
Traceback (most recent call last):
  File "c:\users\认为、\appdata\local\programs\python\python37\lib\site-packages\flask\app.py", line 2292, in wsgi_app
    response = self.full_dispatch_request()
  File "c:\users\认为、\appdata\local\programs\python\python37\lib\site-packages\flask\app.py", line 1815, in full_dispatch_request
    rv = self.handle_user_exception(e)
  File "c:\users\认为、\appdata\local\programs\python\python37\lib\site-packages\flask\app.py", line 1718, in handle_user_exception
    reraise(exc_type, exc_value, tb)
  File "c:\users\认为、\appdata\local\programs\python\python37\lib\site-packages\flask\_compat.py", line 35, in reraise
    raise value
  File "c:\users\认为、\appdata\local\programs\python\python37\lib\site-packages\flask\app.py", line 1813, in full_dispatch_request
    rv = self.dispatch_request()
  File "c:\users\认为、\appdata\local\programs\python\python37\lib\site-packages\flask\app.py", line 1799, in dispatch_request
    return self.view_functions[rule.endpoint](**req.view_args)
  File "D:\项目\project\app\routes.py", line 23, in check_account
    ok = verify_password(str(telnum), str(password))
  File "D:\项目\project\app\models.py", line 173, in verify_password
    user = User.query.filter_by(telnum = telnum).first()
  File "c:\users\认为、\appdata\local\programs\python\python37\lib\site-packages\sqlalchemy\orm\query.py", line 3232, in first
    ret = list(self[0:1])
  File "c:\users\认为、\appdata\local\programs\python\python37\lib\site-packages\sqlalchemy\orm\query.py", line 3018, in __getitem__
    return list(res)
  File "c:\users\认为、\appdata\local\programs\python\python37\lib\site-packages\sqlalchemy\orm\loading.py", line 105, in instances
    util.raise_from_cause(err)
  File "c:\users\认为、\appdata\local\programs\python\python37\lib\site-packages\sqlalchemy\util\compat.py", line 398, in raise_from_cause
    reraise(type(exception), exception, tb=exc_tb, cause=cause)
  File "c:\users\认为、\appdata\local\programs\python\python37\lib\site-packages\sqlalchemy\util\compat.py", line 153, in reraise
    raise value
  File "c:\users\认为、\appdata\local\programs\python\python37\lib\site-packages\sqlalchemy\orm\loading.py", line 85, in instances
    rows = [proc(row) for row in fetch]
  File "c:\users\认为、\appdata\local\programs\python\python37\lib\site-packages\sqlalchemy\orm\loading.py", line 85, in <listcomp>
    rows = [proc(row) for row in fetch]
  File "c:\users\认为、\appdata\local\programs\python\python37\lib\site-packages\sqlalchemy\orm\loading.py", line 572, in _instance
    populators,
  File "c:\users\认为、\appdata\local\programs\python\python37\lib\site-packages\sqlalchemy\orm\loading.py", line 693, in _populate_full
    dict_[key] = getter(row)
  File "c:\users\认为、\appdata\local\programs\python\python37\lib\site-packages\sqlalchemy\sql\sqltypes.py", line 1681, in process
    value = impl_processor(value)
  File "c:\users\认为、\appdata\local\programs\python\python37\lib\site-packages\sqlalchemy\sql\sqltypes.py", line 944, in process
    value = bytes(value)
TypeError: string argument without an encoding
2019-09-28 21:41:28,333 INFO: Microblog startup [in D:\项目\project\app\__init__.py:35]
2019-09-28 21:41:30,813 ERROR: Exception on /api/check_account [POST] [in c:\users\认为、\appdata\local\programs\python\python37\lib\site-packages\flask\app.py:1761]
Traceback (most recent call last):
  File "c:\users\认为、\appdata\local\programs\python\python37\lib\site-packages\flask\app.py", line 2292, in wsgi_app
    response = self.full_dispatch_request()
  File "c:\users\认为、\appdata\local\programs\python\python37\lib\site-packages\flask\app.py", line 1815, in full_dispatch_request
    rv = self.handle_user_exception(e)
  File "c:\users\认为、\appdata\local\programs\python\python37\lib\site-packages\flask\app.py", line 1718, in handle_user_exception
    reraise(exc_type, exc_value, tb)
  File "c:\users\认为、\appdata\local\programs\python\python37\lib\site-packages\flask\_compat.py", line 35, in reraise
    raise value
  File "c:\users\认为、\appdata\local\programs\python\python37\lib\site-packages\flask\app.py", line 1813, in full_dispatch_request
    rv = self.dispatch_request()
  File "c:\users\认为、\appdata\local\programs\python\python37\lib\site-packages\flask\app.py", line 1799, in dispatch_request
    return self.view_functions[rule.endpoint](**req.view_args)
  File "D:\项目\project\app\routes.py", line 23, in check_account
    ok = verify_password(str(telnum), str(password))
  File "D:\项目\project\app\models.py", line 173, in verify_password
    user = User.query.filter_by(telnum = telnum).first()
  File "c:\users\认为、\appdata\local\programs\python\python37\lib\site-packages\sqlalchemy\orm\query.py", line 3232, in first
    ret = list(self[0:1])
  File "c:\users\认为、\appdata\local\programs\python\python37\lib\site-packages\sqlalchemy\orm\query.py", line 3018, in __getitem__
    return list(res)
  File "c:\users\认为、\appdata\local\programs\python\python37\lib\site-packages\sqlalchemy\orm\loading.py", line 105, in instances
    util.raise_from_cause(err)
  File "c:\users\认为、\appdata\local\programs\python\python37\lib\site-packages\sqlalchemy\util\compat.py", line 398, in raise_from_cause
    reraise(type(exception), exception, tb=exc_tb, cause=cause)
  File "c:\users\认为、\appdata\local\programs\python\python37\lib\site-packages\sqlalchemy\util\compat.py", line 153, in reraise
    raise value
  File "c:\users\认为、\appdata\local\programs\python\python37\lib\site-packages\sqlalchemy\orm\loading.py", line 85, in instances
    rows = [proc(row) for row in fetch]
  File "c:\users\认为、\appdata\local\programs\python\python37\lib\site-packages\sqlalchemy\orm\loading.py", line 85, in <listcomp>
    rows = [proc(row) for row in fetch]
  File "c:\users\认为、\appdata\local\programs\python\python37\lib\site-packages\sqlalchemy\orm\loading.py", line 572, in _instance
    populators,
  File "c:\users\认为、\appdata\local\programs\python\python37\lib\site-packages\sqlalchemy\orm\loading.py", line 693, in _populate_full
    dict_[key] = getter(row)
  File "c:\users\认为、\appdata\local\programs\python\python37\lib\site-packages\sqlalchemy\sql\sqltypes.py", line 1681, in process
    value = impl_processor(value)
  File "c:\users\认为、\appdata\local\programs\python\python37\lib\site-packages\sqlalchemy\sql\sqltypes.py", line 944, in process
    value = bytes(value)
TypeError: string argument without an encoding
2019-09-28 21:44:19,512 INFO: Microblog startup [in D:\项目\project\app\__init__.py:35]
2019-09-28 21:44:37,580 INFO: Microblog startup [in D:\项目\project\app\__init__.py:35]
2019-09-28 21:44:41,327 ERROR: Exception on /api/check_account [POST] [in c:\users\认为、\appdata\local\programs\python\python37\lib\site-packages\flask\app.py:1761]
Traceback (most recent call last):
  File "c:\users\认为、\appdata\local\programs\python\python37\lib\site-packages\flask\app.py", line 2292, in wsgi_app
    response = self.full_dispatch_request()
  File "c:\users\认为、\appdata\local\programs\python\python37\lib\site-packages\flask\app.py", line 1815, in full_dispatch_request
    rv = self.handle_user_exception(e)
  File "c:\users\认为、\appdata\local\programs\python\python37\lib\site-packages\flask\app.py", line 1718, in handle_user_exception
    reraise(exc_type, exc_value, tb)
  File "c:\users\认为、\appdata\local\programs\python\python37\lib\site-packages\flask\_compat.py", line 35, in reraise
    raise value
  File "c:\users\认为、\appdata\local\programs\python\python37\lib\site-packages\flask\app.py", line 1813, in full_dispatch_request
    rv = self.dispatch_request()
  File "c:\users\认为、\appdata\local\programs\python\python37\lib\site-packages\flask\app.py", line 1799, in dispatch_request
    return self.view_functions[rule.endpoint](**req.view_args)
  File "D:\项目\project\app\routes.py", line 23, in check_account
    ok = verify_password(telnum.encode('ascii'), password.encode('ascii'))
  File "D:\项目\project\app\models.py", line 173, in verify_password
    user = User.query.filter_by(telnum = '1234').first()
  File "c:\users\认为、\appdata\local\programs\python\python37\lib\site-packages\sqlalchemy\orm\query.py", line 3232, in first
    ret = list(self[0:1])
  File "c:\users\认为、\appdata\local\programs\python\python37\lib\site-packages\sqlalchemy\orm\query.py", line 3018, in __getitem__
    return list(res)
  File "c:\users\认为、\appdata\local\programs\python\python37\lib\site-packages\sqlalchemy\orm\loading.py", line 105, in instances
    util.raise_from_cause(err)
  File "c:\users\认为、\appdata\local\programs\python\python37\lib\site-packages\sqlalchemy\util\compat.py", line 398, in raise_from_cause
    reraise(type(exception), exception, tb=exc_tb, cause=cause)
  File "c:\users\认为、\appdata\local\programs\python\python37\lib\site-packages\sqlalchemy\util\compat.py", line 153, in reraise
    raise value
  File "c:\users\认为、\appdata\local\programs\python\python37\lib\site-packages\sqlalchemy\orm\loading.py", line 85, in instances
    rows = [proc(row) for row in fetch]
  File "c:\users\认为、\appdata\local\programs\python\python37\lib\site-packages\sqlalchemy\orm\loading.py", line 85, in <listcomp>
    rows = [proc(row) for row in fetch]
  File "c:\users\认为、\appdata\local\programs\python\python37\lib\site-packages\sqlalchemy\orm\loading.py", line 572, in _instance
    populators,
  File "c:\users\认为、\appdata\local\programs\python\python37\lib\site-packages\sqlalchemy\orm\loading.py", line 693, in _populate_full
    dict_[key] = getter(row)
  File "c:\users\认为、\appdata\local\programs\python\python37\lib\site-packages\sqlalchemy\sql\sqltypes.py", line 1681, in process
    value = impl_processor(value)
  File "c:\users\认为、\appdata\local\programs\python\python37\lib\site-packages\sqlalchemy\sql\sqltypes.py", line 944, in process
    value = bytes(value)
TypeError: string argument without an encoding
2019-09-28 21:45:16,244 INFO: Microblog startup [in D:\项目\project\app\__init__.py:35]
2019-09-28 21:47:18,778 INFO: Microblog startup [in D:\项目\project\app\__init__.py:35]
2019-09-28 21:53:03,550 INFO: Microblog startup [in D:\项目\project\app\__init__.py:35]
2019-09-28 21:53:07,620 ERROR: Exception on /api/check_account [POST] [in c:\users\认为、\appdata\local\programs\python\python37\lib\site-packages\flask\app.py:1761]
Traceback (most recent call last):
  File "c:\users\认为、\appdata\local\programs\python\python37\lib\site-packages\flask\app.py", line 2292, in wsgi_app
    response = self.full_dispatch_request()
  File "c:\users\认为、\appdata\local\programs\python\python37\lib\site-packages\flask\app.py", line 1815, in full_dispatch_request
    rv = self.handle_user_exception(e)
  File "c:\users\认为、\appdata\local\programs\python\python37\lib\site-packages\flask\app.py", line 1718, in handle_user_exception
    reraise(exc_type, exc_value, tb)
  File "c:\users\认为、\appdata\local\programs\python\python37\lib\site-packages\flask\_compat.py", line 35, in reraise
    raise value
  File "c:\users\认为、\appdata\local\programs\python\python37\lib\site-packages\flask\app.py", line 1813, in full_dispatch_request
    rv = self.dispatch_request()
  File "c:\users\认为、\appdata\local\programs\python\python37\lib\site-packages\flask\app.py", line 1799, in dispatch_request
    return self.view_functions[rule.endpoint](**req.view_args)
  File "D:\项目\project\app\routes.py", line 23, in check_account
    ok = verify_password(bytes(telnum), bytes(password))
TypeError: string argument without an encoding
2019-09-28 21:53:21,879 INFO: Microblog startup [in D:\项目\project\app\__init__.py:35]
2019-09-28 21:53:25,167 ERROR: Exception on /api/check_account [POST] [in c:\users\认为、\appdata\local\programs\python\python37\lib\site-packages\flask\app.py:1761]
Traceback (most recent call last):
  File "c:\users\认为、\appdata\local\programs\python\python37\lib\site-packages\flask\app.py", line 2292, in wsgi_app
    response = self.full_dispatch_request()
  File "c:\users\认为、\appdata\local\programs\python\python37\lib\site-packages\flask\app.py", line 1815, in full_dispatch_request
    rv = self.handle_user_exception(e)
  File "c:\users\认为、\appdata\local\programs\python\python37\lib\site-packages\flask\app.py", line 1718, in handle_user_exception
    reraise(exc_type, exc_value, tb)
  File "c:\users\认为、\appdata\local\programs\python\python37\lib\site-packages\flask\_compat.py", line 35, in reraise
    raise value
  File "c:\users\认为、\appdata\local\programs\python\python37\lib\site-packages\flask\app.py", line 1813, in full_dispatch_request
    rv = self.dispatch_request()
  File "c:\users\认为、\appdata\local\programs\python\python37\lib\site-packages\flask\app.py", line 1799, in dispatch_request
    return self.view_functions[rule.endpoint](**req.view_args)
  File "D:\项目\project\app\routes.py", line 23, in check_account
    ok = verify_password(byte(telnum), byte(password))
NameError: name 'byte' is not defined
2019-09-28 21:54:58,818 INFO: Microblog startup [in D:\项目\project\app\__init__.py:35]
2019-09-28 21:55:03,355 ERROR: Exception on /api/check_account [POST] [in c:\users\认为、\appdata\local\programs\python\python37\lib\site-packages\flask\app.py:1761]
Traceback (most recent call last):
  File "c:\users\认为、\appdata\local\programs\python\python37\lib\site-packages\flask\app.py", line 2292, in wsgi_app
    response = self.full_dispatch_request()
  File "c:\users\认为、\appdata\local\programs\python\python37\lib\site-packages\flask\app.py", line 1815, in full_dispatch_request
    rv = self.handle_user_exception(e)
  File "c:\users\认为、\appdata\local\programs\python\python37\lib\site-packages\flask\app.py", line 1718, in handle_user_exception
    reraise(exc_type, exc_value, tb)
  File "c:\users\认为、\appdata\local\programs\python\python37\lib\site-packages\flask\_compat.py", line 35, in reraise
    raise value
  File "c:\users\认为、\appdata\local\programs\python\python37\lib\site-packages\flask\app.py", line 1813, in full_dispatch_request
    rv = self.dispatch_request()
  File "c:\users\认为、\appdata\local\programs\python\python37\lib\site-packages\flask\app.py", line 1799, in dispatch_request
    return self.view_functions[rule.endpoint](**req.view_args)
  File "D:\项目\project\app\routes.py", line 23, in check_account
    ok = verify_password(byte(telnum), byte(password))
NameError: name 'byte' is not defined
2019-09-28 21:55:25,283 INFO: Microblog startup [in D:\项目\project\app\__init__.py:35]
2019-09-28 21:55:29,672 ERROR: Exception on /api/check_account [POST] [in c:\users\认为、\appdata\local\programs\python\python37\lib\site-packages\flask\app.py:1761]
Traceback (most recent call last):
  File "c:\users\认为、\appdata\local\programs\python\python37\lib\site-packages\flask\app.py", line 2292, in wsgi_app
    response = self.full_dispatch_request()
  File "c:\users\认为、\appdata\local\programs\python\python37\lib\site-packages\flask\app.py", line 1815, in full_dispatch_request
    rv = self.handle_user_exception(e)
  File "c:\users\认为、\appdata\local\programs\python\python37\lib\site-packages\flask\app.py", line 1718, in handle_user_exception
    reraise(exc_type, exc_value, tb)
  File "c:\users\认为、\appdata\local\programs\python\python37\lib\site-packages\flask\_compat.py", line 35, in reraise
    raise value
  File "c:\users\认为、\appdata\local\programs\python\python37\lib\site-packages\flask\app.py", line 1813, in full_dispatch_request
    rv = self.dispatch_request()
  File "c:\users\认为、\appdata\local\programs\python\python37\lib\site-packages\flask\app.py", line 1799, in dispatch_request
    return self.view_functions[rule.endpoint](**req.view_args)
  File "D:\项目\project\app\routes.py", line 23, in check_account
    ok = verify_password(bytes(telnum), bytes(password))
TypeError: string argument without an encoding
2019-09-28 21:57:01,688 INFO: Microblog startup [in D:\项目\project\app\__init__.py:35]
2019-09-28 21:57:04,002 ERROR: Exception on /api/check_account [POST] [in c:\users\认为、\appdata\local\programs\python\python37\lib\site-packages\flask\app.py:1761]
Traceback (most recent call last):
  File "c:\users\认为、\appdata\local\programs\python\python37\lib\site-packages\flask\app.py", line 2292, in wsgi_app
    response = self.full_dispatch_request()
  File "c:\users\认为、\appdata\local\programs\python\python37\lib\site-packages\flask\app.py", line 1815, in full_dispatch_request
    rv = self.handle_user_exception(e)
  File "c:\users\认为、\appdata\local\programs\python\python37\lib\site-packages\flask\app.py", line 1718, in handle_user_exception
    reraise(exc_type, exc_value, tb)
  File "c:\users\认为、\appdata\local\programs\python\python37\lib\site-packages\flask\_compat.py", line 35, in reraise
    raise value
  File "c:\users\认为、\appdata\local\programs\python\python37\lib\site-packages\flask\app.py", line 1813, in full_dispatch_request
    rv = self.dispatch_request()
  File "c:\users\认为、\appdata\local\programs\python\python37\lib\site-packages\flask\app.py", line 1799, in dispatch_request
    return self.view_functions[rule.endpoint](**req.view_args)
  File "D:\项目\project\app\routes.py", line 24, in check_account
    ok = verify_password(bytes(telnum), bytes(password))
TypeError: string argument without an encoding
2019-09-28 21:58:27,965 INFO: Microblog startup [in D:\项目\project\app\__init__.py:35]
2019-09-28 22:01:18,899 INFO: Microblog startup [in D:\项目\project\app\__init__.py:35]
2019-09-28 22:02:02,633 INFO: Microblog startup [in D:\项目\project\app\__init__.py:35]
2019-09-28 22:02:16,171 INFO: Microblog startup [in D:\项目\project\app\__init__.py:35]
2019-09-28 22:03:18,305 INFO: Microblog startup [in D:\项目\project\app\__init__.py:35]
2019-09-28 22:03:22,183 INFO: Microblog startup [in D:\项目\project\app\__init__.py:35]
2019-09-28 22:03:32,020 INFO: Microblog startup [in D:\项目\project\app\__init__.py:35]
2019-09-28 22:04:45,025 INFO: Microblog startup [in D:\项目\project\app\__init__.py:35]
2019-09-28 22:11:53,027 INFO: Microblog startup [in D:\项目\project\app\__init__.py:35]
2019-09-28 22:11:57,300 ERROR: Exception on /api/check_account [POST] [in c:\users\认为、\appdata\local\programs\python\python37\lib\site-packages\flask\app.py:1761]
Traceback (most recent call last):
  File "c:\users\认为、\appdata\local\programs\python\python37\lib\site-packages\flask\app.py", line 2292, in wsgi_app
    response = self.full_dispatch_request()
  File "c:\users\认为、\appdata\local\programs\python\python37\lib\site-packages\flask\app.py", line 1815, in full_dispatch_request
    rv = self.handle_user_exception(e)
  File "c:\users\认为、\appdata\local\programs\python\python37\lib\site-packages\flask\app.py", line 1718, in handle_user_exception
    reraise(exc_type, exc_value, tb)
  File "c:\users\认为、\appdata\local\programs\python\python37\lib\site-packages\flask\_compat.py", line 35, in reraise
    raise value
  File "c:\users\认为、\appdata\local\programs\python\python37\lib\site-packages\flask\app.py", line 1813, in full_dispatch_request
    rv = self.dispatch_request()
  File "c:\users\认为、\appdata\local\programs\python\python37\lib\site-packages\flask\app.py", line 1799, in dispatch_request
    return self.view_functions[rule.endpoint](**req.view_args)
  File "D:\项目\project\app\routes.py", line 28, in check_account
    if not user.check_ip(ip):
  File "D:\项目\project\app\models.py", line 77, in check_ip
    if ip_addr in self.ip_addr or self.right>=5:
TypeError: argument of type 'NoneType' is not iterable
2019-09-28 22:13:58,678 INFO: Microblog startup [in D:\项目\project\app\__init__.py:35]
2019-09-28 22:16:15,101 INFO: Microblog startup [in D:\项目\project\app\__init__.py:35]
2019-09-28 22:17:24,739 INFO: Microblog startup [in D:\项目\project\app\__init__.py:35]
2019-09-28 22:17:42,763 INFO: Microblog startup [in D:\项目\project\app\__init__.py:35]
2019-09-28 22:20:21,875 INFO: Microblog startup [in D:\项目\project\app\__init__.py:35]
