2019-10-12 15:32:25,461 ERROR: Exception on /api/get_store_info [POST] [in c:\users\认为、\appdata\local\programs\python\python37\lib\site-packages\flask\app.py:1761]
Traceback (most recent call last):
  File "c:\users\认为、\appdata\local\programs\python\python37\lib\site-packages\flask\app.py", line 2292, in wsgi_app
    response = self.full_dispatch_request()
  File "c:\users\认为、\appdata\local\programs\python\python37\lib\site-packages\flask\app.py", line 1815, in full_dispatch_request
    rv = self.handle_user_exception(e)
  File "c:\users\认为、\appdata\local\programs\python\python37\lib\site-packages\flask\app.py", line 1718, in handle_user_exception
    reraise(exc_type, exc_value, tb)
  File "c:\users\认为、\appdata\local\programs\python\python37\lib\site-packages\flask\_compat.py", line 35, in reraise
    raise value
  File "c:\users\认为、\appdata\local\programs\python\python37\lib\site-packages\flask\app.py", line 1813, in full_dispatch_request
    rv = self.dispatch_request()
  File "c:\users\认为、\appdata\local\programs\python\python37\lib\site-packages\flask\app.py", line 1799, in dispatch_request
    return self.view_functions[rule.endpoint](**req.view_args)
  File "c:\users\认为、\appdata\local\programs\python\python37\lib\site-packages\flask_httpauth.py", line 103, in decorated
    return self.auth_error_callback()
  File "c:\users\认为、\appdata\local\programs\python\python37\lib\site-packages\flask_httpauth.py", line 44, in decorated
    res = f(*args, **kwargs)
  File "D:\项目\project\app\models.py", line 218, in unauthorized
    if not d_user:
  File "c:\users\认为、\appdata\local\programs\python\python37\lib\site-packages\werkzeug\datastructures.py", line 1354, in __getitem__
    return _unicodify_header_value(self.environ['HTTP_' + key])
KeyError: 'HTTP_AUTHORIZATION'
2019-10-12 15:32:53,702 ERROR: Exception on /api/get_store_info [POST] [in c:\users\认为、\appdata\local\programs\python\python37\lib\site-packages\flask\app.py:1761]
Traceback (most recent call last):
  File "c:\users\认为、\appdata\local\programs\python\python37\lib\site-packages\flask\app.py", line 2292, in wsgi_app
    response = self.full_dispatch_request()
  File "c:\users\认为、\appdata\local\programs\python\python37\lib\site-packages\flask\app.py", line 1815, in full_dispatch_request
    rv = self.handle_user_exception(e)
  File "c:\users\认为、\appdata\local\programs\python\python37\lib\site-packages\flask\app.py", line 1718, in handle_user_exception
    reraise(exc_type, exc_value, tb)
  File "c:\users\认为、\appdata\local\programs\python\python37\lib\site-packages\flask\_compat.py", line 35, in reraise
    raise value
  File "c:\users\认为、\appdata\local\programs\python\python37\lib\site-packages\flask\app.py", line 1813, in full_dispatch_request
    rv = self.dispatch_request()
  File "c:\users\认为、\appdata\local\programs\python\python37\lib\site-packages\flask\app.py", line 1799, in dispatch_request
    return self.view_functions[rule.endpoint](**req.view_args)
  File "c:\users\认为、\appdata\local\programs\python\python37\lib\site-packages\flask_httpauth.py", line 103, in decorated
    return self.auth_error_callback()
  File "c:\users\认为、\appdata\local\programs\python\python37\lib\site-packages\flask_httpauth.py", line 44, in decorated
    res = f(*args, **kwargs)
  File "D:\项目\project\app\models.py", line 218, in unauthorized
    if not d_user:
  File "c:\users\认为、\appdata\local\programs\python\python37\lib\site-packages\werkzeug\datastructures.py", line 1354, in __getitem__
    return _unicodify_header_value(self.environ['HTTP_' + key])
KeyError: 'HTTP_AUTHORIZATION'
2019-10-12 15:33:16,688 ERROR: Exception on /api/get_store_info [POST] [in c:\users\认为、\appdata\local\programs\python\python37\lib\site-packages\flask\app.py:1761]
Traceback (most recent call last):
  File "c:\users\认为、\appdata\local\programs\python\python37\lib\site-packages\flask\app.py", line 2292, in wsgi_app
    response = self.full_dispatch_request()
  File "c:\users\认为、\appdata\local\programs\python\python37\lib\site-packages\flask\app.py", line 1815, in full_dispatch_request
    rv = self.handle_user_exception(e)
  File "c:\users\认为、\appdata\local\programs\python\python37\lib\site-packages\flask\app.py", line 1718, in handle_user_exception
    reraise(exc_type, exc_value, tb)
  File "c:\users\认为、\appdata\local\programs\python\python37\lib\site-packages\flask\_compat.py", line 35, in reraise
    raise value
  File "c:\users\认为、\appdata\local\programs\python\python37\lib\site-packages\flask\app.py", line 1813, in full_dispatch_request
    rv = self.dispatch_request()
  File "c:\users\认为、\appdata\local\programs\python\python37\lib\site-packages\flask\app.py", line 1799, in dispatch_request
    return self.view_functions[rule.endpoint](**req.view_args)
  File "c:\users\认为、\appdata\local\programs\python\python37\lib\site-packages\flask_httpauth.py", line 103, in decorated
    return self.auth_error_callback()
  File "c:\users\认为、\appdata\local\programs\python\python37\lib\site-packages\flask_httpauth.py", line 44, in decorated
    res = f(*args, **kwargs)
  File "D:\项目\project\app\models.py", line 218, in unauthorized
    if not d_user:
  File "c:\users\认为、\appdata\local\programs\python\python37\lib\site-packages\werkzeug\datastructures.py", line 1354, in __getitem__
    return _unicodify_header_value(self.environ['HTTP_' + key])
KeyError: 'HTTP_AUTHORIZATION'
2019-10-12 15:33:24,318 ERROR: Exception on /api/get_store_info [POST] [in c:\users\认为、\appdata\local\programs\python\python37\lib\site-packages\flask\app.py:1761]
Traceback (most recent call last):
  File "c:\users\认为、\appdata\local\programs\python\python37\lib\site-packages\flask\app.py", line 2292, in wsgi_app
    response = self.full_dispatch_request()
  File "c:\users\认为、\appdata\local\programs\python\python37\lib\site-packages\flask\app.py", line 1815, in full_dispatch_request
    rv = self.handle_user_exception(e)
  File "c:\users\认为、\appdata\local\programs\python\python37\lib\site-packages\flask\app.py", line 1718, in handle_user_exception
    reraise(exc_type, exc_value, tb)
  File "c:\users\认为、\appdata\local\programs\python\python37\lib\site-packages\flask\_compat.py", line 35, in reraise
    raise value
  File "c:\users\认为、\appdata\local\programs\python\python37\lib\site-packages\flask\app.py", line 1813, in full_dispatch_request
    rv = self.dispatch_request()
  File "c:\users\认为、\appdata\local\programs\python\python37\lib\site-packages\flask\app.py", line 1799, in dispatch_request
    return self.view_functions[rule.endpoint](**req.view_args)
  File "c:\users\认为、\appdata\local\programs\python\python37\lib\site-packages\flask_httpauth.py", line 103, in decorated
    return self.auth_error_callback()
  File "c:\users\认为、\appdata\local\programs\python\python37\lib\site-packages\flask_httpauth.py", line 44, in decorated
    res = f(*args, **kwargs)
  File "D:\项目\project\app\models.py", line 218, in unauthorized
    if not d_user:
  File "c:\users\认为、\appdata\local\programs\python\python37\lib\site-packages\werkzeug\datastructures.py", line 1354, in __getitem__
    return _unicodify_header_value(self.environ['HTTP_' + key])
KeyError: 'HTTP_AUTHORIZATION'
2019-10-12 15:33:41,171 ERROR: Exception on /api/get_store_info [POST] [in c:\users\认为、\appdata\local\programs\python\python37\lib\site-packages\flask\app.py:1761]
Traceback (most recent call last):
  File "c:\users\认为、\appdata\local\programs\python\python37\lib\site-packages\flask\app.py", line 2292, in wsgi_app
    response = self.full_dispatch_request()
  File "c:\users\认为、\appdata\local\programs\python\python37\lib\site-packages\flask\app.py", line 1815, in full_dispatch_request
    rv = self.handle_user_exception(e)
  File "c:\users\认为、\appdata\local\programs\python\python37\lib\site-packages\flask\app.py", line 1718, in handle_user_exception
    reraise(exc_type, exc_value, tb)
  File "c:\users\认为、\appdata\local\programs\python\python37\lib\site-packages\flask\_compat.py", line 35, in reraise
    raise value
  File "c:\users\认为、\appdata\local\programs\python\python37\lib\site-packages\flask\app.py", line 1813, in full_dispatch_request
    rv = self.dispatch_request()
  File "c:\users\认为、\appdata\local\programs\python\python37\lib\site-packages\flask\app.py", line 1799, in dispatch_request
    return self.view_functions[rule.endpoint](**req.view_args)
  File "c:\users\认为、\appdata\local\programs\python\python37\lib\site-packages\flask_httpauth.py", line 103, in decorated
    return self.auth_error_callback()
  File "c:\users\认为、\appdata\local\programs\python\python37\lib\site-packages\flask_httpauth.py", line 44, in decorated
    res = f(*args, **kwargs)
  File "D:\项目\project\app\models.py", line 218, in unauthorized
    if not d_user:
  File "c:\users\认为、\appdata\local\programs\python\python37\lib\site-packages\werkzeug\datastructures.py", line 1354, in __getitem__
    return _unicodify_header_value(self.environ['HTTP_' + key])
KeyError: 'HTTP_AUTHORIZATION'
2019-10-12 15:34:54,017 ERROR: Exception on /api/get_store_info [POST] [in c:\users\认为、\appdata\local\programs\python\python37\lib\site-packages\flask\app.py:1761]
Traceback (most recent call last):
  File "c:\users\认为、\appdata\local\programs\python\python37\lib\site-packages\flask\app.py", line 2292, in wsgi_app
    response = self.full_dispatch_request()
  File "c:\users\认为、\appdata\local\programs\python\python37\lib\site-packages\flask\app.py", line 1815, in full_dispatch_request
    rv = self.handle_user_exception(e)
  File "c:\users\认为、\appdata\local\programs\python\python37\lib\site-packages\flask\app.py", line 1718, in handle_user_exception
    reraise(exc_type, exc_value, tb)
  File "c:\users\认为、\appdata\local\programs\python\python37\lib\site-packages\flask\_compat.py", line 35, in reraise
    raise value
  File "c:\users\认为、\appdata\local\programs\python\python37\lib\site-packages\flask\app.py", line 1813, in full_dispatch_request
    rv = self.dispatch_request()
  File "c:\users\认为、\appdata\local\programs\python\python37\lib\site-packages\flask\app.py", line 1799, in dispatch_request
    return self.view_functions[rule.endpoint](**req.view_args)
  File "c:\users\认为、\appdata\local\programs\python\python37\lib\site-packages\flask_httpauth.py", line 103, in decorated
    return self.auth_error_callback()
  File "c:\users\认为、\appdata\local\programs\python\python37\lib\site-packages\flask_httpauth.py", line 44, in decorated
    res = f(*args, **kwargs)
  File "D:\项目\project\app\models.py", line 218, in unauthorized
    if not d_user:
  File "c:\users\认为、\appdata\local\programs\python\python37\lib\site-packages\werkzeug\datastructures.py", line 1354, in __getitem__
    return _unicodify_header_value(self.environ['HTTP_' + key])
KeyError: 'HTTP_AUTHORIZATION'
2019-10-12 15:35:16,992 ERROR: Exception on /api/get_store_info [POST] [in c:\users\认为、\appdata\local\programs\python\python37\lib\site-packages\flask\app.py:1761]
Traceback (most recent call last):
  File "c:\users\认为、\appdata\local\programs\python\python37\lib\site-packages\flask\app.py", line 2292, in wsgi_app
    response = self.full_dispatch_request()
  File "c:\users\认为、\appdata\local\programs\python\python37\lib\site-packages\flask\app.py", line 1815, in full_dispatch_request
    rv = self.handle_user_exception(e)
  File "c:\users\认为、\appdata\local\programs\python\python37\lib\site-packages\flask\app.py", line 1718, in handle_user_exception
    reraise(exc_type, exc_value, tb)
  File "c:\users\认为、\appdata\local\programs\python\python37\lib\site-packages\flask\_compat.py", line 35, in reraise
    raise value
  File "c:\users\认为、\appdata\local\programs\python\python37\lib\site-packages\flask\app.py", line 1813, in full_dispatch_request
    rv = self.dispatch_request()
  File "c:\users\认为、\appdata\local\programs\python\python37\lib\site-packages\flask\app.py", line 1799, in dispatch_request
    return self.view_functions[rule.endpoint](**req.view_args)
  File "c:\users\认为、\appdata\local\programs\python\python37\lib\site-packages\flask_httpauth.py", line 103, in decorated
    return self.auth_error_callback()
  File "c:\users\认为、\appdata\local\programs\python\python37\lib\site-packages\flask_httpauth.py", line 44, in decorated
    res = f(*args, **kwargs)
  File "D:\项目\project\app\models.py", line 218, in unauthorized
    if not d_user:
  File "c:\users\认为、\appdata\local\programs\python\python37\lib\site-packages\werkzeug\datastructures.py", line 1354, in __getitem__
    return _unicodify_header_value(self.environ['HTTP_' + key])
KeyError: 'HTTP_AUTHORIZATION'
2019-10-12 15:35:24,623 ERROR: Exception on /api/get_store_info [POST] [in c:\users\认为、\appdata\local\programs\python\python37\lib\site-packages\flask\app.py:1761]
Traceback (most recent call last):
  File "c:\users\认为、\appdata\local\programs\python\python37\lib\site-packages\flask\app.py", line 2292, in wsgi_app
    response = self.full_dispatch_request()
  File "c:\users\认为、\appdata\local\programs\python\python37\lib\site-packages\flask\app.py", line 1815, in full_dispatch_request
    rv = self.handle_user_exception(e)
  File "c:\users\认为、\appdata\local\programs\python\python37\lib\site-packages\flask\app.py", line 1718, in handle_user_exception
    reraise(exc_type, exc_value, tb)
  File "c:\users\认为、\appdata\local\programs\python\python37\lib\site-packages\flask\_compat.py", line 35, in reraise
    raise value
  File "c:\users\认为、\appdata\local\programs\python\python37\lib\site-packages\flask\app.py", line 1813, in full_dispatch_request
    rv = self.dispatch_request()
  File "c:\users\认为、\appdata\local\programs\python\python37\lib\site-packages\flask\app.py", line 1799, in dispatch_request
    return self.view_functions[rule.endpoint](**req.view_args)
  File "c:\users\认为、\appdata\local\programs\python\python37\lib\site-packages\flask_httpauth.py", line 103, in decorated
    return self.auth_error_callback()
  File "c:\users\认为、\appdata\local\programs\python\python37\lib\site-packages\flask_httpauth.py", line 44, in decorated
    res = f(*args, **kwargs)
  File "D:\项目\project\app\models.py", line 218, in unauthorized
    if not d_user:
  File "c:\users\认为、\appdata\local\programs\python\python37\lib\site-packages\werkzeug\datastructures.py", line 1354, in __getitem__
    return _unicodify_header_value(self.environ['HTTP_' + key])
KeyError: 'HTTP_AUTHORIZATION'
2019-10-12 15:35:36,922 ERROR: Exception on /api/get_store_info [POST] [in c:\users\认为、\appdata\local\programs\python\python37\lib\site-packages\flask\app.py:1761]
Traceback (most recent call last):
  File "c:\users\认为、\appdata\local\programs\python\python37\lib\site-packages\flask\app.py", line 2292, in wsgi_app
    response = self.full_dispatch_request()
  File "c:\users\认为、\appdata\local\programs\python\python37\lib\site-packages\flask\app.py", line 1815, in full_dispatch_request
    rv = self.handle_user_exception(e)
  File "c:\users\认为、\appdata\local\programs\python\python37\lib\site-packages\flask\app.py", line 1718, in handle_user_exception
    reraise(exc_type, exc_value, tb)
  File "c:\users\认为、\appdata\local\programs\python\python37\lib\site-packages\flask\_compat.py", line 35, in reraise
    raise value
  File "c:\users\认为、\appdata\local\programs\python\python37\lib\site-packages\flask\app.py", line 1813, in full_dispatch_request
    rv = self.dispatch_request()
  File "c:\users\认为、\appdata\local\programs\python\python37\lib\site-packages\flask\app.py", line 1799, in dispatch_request
    return self.view_functions[rule.endpoint](**req.view_args)
  File "c:\users\认为、\appdata\local\programs\python\python37\lib\site-packages\flask_httpauth.py", line 103, in decorated
    return self.auth_error_callback()
  File "c:\users\认为、\appdata\local\programs\python\python37\lib\site-packages\flask_httpauth.py", line 44, in decorated
    res = f(*args, **kwargs)
  File "D:\项目\project\app\models.py", line 218, in unauthorized
    if not d_user:
  File "c:\users\认为、\appdata\local\programs\python\python37\lib\site-packages\werkzeug\datastructures.py", line 1354, in __getitem__
    return _unicodify_header_value(self.environ['HTTP_' + key])
KeyError: 'HTTP_AUTHORIZATION'
2019-10-12 15:36:15,299 ERROR: Exception on /api/get_store_info [POST] [in c:\users\认为、\appdata\local\programs\python\python37\lib\site-packages\flask\app.py:1761]
Traceback (most recent call last):
  File "c:\users\认为、\appdata\local\programs\python\python37\lib\site-packages\flask\app.py", line 2292, in wsgi_app
    response = self.full_dispatch_request()
  File "c:\users\认为、\appdata\local\programs\python\python37\lib\site-packages\flask\app.py", line 1815, in full_dispatch_request
    rv = self.handle_user_exception(e)
  File "c:\users\认为、\appdata\local\programs\python\python37\lib\site-packages\flask\app.py", line 1718, in handle_user_exception
    reraise(exc_type, exc_value, tb)
  File "c:\users\认为、\appdata\local\programs\python\python37\lib\site-packages\flask\_compat.py", line 35, in reraise
    raise value
  File "c:\users\认为、\appdata\local\programs\python\python37\lib\site-packages\flask\app.py", line 1813, in full_dispatch_request
    rv = self.dispatch_request()
  File "c:\users\认为、\appdata\local\programs\python\python37\lib\site-packages\flask\app.py", line 1799, in dispatch_request
    return self.view_functions[rule.endpoint](**req.view_args)
  File "c:\users\认为、\appdata\local\programs\python\python37\lib\site-packages\flask_httpauth.py", line 103, in decorated
    return self.auth_error_callback()
  File "c:\users\认为、\appdata\local\programs\python\python37\lib\site-packages\flask_httpauth.py", line 44, in decorated
    res = f(*args, **kwargs)
  File "D:\项目\project\app\models.py", line 218, in unauthorized
    if not d_user:
  File "c:\users\认为、\appdata\local\programs\python\python37\lib\site-packages\werkzeug\datastructures.py", line 1354, in __getitem__
    return _unicodify_header_value(self.environ['HTTP_' + key])
KeyError: 'HTTP_AUTHORIZATION'
2019-10-12 15:37:03,305 ERROR: Exception on /api/get_store_info [POST] [in c:\users\认为、\appdata\local\programs\python\python37\lib\site-packages\flask\app.py:1761]
Traceback (most recent call last):
  File "c:\users\认为、\appdata\local\programs\python\python37\lib\site-packages\flask\app.py", line 2292, in wsgi_app
    response = self.full_dispatch_request()
  File "c:\users\认为、\appdata\local\programs\python\python37\lib\site-packages\flask\app.py", line 1815, in full_dispatch_request
    rv = self.handle_user_exception(e)
  File "c:\users\认为、\appdata\local\programs\python\python37\lib\site-packages\flask\app.py", line 1718, in handle_user_exception
    reraise(exc_type, exc_value, tb)
  File "c:\users\认为、\appdata\local\programs\python\python37\lib\site-packages\flask\_compat.py", line 35, in reraise
    raise value
  File "c:\users\认为、\appdata\local\programs\python\python37\lib\site-packages\flask\app.py", line 1813, in full_dispatch_request
    rv = self.dispatch_request()
  File "c:\users\认为、\appdata\local\programs\python\python37\lib\site-packages\flask\app.py", line 1799, in dispatch_request
    return self.view_functions[rule.endpoint](**req.view_args)
  File "c:\users\认为、\appdata\local\programs\python\python37\lib\site-packages\flask_httpauth.py", line 103, in decorated
    return self.auth_error_callback()
  File "c:\users\认为、\appdata\local\programs\python\python37\lib\site-packages\flask_httpauth.py", line 44, in decorated
    res = f(*args, **kwargs)
  File "D:\项目\project\app\models.py", line 218, in unauthorized
    if not d_user:
  File "c:\users\认为、\appdata\local\programs\python\python37\lib\site-packages\werkzeug\datastructures.py", line 1354, in __getitem__
    return _unicodify_header_value(self.environ['HTTP_' + key])
KeyError: 'HTTP_AUTHORIZATION'
2019-10-12 15:37:46,086 ERROR: Exception on /api/get_store_info [POST] [in c:\users\认为、\appdata\local\programs\python\python37\lib\site-packages\flask\app.py:1761]
Traceback (most recent call last):
  File "c:\users\认为、\appdata\local\programs\python\python37\lib\site-packages\flask\app.py", line 2292, in wsgi_app
    response = self.full_dispatch_request()
  File "c:\users\认为、\appdata\local\programs\python\python37\lib\site-packages\flask\app.py", line 1815, in full_dispatch_request
    rv = self.handle_user_exception(e)
  File "c:\users\认为、\appdata\local\programs\python\python37\lib\site-packages\flask\app.py", line 1718, in handle_user_exception
    reraise(exc_type, exc_value, tb)
  File "c:\users\认为、\appdata\local\programs\python\python37\lib\site-packages\flask\_compat.py", line 35, in reraise
    raise value
  File "c:\users\认为、\appdata\local\programs\python\python37\lib\site-packages\flask\app.py", line 1813, in full_dispatch_request
    rv = self.dispatch_request()
  File "c:\users\认为、\appdata\local\programs\python\python37\lib\site-packages\flask\app.py", line 1799, in dispatch_request
    return self.view_functions[rule.endpoint](**req.view_args)
  File "c:\users\认为、\appdata\local\programs\python\python37\lib\site-packages\flask_httpauth.py", line 103, in decorated
    return self.auth_error_callback()
  File "c:\users\认为、\appdata\local\programs\python\python37\lib\site-packages\flask_httpauth.py", line 44, in decorated
    res = f(*args, **kwargs)
  File "D:\项目\project\app\models.py", line 218, in unauthorized
    if not d_user:
  File "c:\users\认为、\appdata\local\programs\python\python37\lib\site-packages\werkzeug\datastructures.py", line 1354, in __getitem__
    return _unicodify_header_value(self.environ['HTTP_' + key])
KeyError: 'HTTP_AUTHORIZATION'
2019-10-12 15:37:52,289 ERROR: Exception on /api/get_store_info [POST] [in c:\users\认为、\appdata\local\programs\python\python37\lib\site-packages\flask\app.py:1761]
Traceback (most recent call last):
  File "c:\users\认为、\appdata\local\programs\python\python37\lib\site-packages\flask\app.py", line 2292, in wsgi_app
    response = self.full_dispatch_request()
  File "c:\users\认为、\appdata\local\programs\python\python37\lib\site-packages\flask\app.py", line 1815, in full_dispatch_request
    rv = self.handle_user_exception(e)
  File "c:\users\认为、\appdata\local\programs\python\python37\lib\site-packages\flask\app.py", line 1718, in handle_user_exception
    reraise(exc_type, exc_value, tb)
  File "c:\users\认为、\appdata\local\programs\python\python37\lib\site-packages\flask\_compat.py", line 35, in reraise
    raise value
  File "c:\users\认为、\appdata\local\programs\python\python37\lib\site-packages\flask\app.py", line 1813, in full_dispatch_request
    rv = self.dispatch_request()
  File "c:\users\认为、\appdata\local\programs\python\python37\lib\site-packages\flask\app.py", line 1799, in dispatch_request
    return self.view_functions[rule.endpoint](**req.view_args)
  File "c:\users\认为、\appdata\local\programs\python\python37\lib\site-packages\flask_httpauth.py", line 103, in decorated
    return self.auth_error_callback()
  File "c:\users\认为、\appdata\local\programs\python\python37\lib\site-packages\flask_httpauth.py", line 44, in decorated
    res = f(*args, **kwargs)
  File "D:\项目\project\app\models.py", line 218, in unauthorized
    if not d_user:
  File "c:\users\认为、\appdata\local\programs\python\python37\lib\site-packages\werkzeug\datastructures.py", line 1354, in __getitem__
    return _unicodify_header_value(self.environ['HTTP_' + key])
KeyError: 'HTTP_AUTHORIZATION'
2019-10-12 15:37:58,890 ERROR: Exception on /api/get_store_info [POST] [in c:\users\认为、\appdata\local\programs\python\python37\lib\site-packages\flask\app.py:1761]
Traceback (most recent call last):
  File "c:\users\认为、\appdata\local\programs\python\python37\lib\site-packages\flask\app.py", line 2292, in wsgi_app
    response = self.full_dispatch_request()
  File "c:\users\认为、\appdata\local\programs\python\python37\lib\site-packages\flask\app.py", line 1815, in full_dispatch_request
    rv = self.handle_user_exception(e)
  File "c:\users\认为、\appdata\local\programs\python\python37\lib\site-packages\flask\app.py", line 1718, in handle_user_exception
    reraise(exc_type, exc_value, tb)
  File "c:\users\认为、\appdata\local\programs\python\python37\lib\site-packages\flask\_compat.py", line 35, in reraise
    raise value
  File "c:\users\认为、\appdata\local\programs\python\python37\lib\site-packages\flask\app.py", line 1813, in full_dispatch_request
    rv = self.dispatch_request()
  File "c:\users\认为、\appdata\local\programs\python\python37\lib\site-packages\flask\app.py", line 1799, in dispatch_request
    return self.view_functions[rule.endpoint](**req.view_args)
  File "c:\users\认为、\appdata\local\programs\python\python37\lib\site-packages\flask_httpauth.py", line 103, in decorated
    return self.auth_error_callback()
  File "c:\users\认为、\appdata\local\programs\python\python37\lib\site-packages\flask_httpauth.py", line 44, in decorated
    res = f(*args, **kwargs)
  File "D:\项目\project\app\models.py", line 218, in unauthorized
    if not d_user:
  File "c:\users\认为、\appdata\local\programs\python\python37\lib\site-packages\werkzeug\datastructures.py", line 1354, in __getitem__
    return _unicodify_header_value(self.environ['HTTP_' + key])
KeyError: 'HTTP_AUTHORIZATION'
2019-10-12 15:37:59,283 ERROR: Exception on /api/get_store_info [POST] [in c:\users\认为、\appdata\local\programs\python\python37\lib\site-packages\flask\app.py:1761]
Traceback (most recent call last):
  File "c:\users\认为、\appdata\local\programs\python\python37\lib\site-packages\flask\app.py", line 2292, in wsgi_app
    response = self.full_dispatch_request()
  File "c:\users\认为、\appdata\local\programs\python\python37\lib\site-packages\flask\app.py", line 1815, in full_dispatch_request
    rv = self.handle_user_exception(e)
  File "c:\users\认为、\appdata\local\programs\python\python37\lib\site-packages\flask\app.py", line 1718, in handle_user_exception
    reraise(exc_type, exc_value, tb)
  File "c:\users\认为、\appdata\local\programs\python\python37\lib\site-packages\flask\_compat.py", line 35, in reraise
    raise value
  File "c:\users\认为、\appdata\local\programs\python\python37\lib\site-packages\flask\app.py", line 1813, in full_dispatch_request
    rv = self.dispatch_request()
  File "c:\users\认为、\appdata\local\programs\python\python37\lib\site-packages\flask\app.py", line 1799, in dispatch_request
    return self.view_functions[rule.endpoint](**req.view_args)
  File "c:\users\认为、\appdata\local\programs\python\python37\lib\site-packages\flask_httpauth.py", line 103, in decorated
    return self.auth_error_callback()
  File "c:\users\认为、\appdata\local\programs\python\python37\lib\site-packages\flask_httpauth.py", line 44, in decorated
    res = f(*args, **kwargs)
  File "D:\项目\project\app\models.py", line 218, in unauthorized
    if not d_user:
  File "c:\users\认为、\appdata\local\programs\python\python37\lib\site-packages\werkzeug\datastructures.py", line 1354, in __getitem__
    return _unicodify_header_value(self.environ['HTTP_' + key])
KeyError: 'HTTP_AUTHORIZATION'
2019-10-12 15:37:59,410 ERROR: Exception on /api/get_store_info [POST] [in c:\users\认为、\appdata\local\programs\python\python37\lib\site-packages\flask\app.py:1761]
Traceback (most recent call last):
  File "c:\users\认为、\appdata\local\programs\python\python37\lib\site-packages\flask\app.py", line 2292, in wsgi_app
    response = self.full_dispatch_request()
  File "c:\users\认为、\appdata\local\programs\python\python37\lib\site-packages\flask\app.py", line 1815, in full_dispatch_request
    rv = self.handle_user_exception(e)
  File "c:\users\认为、\appdata\local\programs\python\python37\lib\site-packages\flask\app.py", line 1718, in handle_user_exception
    reraise(exc_type, exc_value, tb)
  File "c:\users\认为、\appdata\local\programs\python\python37\lib\site-packages\flask\_compat.py", line 35, in reraise
    raise value
  File "c:\users\认为、\appdata\local\programs\python\python37\lib\site-packages\flask\app.py", line 1813, in full_dispatch_request
    rv = self.dispatch_request()
  File "c:\users\认为、\appdata\local\programs\python\python37\lib\site-packages\flask\app.py", line 1799, in dispatch_request
    return self.view_functions[rule.endpoint](**req.view_args)
  File "c:\users\认为、\appdata\local\programs\python\python37\lib\site-packages\flask_httpauth.py", line 103, in decorated
    return self.auth_error_callback()
  File "c:\users\认为、\appdata\local\programs\python\python37\lib\site-packages\flask_httpauth.py", line 44, in decorated
    res = f(*args, **kwargs)
  File "D:\项目\project\app\models.py", line 218, in unauthorized
    if not d_user:
  File "c:\users\认为、\appdata\local\programs\python\python37\lib\site-packages\werkzeug\datastructures.py", line 1354, in __getitem__
    return _unicodify_header_value(self.environ['HTTP_' + key])
KeyError: 'HTTP_AUTHORIZATION'
2019-10-12 15:39:03,624 ERROR: Exception on /api/get_store_info [POST] [in c:\users\认为、\appdata\local\programs\python\python37\lib\site-packages\flask\app.py:1761]
Traceback (most recent call last):
  File "c:\users\认为、\appdata\local\programs\python\python37\lib\site-packages\flask\app.py", line 2292, in wsgi_app
    response = self.full_dispatch_request()
  File "c:\users\认为、\appdata\local\programs\python\python37\lib\site-packages\flask\app.py", line 1815, in full_dispatch_request
    rv = self.handle_user_exception(e)
  File "c:\users\认为、\appdata\local\programs\python\python37\lib\site-packages\flask\app.py", line 1718, in handle_user_exception
    reraise(exc_type, exc_value, tb)
  File "c:\users\认为、\appdata\local\programs\python\python37\lib\site-packages\flask\_compat.py", line 35, in reraise
    raise value
  File "c:\users\认为、\appdata\local\programs\python\python37\lib\site-packages\flask\app.py", line 1813, in full_dispatch_request
    rv = self.dispatch_request()
  File "c:\users\认为、\appdata\local\programs\python\python37\lib\site-packages\flask\app.py", line 1799, in dispatch_request
    return self.view_functions[rule.endpoint](**req.view_args)
  File "c:\users\认为、\appdata\local\programs\python\python37\lib\site-packages\flask_httpauth.py", line 103, in decorated
    return self.auth_error_callback()
  File "c:\users\认为、\appdata\local\programs\python\python37\lib\site-packages\flask_httpauth.py", line 44, in decorated
    res = f(*args, **kwargs)
  File "D:\项目\project\app\models.py", line 218, in unauthorized
    if not d_user:
  File "c:\users\认为、\appdata\local\programs\python\python37\lib\site-packages\werkzeug\datastructures.py", line 1354, in __getitem__
    return _unicodify_header_value(self.environ['HTTP_' + key])
KeyError: 'HTTP_AUTHORIZATION'
2019-10-12 15:39:08,868 ERROR: Exception on /api/get_store_info [POST] [in c:\users\认为、\appdata\local\programs\python\python37\lib\site-packages\flask\app.py:1761]
Traceback (most recent call last):
  File "c:\users\认为、\appdata\local\programs\python\python37\lib\site-packages\flask\app.py", line 2292, in wsgi_app
    response = self.full_dispatch_request()
  File "c:\users\认为、\appdata\local\programs\python\python37\lib\site-packages\flask\app.py", line 1815, in full_dispatch_request
    rv = self.handle_user_exception(e)
  File "c:\users\认为、\appdata\local\programs\python\python37\lib\site-packages\flask\app.py", line 1718, in handle_user_exception
    reraise(exc_type, exc_value, tb)
  File "c:\users\认为、\appdata\local\programs\python\python37\lib\site-packages\flask\_compat.py", line 35, in reraise
    raise value
  File "c:\users\认为、\appdata\local\programs\python\python37\lib\site-packages\flask\app.py", line 1813, in full_dispatch_request
    rv = self.dispatch_request()
  File "c:\users\认为、\appdata\local\programs\python\python37\lib\site-packages\flask\app.py", line 1799, in dispatch_request
    return self.view_functions[rule.endpoint](**req.view_args)
  File "c:\users\认为、\appdata\local\programs\python\python37\lib\site-packages\flask_httpauth.py", line 103, in decorated
    return self.auth_error_callback()
  File "c:\users\认为、\appdata\local\programs\python\python37\lib\site-packages\flask_httpauth.py", line 44, in decorated
    res = f(*args, **kwargs)
  File "D:\项目\project\app\models.py", line 218, in unauthorized
    if not d_user:
  File "c:\users\认为、\appdata\local\programs\python\python37\lib\site-packages\werkzeug\datastructures.py", line 1354, in __getitem__
    return _unicodify_header_value(self.environ['HTTP_' + key])
KeyError: 'HTTP_AUTHORIZATION'
2019-10-12 15:39:49,197 ERROR: Exception on /api/get_store_info [POST] [in c:\users\认为、\appdata\local\programs\python\python37\lib\site-packages\flask\app.py:1761]
Traceback (most recent call last):
  File "c:\users\认为、\appdata\local\programs\python\python37\lib\site-packages\flask\app.py", line 2292, in wsgi_app
    response = self.full_dispatch_request()
  File "c:\users\认为、\appdata\local\programs\python\python37\lib\site-packages\flask\app.py", line 1815, in full_dispatch_request
    rv = self.handle_user_exception(e)
  File "c:\users\认为、\appdata\local\programs\python\python37\lib\site-packages\flask\app.py", line 1718, in handle_user_exception
    reraise(exc_type, exc_value, tb)
  File "c:\users\认为、\appdata\local\programs\python\python37\lib\site-packages\flask\_compat.py", line 35, in reraise
    raise value
  File "c:\users\认为、\appdata\local\programs\python\python37\lib\site-packages\flask\app.py", line 1813, in full_dispatch_request
    rv = self.dispatch_request()
  File "c:\users\认为、\appdata\local\programs\python\python37\lib\site-packages\flask\app.py", line 1799, in dispatch_request
    return self.view_functions[rule.endpoint](**req.view_args)
  File "c:\users\认为、\appdata\local\programs\python\python37\lib\site-packages\flask_httpauth.py", line 103, in decorated
    return self.auth_error_callback()
  File "c:\users\认为、\appdata\local\programs\python\python37\lib\site-packages\flask_httpauth.py", line 44, in decorated
    res = f(*args, **kwargs)
  File "D:\项目\project\app\models.py", line 218, in unauthorized
    if not d_user:
  File "c:\users\认为、\appdata\local\programs\python\python37\lib\site-packages\werkzeug\datastructures.py", line 1354, in __getitem__
    return _unicodify_header_value(self.environ['HTTP_' + key])
KeyError: 'HTTP_AUTHORIZATION'
2019-10-12 15:41:09,174 ERROR: Exception on /api/get_store_info [POST] [in c:\users\认为、\appdata\local\programs\python\python37\lib\site-packages\flask\app.py:1761]
Traceback (most recent call last):
  File "c:\users\认为、\appdata\local\programs\python\python37\lib\site-packages\flask\app.py", line 2292, in wsgi_app
    response = self.full_dispatch_request()
  File "c:\users\认为、\appdata\local\programs\python\python37\lib\site-packages\flask\app.py", line 1815, in full_dispatch_request
    rv = self.handle_user_exception(e)
  File "c:\users\认为、\appdata\local\programs\python\python37\lib\site-packages\flask\app.py", line 1718, in handle_user_exception
    reraise(exc_type, exc_value, tb)
  File "c:\users\认为、\appdata\local\programs\python\python37\lib\site-packages\flask\_compat.py", line 35, in reraise
    raise value
  File "c:\users\认为、\appdata\local\programs\python\python37\lib\site-packages\flask\app.py", line 1813, in full_dispatch_request
    rv = self.dispatch_request()
  File "c:\users\认为、\appdata\local\programs\python\python37\lib\site-packages\flask\app.py", line 1799, in dispatch_request
    return self.view_functions[rule.endpoint](**req.view_args)
  File "c:\users\认为、\appdata\local\programs\python\python37\lib\site-packages\flask_httpauth.py", line 103, in decorated
    return self.auth_error_callback()
  File "c:\users\认为、\appdata\local\programs\python\python37\lib\site-packages\flask_httpauth.py", line 44, in decorated
    res = f(*args, **kwargs)
  File "D:\项目\project\app\models.py", line 218, in unauthorized
    if not d_user:
  File "c:\users\认为、\appdata\local\programs\python\python37\lib\site-packages\werkzeug\datastructures.py", line 1354, in __getitem__
    return _unicodify_header_value(self.environ['HTTP_' + key])
KeyError: 'HTTP_AUTHORIZATION'
2019-10-12 15:41:49,513 ERROR: Exception on /api/get_store_info [POST] [in c:\users\认为、\appdata\local\programs\python\python37\lib\site-packages\flask\app.py:1761]
Traceback (most recent call last):
  File "c:\users\认为、\appdata\local\programs\python\python37\lib\site-packages\flask\app.py", line 2292, in wsgi_app
    response = self.full_dispatch_request()
  File "c:\users\认为、\appdata\local\programs\python\python37\lib\site-packages\flask\app.py", line 1815, in full_dispatch_request
    rv = self.handle_user_exception(e)
  File "c:\users\认为、\appdata\local\programs\python\python37\lib\site-packages\flask\app.py", line 1718, in handle_user_exception
    reraise(exc_type, exc_value, tb)
  File "c:\users\认为、\appdata\local\programs\python\python37\lib\site-packages\flask\_compat.py", line 35, in reraise
    raise value
  File "c:\users\认为、\appdata\local\programs\python\python37\lib\site-packages\flask\app.py", line 1813, in full_dispatch_request
    rv = self.dispatch_request()
  File "c:\users\认为、\appdata\local\programs\python\python37\lib\site-packages\flask\app.py", line 1799, in dispatch_request
    return self.view_functions[rule.endpoint](**req.view_args)
  File "c:\users\认为、\appdata\local\programs\python\python37\lib\site-packages\flask_httpauth.py", line 103, in decorated
    return self.auth_error_callback()
  File "c:\users\认为、\appdata\local\programs\python\python37\lib\site-packages\flask_httpauth.py", line 44, in decorated
    res = f(*args, **kwargs)
  File "D:\项目\project\app\models.py", line 218, in unauthorized
    if not d_user:
  File "c:\users\认为、\appdata\local\programs\python\python37\lib\site-packages\werkzeug\datastructures.py", line 1354, in __getitem__
    return _unicodify_header_value(self.environ['HTTP_' + key])
KeyError: 'HTTP_AUTHORIZATION'
2019-10-12 15:42:56,536 ERROR: Exception on /api/get_store_info [POST] [in c:\users\认为、\appdata\local\programs\python\python37\lib\site-packages\flask\app.py:1761]
Traceback (most recent call last):
  File "c:\users\认为、\appdata\local\programs\python\python37\lib\site-packages\flask\app.py", line 2292, in wsgi_app
    response = self.full_dispatch_request()
  File "c:\users\认为、\appdata\local\programs\python\python37\lib\site-packages\flask\app.py", line 1815, in full_dispatch_request
    rv = self.handle_user_exception(e)
  File "c:\users\认为、\appdata\local\programs\python\python37\lib\site-packages\flask\app.py", line 1718, in handle_user_exception
    reraise(exc_type, exc_value, tb)
  File "c:\users\认为、\appdata\local\programs\python\python37\lib\site-packages\flask\_compat.py", line 35, in reraise
    raise value
  File "c:\users\认为、\appdata\local\programs\python\python37\lib\site-packages\flask\app.py", line 1813, in full_dispatch_request
    rv = self.dispatch_request()
  File "c:\users\认为、\appdata\local\programs\python\python37\lib\site-packages\flask\app.py", line 1799, in dispatch_request
    return self.view_functions[rule.endpoint](**req.view_args)
  File "c:\users\认为、\appdata\local\programs\python\python37\lib\site-packages\flask_httpauth.py", line 103, in decorated
    return self.auth_error_callback()
  File "c:\users\认为、\appdata\local\programs\python\python37\lib\site-packages\flask_httpauth.py", line 44, in decorated
    res = f(*args, **kwargs)
  File "D:\项目\project\app\models.py", line 218, in unauthorized
    if not d_user:
  File "c:\users\认为、\appdata\local\programs\python\python37\lib\site-packages\werkzeug\datastructures.py", line 1354, in __getitem__
    return _unicodify_header_value(self.environ['HTTP_' + key])
KeyError: 'HTTP_AUTHORIZATION'
